Workbook

Sheet Índice
A1: AUTORIDAD NACIONAL DE INFRAESTRUCTURA - ANIN
A2: DIRECCIÓN DE INTERVENCIONES MULTISECTORIALES Y DE EMERGENCIA - DIME
A3: SUBDIRECCIÓN DE ESTUDIOS DE INVERSIÓN - SESDI
A4: ANEXOS DEL INFORME DE AVANCE DEL PERFIL IN PIURA — RESPUESTA A SOLICITUD DE INFORMACIÓN
A5: PROYECTO IN PIURA | CUI 2669244 | Cuenca Alta del Río Piura | UTM WGS 84 Zona 17S (EPSG:32717)
A6: Fuente: repositorio del Proyecto IN Piura, corte 23.10.2026
A8: Hoja | B8: Punto de la solicitud | C8: Contenido
A9: A1_Ambito_Distrito | B9: 1. Delimitación del ámbito | C9: Bloques V6 y área de influencia por distrito y provincia
A10: A1_Microcuencas | B10: 1. Delimitación del ámbito | C10: Bloques V6 por microcuenca (26 microcuencas)
A11: A1_Bloques | B11: 1, 2 y 4 | C11: Detalle de los 117 bloques V6: ubicación, AI, MSAVI, ecosistema, CCPP
A12: A2_Criterios | B12: 2. Criterios de selección | C12: Matriz de criterios de selección y priorización
A13: A3_Poblacion_CCPP | B13: 3. Población afectada | C13: Centros poblados asociados a los bloques V6 (únicos)
A14: A3_Poblacion_Distrito | B14: 3. Población afectada | C14: Población de los CCPP asociados por distrito y provincia
A15: A3_Avance_Social | B15: 3 y 5 | C15: Diseño muestral y avance de las fichas F-DS por centro poblado
A16: A4_UP_Ecosistemas | B16: 4. Unidad Productora | C16: Ecosistemas en los bloques V6 (MINAM 2018)
A17: A4_UP_Eco_Bloque | B17: 4. Unidad Productora | C17: Ecosistemas por bloque (detalle)
A18: A4_UP_MSAVI | B18: 4. Unidad Productora | C18: Cobertura vegetal MSAVI 2024 por clase y bloque
A19: A4_UP_Carcavas | B19: 4. Unidad Productora | C19: Cárcavas caracterizadas (55)
... A22: Notas | B22: — | C22: Fuentes, controles y datos pendientes [POR DEFINIR]

Sheet A1_Ambito_Distrito
A1: AUTORIDAD NACIONAL DE INFRAESTRUCTURA - ANIN
A2: DIRECCIÓN DE INTERVENCIONES MULTISECTORIALES Y DE EMERGENCIA - DIME
A3: SUBDIRECCIÓN DE ESTUDIOS DE INVERSIÓN - SESDI
A4: A1. ÁMBITO DE ESTUDIO Y ÁREA DE INFLUENCIA — BLOQUES V6 Y AI POR DISTRITO
A5: PROYECTO IN PIURA | CUI 2669244 | Cuenca Alta del Río Piura | UTM WGS 84 Zona 17S (EPSG:32717)
A6: Fuente: Bloques V6 (Bloques V6.kml) y catálogo V6 (datos/unidades_liberacion_areas.csv), ANIN-DIME-SESDI 2026. Área de influencia aprobada (AI_aprobado_2.shp), ANIN-DIME-SESDI 2026; sin los AI de los bloques retirados 74 y 75. Límites distritales INEI (referencial)
A8: Provincia | B8: Distrito | C8: Área del distrito (ha, ref.) | D8: N.° bloques | E8: Área bloques (ha) | F8: Polígonos AI | G8: Área AI (ha) | H8: Bloques + AI (ha) | I8: % del área de bloques
A9: Ayabaca | B9: Frías | C9: 56736.6 | D9: =COUNTIFS('A1_Bloques'!$D$9:$D$125,B9) | E9: =SUMIFS('A1_Bloques'!$E$9:$E$125,'A1_Bloques'!$D$9:$D$125,B9) | F9: =SUMIFS('A1_Bloques'!$F$9:$F$125,'A1_Bloques'!$D$9:$D$125,B9) | G9: =SUMIFS('A1_Bloques'!$G$9:$G$125,'A1_Bloques'!$D$9:$D$125,B9) | H9: =E9+G9 | I9: =E9/$E$24
A10: Huancabamba | B10: Canchaque | C10: 30327.7 | D10: =COUNTIFS('A1_Bloques'!$D$9:$D$125,B10) | E10: =SUMIFS('A1_Bloques'!$E$9:$E$125,'A1_Bloques'!$D$9:$D$125,B10) | F10: =SUMIFS('A1_Bloques'!$F$9:$F$125,'A1_Bloques'!$D$9:$D$125,B10) | G10: =SUMIFS('A1_Bloques'!$G$9:$G$125,'A1_Bloques'!$D$9:$D$125,B10) | H10: =E10+G10 | I10: =E10/$E$24
A11: Huancabamba | B11: Huancabamba | C11: 45862.9 | D11: =COUNTIFS('A1_Bloques'!$D$9:$D$125,B11) | E11: =SUMIFS('A1_Bloques'!$E$9:$E$125,'A1_Bloques'!$D$9:$D$125,B11) | F11: =SUMIFS('A1_Bloques'!$F$9:$F$125,'A1_Bloques'!$D$9:$D$125,B11) | G11: =SUMIFS('A1_Bloques'!$G$9:$G$125,'A1_Bloques'!$D$9:$D$125,B11) | H11: =E11+G11 | I11: =E11/$E$24
A12: Huancabamba | B12: Huarmaca | C12: 194552 | D12: =COUNTIFS('A1_Bloques'!$D$9:$D$125,B12) | E12: =SUMIFS('A1_Bloques'!$E$9:$E$125,'A1_Bloques'!$D$9:$D$125,B12) | F12: =SUMIFS('A1_Bloques'!$F$9:$F$125,'A1_Bloques'!$D$9:$D$125,B12) | G12: =SUMIFS('A1_Bloques'!$G$9:$G$125,'A1_Bloques'!$D$9:$D$125,B12) | H12: =E12+G12 | I12: =E12/$E$24
A13: Huancabamba | B13: Lalaquiz | C13: 15627.3 | D13: =COUNTIFS('A1_Bloques'!$D$9:$D$125,B13) | E13: =SUMIFS('A1_Bloques'!$E$9:$E$125,'A1_Bloques'!$D$9:$D$125,B13) | F13: =SUMIFS('A1_Bloques'!$F$9:$F$125,'A1_Bloques'!$D$9:$D$125,B13) | G13: =SUMIFS('A1_Bloques'!$G$9:$G$125,'A1_Bloques'!$D$9:$D$125,B13) | H13: =E13+G13 | I13: =E13/$E$24
A14: Huancabamba | B14: San Miguel de El Faique | C14: 22112.5 | D14: =COUNTIFS('A1_Bloques'!$D$9:$D$125,B14) | E14: =SUMIFS('A1_Bloques'!$E$9:$E$125,'A1_Bloques'!$D$9:$D$125,B14) | F14: =SUMIFS('A1_Bloques'!$F$9:$F$125,'A1_Bloques'!$D$9:$D$125,B14) | G14: =SUMIFS('A1_Bloques'!$G$9:$G$125,'A1_Bloques'!$D$9:$D$125,B14) | H14: =E14+G14 | I14: =E14/$E$24
A15: Morropón | B15: Buenos Aires | C15: 23989 | D15: =COUNTIFS('A1_Bloques'!$D$9:$D$125,B15) | E15: =SUMIFS('A1_Bloques'!$E$9:$E$125,'A1_Bloques'!$D$9:$D$125,B15) | F15: =SUMIFS('A1_Bloques'!$F$9:$F$125,'A1_Bloques'!$D$9:$D$125,B15) | G15: =SUMIFS('A1_Bloques'!$G$9:$G$125,'A1_Bloques'!$D$9:$D$125,B15) | H15: =E15+G15 | I15: =E15/$E$24
A16: Morropón | B16: Chalaco | C16: 15738.9 | D16: =COUNTIFS('A1_Bloques'!$D$9:$D$125,B16) | E16: =SUMIFS('A1_Bloques'!$E$9:$E$125,'A1_Bloques'!$D$9:$D$125,B16) | F16: =SUMIFS('A1_Bloques'!$F$9:$F$125,'A1_Bloques'!$D$9:$D$125,B16) | G16: =SUMIFS('A1_Bloques'!$G$9:$G$125,'A1_Bloques'!$D$9:$D$125,B16) | H16: =E16+G16 | I16: =E16/$E$24
A17: Morropón | B17: Chulucanas | C17: 85798.2 | D17: =COUNTIFS('A1_Bloques'!$D$9:$D$125,B17) | E17: =SUMIFS('A1_Bloques'!$E$9:$E$125,'A1_Bloques'!$D$9:$D$125,B17) | F17: =SUMIFS('A1_Bloques'!$F$9:$F$125,'A1_Bloques'!$D$9:$D$125,B17) | G17: =SUMIFS('A1_Bloques'!$G$9:$G$125,'A1_Bloques'!$D$9:$D$125,B17) | H17: =E17+G17 | I17: =E17/$E$24
A18: Morropón | B18: Morropón | C18: 16612.7 | D18: =COUNTIFS('A1_Bloques'!$D$9:$D$125,B18) | E18: =SUMIFS('A1_Bloques'!$E$9:$E$125,'A1_Bloques'!$D$9:$D$125,B18) | F18: =SUMIFS('A1_Bloques'!$F$9:$F$125,'A1_Bloques'!$D$9:$D$125,B18) | G18: =SUMIFS('A1_Bloques'!$G$9:$G$125,'A1_Bloques'!$D$9:$D$125,B18) | H18: =E18+G18 | I18: =E18/$E$24
A19: Morropón | B19: Salitral | C19: 62324 | D19: =COUNTIFS('A1_Bloques'!$D$9:$D$125,B19) | E19: =SUMIFS('A1_Bloques'!$E$9:$E$125,'A1_Bloques'!$D$9:$D$125,B19) | F19: =SUMIFS('A1_Bloques'!$F$9:$F$125,'A1_Bloques'!$D$9:$D$125,B19) | G19: =SUMIFS('A1_Bloques'!$G$9:$G$125,'A1_Bloques'!$D$9:$D$125,B19) | H19: =E19+G19 | I19: =E19/$E$24
A20: Morropón | B20: San Juan de Bigote | C20: 24019.1 | D20: =COUNTIFS('A1_Bloques'!$D$9:$D$125,B20) | E20: =SUMIFS('A1_Bloques'!$E$9:$E$125,'A1_Bloques'!$D$9:$D$125,B20) | F20: =SUMIFS('A1_Bloques'!$F$9:$F$125,'A1_Bloques'!$D$9:$D$125,B20) | G20: =SUMIFS('A1_Bloques'!$G$9:$G$125,'A1_Bloques'!$D$9:$D$125,B20) | H20: =E20+G20 | I20: =E20/$E$24
... A23: Morropón | B23: Yamango | C23: 21653.9 | D23: =COUNTIFS('A1_Bloques'!$D$9:$D$125,B23) | E23: =SUMIFS('A1_Bloques'!$E$9:$E$125,'A1_Bloques'!$D$9:$D$125,B23) | F23: =SUMIFS('A1_Bloques'!$F$9:$F$125,'A1_Bloques'!$D$9:$D$125,B23) | G23: =SUMIFS('A1_Bloques'!$G$9:$G$125,'A1_Bloques'!$D$9:$D$125,B23) | H23: =E23+G23 | I23: =E23/$E$24
A24: TOTAL | B24: 15 distritos | C24: =SUM(C9:C23) | D24: =SUM(D9:D23) | E24: =SUM(E9:E23) | F24: =SUM(F9:F23) | G24: =SUM(G9:G23) | H24: =SUM(H9:H23) | I24: =SUM(I9:I23)
A26: Resumen por provincia
A27: Provincia | B27: N.° distritos | C27: Área de distritos (ha, ref.) | D27: N.° bloques | E27: Área bloques (ha) | F27: Área AI (ha) | G27: Bloques + AI (ha)
A28: Ayabaca | B28: =COUNTIFS($A$9:$A$23,A28) | C28: =SUMIFS($C$9:$C$23,$A$9:$A$23,A28) | D28: =SUMIFS($D$9:$D$23,$A$9:$A$23,A28) | E28: =SUMIFS($E$9:$E$23,$A$9:$A$23,A28) | F28: =SUMIFS($G$9:$G$23,$A$9:$A$23,A28) | G28: =E28+F28
A29: Huancabamba | B29: =COUNTIFS($A$9:$A$23,A29) | C29: =SUMIFS($C$9:$C$23,$A$9:$A$23,A29) | D29: =SUMIFS($D$9:$D$23,$A$9:$A$23,A29) | E29: =SUMIFS($E$9:$E$23,$A$9:$A$23,A29) | F29: =SUMIFS($G$9:$G$23,$A$9:$A$23,A29) | G29: =E29+F29
A30: Morropón | B30: =COUNTIFS($A$9:$A$23,A30) | C30: =SUMIFS($C$9:$C$23,$A$9:$A$23,A30) | D30: =SUMIFS($D$9:$D$23,$A$9:$A$23,A30) | E30: =SUMIFS($E$9:$E$23,$A$9:$A$23,A30) | F30: =SUMIFS($G$9:$G$23,$A$9:$A$23,A30) | G30: =E30+F30
A31: TOTAL | B31: =SUM(B28:B30) | C31: =SUM(C28:C30) | D31: =SUM(D28:D30) | E31: =SUM(E28:E30) | F31: =SUM(F28:F30) | G31: =SUM(G28:G30)
A33: Controles
A34: Total de bloques = 117 | D34: =IF(D24=117,"OK","REVISAR")
A35: Área de bloques = 12,270.235 ha | D35: =IF(ABS(E24-12270.235)<0.001,"OK","REVISAR")
A36: Área AI = suma de A1_Bloques | D36: =IF(ABS(G24-SUM('A1_Bloques'!$G$9:$G$125))<0.001,"OK","REVISAR")
A37: Resumen provincial = distrital | D37: =IF(ABS(E31-E24)<0.001,"OK","REVISAR")
A39: El área de influencia (AI) de cada bloque se asigna al distrito de su bloque. El área de los distritos proviene de la capa INEI simplificada y es referencial. Cifras en hectáreas, calculadas en UTM WGS84 17S.

Sheet A1_Microcuencas
A1: AUTORIDAD NACIONAL DE INFRAESTRUCTURA - ANIN
A2: DIRECCIÓN DE INTERVENCIONES MULTISECTORIALES Y DE EMERGENCIA - DIME
A3: SUBDIRECCIÓN DE ESTUDIOS DE INVERSIÓN - SESDI
A4: A1. BLOQUES V6 POR MICROCUENCA PRIORIZADA
A5: PROYECTO IN PIURA | CUI 2669244 | Cuenca Alta del Río Piura | UTM WGS 84 Zona 17S (EPSG:32717)
A6: Fuente: Bloques V6 (Bloques V6.kml) y catálogo V6 (datos/unidades_liberacion_areas.csv), ANIN-DIME-SESDI 2026
A8: Microcuenca (código) | B8: Provincia(s) | C8: Distrito(s) | D8: N.° bloques | E8: Área bloques (ha) | F8: Área AI (ha) | G8: Sup. MSAVI ≤ 0.4976 (ha)
A9: C1076-Q9581 | B9: Morropón | C9: Salitral | D9: =COUNTIFS('A1_Bloques'!$B$9:$B$125,A9) | E9: =SUMIFS('A1_Bloques'!$E$9:$E$125,'A1_Bloques'!$B$9:$B$125,A9) | F9: =SUMIFS('A1_Bloques'!$G$9:$G$125,'A1_Bloques'!$B$9:$B$125,A9) | G9: =SUMIFS('A1_Bloques'!$I$9:$I$125,'A1_Bloques'!$B$9:$B$125,A9)
A10: C1076-Q9584 | B10: Huancabamba, Morropón | C10: Salitral, San Miguel de El Faique | D10: =COUNTIFS('A1_Bloques'!$B$9:$B$125,A10) | E10: =SUMIFS('A1_Bloques'!$E$9:$E$125,'A1_Bloques'!$B$9:$B$125,A10) | F10: =SUMIFS('A1_Bloques'!$G$9:$G$125,'A1_Bloques'!$B$9:$B$125,A10) | G10: =SUMIFS('A1_Bloques'!$I$9:$I$125,'A1_Bloques'!$B$9:$B$125,A10)
A11: C1076-Q9585 | B11: Huancabamba | C11: Canchaque, San Miguel de El Faique | D11: =COUNTIFS('A1_Bloques'!$B$9:$B$125,A11) | E11: =SUMIFS('A1_Bloques'!$E$9:$E$125,'A1_Bloques'!$B$9:$B$125,A11) | F11: =SUMIFS('A1_Bloques'!$G$9:$G$125,'A1_Bloques'!$B$9:$B$125,A11) | G11: =SUMIFS('A1_Bloques'!$I$9:$I$125,'A1_Bloques'!$B$9:$B$125,A11)
A12: C1076-Q9586 | B12: Huancabamba | C12: San Miguel de El Faique | D12: =COUNTIFS('A1_Bloques'!$B$9:$B$125,A12) | E12: =SUMIFS('A1_Bloques'!$E$9:$E$125,'A1_Bloques'!$B$9:$B$125,A12) | F12: =SUMIFS('A1_Bloques'!$G$9:$G$125,'A1_Bloques'!$B$9:$B$125,A12) | G12: =SUMIFS('A1_Bloques'!$I$9:$I$125,'A1_Bloques'!$B$9:$B$125,A12)
A13: C1076-Q9587 | B13: Huancabamba | C13: Canchaque | D13: =COUNTIFS('A1_Bloques'!$B$9:$B$125,A13) | E13: =SUMIFS('A1_Bloques'!$E$9:$E$125,'A1_Bloques'!$B$9:$B$125,A13) | F13: =SUMIFS('A1_Bloques'!$G$9:$G$125,'A1_Bloques'!$B$9:$B$125,A13) | G13: =SUMIFS('A1_Bloques'!$I$9:$I$125,'A1_Bloques'!$B$9:$B$125,A13)
A14: C1076-Q9588 | B14: Huancabamba | C14: Huarmaca | D14: =COUNTIFS('A1_Bloques'!$B$9:$B$125,A14) | E14: =SUMIFS('A1_Bloques'!$E$9:$E$125,'A1_Bloques'!$B$9:$B$125,A14) | F14: =SUMIFS('A1_Bloques'!$G$9:$G$125,'A1_Bloques'!$B$9:$B$125,A14) | G14: =SUMIFS('A1_Bloques'!$I$9:$I$125,'A1_Bloques'!$B$9:$B$125,A14)
A15: C1076-Q9589 | B15: Huancabamba | C15: Huarmaca | D15: =COUNTIFS('A1_Bloques'!$B$9:$B$125,A15) | E15: =SUMIFS('A1_Bloques'!$E$9:$E$125,'A1_Bloques'!$B$9:$B$125,A15) | F15: =SUMIFS('A1_Bloques'!$G$9:$G$125,'A1_Bloques'!$B$9:$B$125,A15) | G15: =SUMIFS('A1_Bloques'!$I$9:$I$125,'A1_Bloques'!$B$9:$B$125,A15)
A16: C1076-Q9592 | B16: Huancabamba | C16: Huarmaca | D16: =COUNTIFS('A1_Bloques'!$B$9:$B$125,A16) | E16: =SUMIFS('A1_Bloques'!$E$9:$E$125,'A1_Bloques'!$B$9:$B$125,A16) | F16: =SUMIFS('A1_Bloques'!$G$9:$G$125,'A1_Bloques'!$B$9:$B$125,A16) | G16: =SUMIFS('A1_Bloques'!$I$9:$I$125,'A1_Bloques'!$B$9:$B$125,A16)
A17: C1076-Q9593 | B17: Huancabamba | C17: Huarmaca | D17: =COUNTIFS('A1_Bloques'!$B$9:$B$125,A17) | E17: =SUMIFS('A1_Bloques'!$E$9:$E$125,'A1_Bloques'!$B$9:$B$125,A17) | F17: =SUMIFS('A1_Bloques'!$G$9:$G$125,'A1_Bloques'!$B$9:$B$125,A17) | G17: =SUMIFS('A1_Bloques'!$I$9:$I$125,'A1_Bloques'!$B$9:$B$125,A17)
A18: C1077-Q9566 | B18: Morropón | C18: Buenos Aires | D18: =COUNTIFS('A1_Bloques'!$B$9:$B$125,A18) | E18: =SUMIFS('A1_Bloques'!$E$9:$E$125,'A1_Bloques'!$B$9:$B$125,A18) | F18: =SUMIFS('A1_Bloques'!$G$9:$G$125,'A1_Bloques'!$B$9:$B$125,A18) | G18: =SUMIFS('A1_Bloques'!$I$9:$I$125,'A1_Bloques'!$B$9:$B$125,A18)
A19: C1077-Q9579 | B19: Morropón | C19: Buenos Aires, Salitral | D19: =COUNTIFS('A1_Bloques'!$B$9:$B$125,A19) | E19: =SUMIFS('A1_Bloques'!$E$9:$E$125,'A1_Bloques'!$B$9:$B$125,A19) | F19: =SUMIFS('A1_Bloques'!$G$9:$G$125,'A1_Bloques'!$B$9:$B$125,A19) | G19: =SUMIFS('A1_Bloques'!$I$9:$I$125,'A1_Bloques'!$B$9:$B$125,A19)
A20: C1077-Q9580 | B20: Morropón | C20: Buenos Aires | D20: =COUNTIFS('A1_Bloques'!$B$9:$B$125,A20) | E20: =SUMIFS('A1_Bloques'!$E$9:$E$125,'A1_Bloques'!$B$9:$B$125,A20) | F20: =SUMIFS('A1_Bloques'!$G$9:$G$125,'A1_Bloques'!$B$9:$B$125,A20) | G20: =SUMIFS('A1_Bloques'!$I$9:$I$125,'A1_Bloques'!$B$9:$B$125,A20)
... A34: C1096-Q9564 | B34: Ayabaca, Morropón | C34: Frías, Santo Domingo | D34: =COUNTIFS('A1_Bloques'!$B$9:$B$125,A34) | E34: =SUMIFS('A1_Bloques'!$E$9:$E$125,'A1_Bloques'!$B$9:$B$125,A34) | F34: =SUMIFS('A1_Bloques'!$G$9:$G$125,'A1_Bloques'!$B$9:$B$125,A34) | G34: =SUMIFS('A1_Bloques'!$I$9:$I$125,'A1_Bloques'!$B$9:$B$125,A34)
A35: TOTAL | B35: 26 microcuencas | D35: =SUM(D9:D34) | E35: =SUM(E9:E34) | F35: =SUM(F9:F34) | G35: =SUM(G9:G34)
A37: Código de microcuenca según la capa de bloques V6 (campo MICROC). La capa de límites de las microcuencas priorizadas no forma parte de este paquete: [POR DEFINIR] su remisión por el especialista SIG.

Sheet A1_Bloques
A1: AUTORIDAD NACIONAL DE INFRAESTRUCTURA - ANIN
A2: DIRECCIÓN DE INTERVENCIONES MULTISECTORIALES Y DE EMERGENCIA - DIME
A3: SUBDIRECCIÓN DE ESTUDIOS DE INVERSIÓN - SESDI
A4: A1. DETALLE DE LOS 117 BLOQUES DE INTERVENCIÓN V6
A5: PROYECTO IN PIURA | CUI 2669244 | Cuenca Alta del Río Piura | UTM WGS 84 Zona 17S (EPSG:32717)
A6: Fuente: Bloques V6 (Bloques V6.kml) y catálogo V6 (datos/unidades_liberacion_areas.csv), ANIN-DIME-SESDI 2026. Área de influencia aprobada (AI_aprobado_2.shp), ANIN-DIME-SESDI 2026; sin los AI de los bloques retirados 74 y 75. MSAVI 2024 (traspaso V6). Mapa Nacional de Ecosistemas del Perú, MINAM 2018 (R.M. N.° 440-2018-MINAM), recorte al ámbito
A8: Bloque | B8: Microcuenca | C8: Provincia | D8: Distrito | E8: Área bloque (ha) | F8: Polígonos AI | G8: Área AI (ha) | H8: MSAVI 2024 media | I8: Sup. MSAVI ≤ 0.4976 (ha) | J8: Ecosistema dominante | K8: % ecosistema dominante | L8: CCPP asociados | M8: Punto interior ESTE (m) | N8: Punto interior NORTE (m)
A9: 27 | B9: C1096-Q9556 | C9: Ayabaca | D9: Frías | E9: 78.154 | F9: 1 | G9: 81.506 | H9: 0.5323 | I9: 29.306 | J9: Zona agrícola | K9: 1 | L9: 2 | M9: 613421.61 | N9: 9450244.7
A10: 3 | B10: C1096-Q9545 | C10: Ayabaca | D10: Frías | E10: 459.295 | F10: 1 | G10: 92.193 | H10: 0.5677 | I10: 133.481 | J10: Zona agrícola | K10: 0.9454 | L10: 5 | M10: 606765.09 | N10: 9458475.9
A11: 36 | B11: C1096-Q9547 | C11: Ayabaca | D11: Frías | E11: 24.843 | F11: 1 | G11: 32.298 | H11: 0.5395 | I11: 8.852 | J11: Zona agrícola | K11: 1 | L11: 1 | M11: 606332.5 | N11: 9454727
A12: 39 | B12: C1096-Q9564 | C12: Ayabaca | D12: Frías | E12: 68.569 | F12: 1 | G12: 91.192 | H12: 0.7016 | I12: 2.636 | J12: Matorral andino | K12: 1 | L12: 1 | M12: 618400.45 | N12: 9448932.4
A13: 56 | B13: C1096-Q9564 | C13: Ayabaca | D13: Frías | E13: 77.666 | F13: 1 | G13: 22.2 | H13: 0.6777 | I13: 2.171 | J13: Bosque relicto montano de vertiente occidental | K13: 0.5388 | L13: 2 | M13: 621631.02 | N13: 9452849.2
A14: 6 | B14: C1096-Q9547 | C14: Ayabaca | D14: Frías | E14: 168.411 | F14: 2 | G14: 165.147 | H14: 0.5381 | I14: 59.635 | J14: Zona agrícola | K14: 0.9752 | L14: 3 | M14: 605211.18 | N14: 9455229.2
A15: M17B10 | B15: C1096-Q9556 | C15: Ayabaca | D15: Frías | E15: 75.363 | F15: 1 | G15: 41.649 | H15: 0.4725 | I15: 55.265 | J15: Zona agrícola | K15: 0.5748 | L15: 0 | M15: 606090.26 | N15: 9447318.8
A16: M17B5 | B16: C1096-Q9556 | C16: Ayabaca | D16: Frías | E16: 74.028 | F16: 1 | G16: 23.733 | H16: 0.5482 | I16: 21.426 | J16: Bosque estacionalmente seco de colina y montaña | K16: 0.7086 | L16: 1 | M16: 608932.95 | N16: 9445588.3
A17: M17B6 | B17: C1096-Q9556 | C17: Ayabaca | D17: Frías | E17: 106.538 | F17: 1 | G17: 64.622 | H17: 0.4464 | I17: 87.169 | J17: Bosque estacionalmente seco de colina y montaña | K17: 1 | L17: 3 | M17: 607245.17 | N17: 9446176.6
A18: M17B7 | B18: C1096-Q9556 | C18: Ayabaca | D18: Frías | E18: 258.837 | F18: 1 | G18: 206.565 | H18: 0.5087 | I18: 125.266 | J18: Zona agrícola | K18: 0.559 | L18: 1 | M18: 608879.78 | N18: 9448019.2
A19: 21 | B19: C1081-Q9591 | C19: Huancabamba | D19: Canchaque | E19: 84.227 | F19: 1 | G19: 34.349 | H19: 0.6201 | I19: 4.357 | J19: Zona agrícola | K19: 0.5607 | L19: 1 | M19: 654592.14 | N19: 9417738.6
A20: 24 | B20: C1081-Q9583 | C20: Huancabamba | D20: Canchaque | E20: 90.159 | F20: 1 | G20: 219.755 | H20: 0.6748 | I20: 2.061 | J20: Zona agrícola | K20: 0.6608 | L20: 1 | M20: 652157.25 | N20: 9414359.2
... A125: M28B4 | B125: C1086-Q9575 | C125: Morropón | D125: Yamango | E125: 283.428 | F125: 1 | G125: 116.586 | H125: 0.4275 | I125: 212.024 | J125: Bosque estacionalmente seco de colina y montaña | K125: 1 | L125: 3 | M125: 626285.83 | N125: 9427072.5
A126: TOTAL | E126: =SUM(E9:E125) | F126: =SUM(F9:F125) | G126: =SUM(G9:G125) | I126: =SUM(I9:I125)
A128: La columna «CCPP asociados» cuenta los centros poblados vinculados al bloque; un mismo centro poblado puede atender a varios bloques, por lo que no se suma entre bloques. El punto interior es un punto garantizado dentro del polígono (UTM WGS84 17S), útil para ubicar el bloque.

Sheet A2_Criterios
A1: AUTORIDAD NACIONAL DE INFRAESTRUCTURA - ANIN
A2: DIRECCIÓN DE INTERVENCIONES MULTISECTORIALES Y DE EMERGENCIA - DIME
A3: SUBDIRECCIÓN DE ESTUDIOS DE INVERSIÓN - SESDI
A4: A2. MATRIZ DE CRITERIOS DE SELECCIÓN Y PRIORIZACIÓN DE LOS ÁMBITOS DE INTERVENCIÓN
A5: PROYECTO IN PIURA | CUI 2669244 | Cuenca Alta del Río Piura | UTM WGS 84 Zona 17S (EPSG:32717)
A6: Fuente: Nota Técnica de Meso y Microlocalización IN (ANIN-DIME, 2023) y procedimiento AdR-CCC territorial del Proyecto IN Piura
A8: Paso | B8: Etapa | C8: Criterio | D8: Variable / parámetro y regla | E8: Fuente de información | F8: Producto / resultado
A9: 1 | B9: Mesolocalización | C9: Peligro integrado (PI) en la cuenca alta | D9: Modelamiento GIS por análisis multicriterio (MCA) y proceso analítico jerárquico (AHP) de: peligro por movimientos en masa (PMM: geología, pendiente, TPI, cobertura vegetal; desencadenante: precipitación acumulada multianual; parámetro: tendencia a la degradación TAU/NDVI), erosión potencial hídrica (EPH) y peligro generador de inundaciones (PGI: pendiente, escorrentía total, NDVI). PI en 5 niveles (muy bajo a muy alto). | E9: Sentinel-2, Landsat, DEM, WorldClim, SENAMHI, INGEMMET | F9: Mapa de peligro integrado y microcuencas priorizadas (26 microcuencas con bloques V6)
A10: 2 | B10: Digitalización | C10: Áreas con PI medio, alto y muy alto | D10: Delimitación semiautomática o manual de bloques sobre las microcuencas priorizadas, en zonas de origen del peligro (cuenca alta), no en la zona de impacto. | E10: Mapa de PI; imágenes satelitales | F10: Bloques preliminares de intervención
A11: 3 | B11: Filtros de exclusión | C11: Restos arqueológicos | D11: Exclusión de superficies con sitios arqueológicos declarados. | E11: SIGDA — Ministerio de Cultura | F11: Bloques depurados
A12: 3 | B12: Filtros de exclusión | C12: Concesiones mineras activas | D12: Exclusión de superficies con concesiones mineras vigentes. | E12: INGEMMET (GEOCATMIN) | F12: Bloques depurados
A13: 3 | B13: Filtros de exclusión | C13: Infraestructura eléctrica | D13: Exclusión de líneas eléctricas con franja (buffer) de 10 m. | E13: OSINERGMIN | F13: Bloques depurados
A14: 3 | B14: Filtros de exclusión | C14: Áreas Naturales Protegidas | D14: Exclusión de superficies dentro de ANP. | E14: SERNANP | F14: Bloques depurados
A15: 4 | B15: Idoneidad | C15: Accesibilidad | D15: Acceso desde la red vial y caminos identificables. | E15: Red vial MTC; imágenes satelitales | F15: Bloques accesibles
A16: 4 | B16: Idoneidad | C16: Pendiente máxima | D16: Pendiente ≤ 75 %. | E16: DEM | F16: Bloques técnicamente intervenibles
A17: 4 | B17: Idoneidad | C17: Cobertura territorial | D17: Cobertura de los distritos priorizados (15 distritos de Ayabaca, Huancabamba y Morropón). | E17: Límites INEI | F17: Distribución territorial de bloques
A18: 4 | B18: Idoneidad | C18: Déficit hídrico futuro | D18: Déficit hídrico proyectado con el modelo MPI-ESM1-2HR, escenario SSP5-8.5, periodo 2021-2040. | E18: Escenarios CMIP6 | F18: Priorización por exposición climática
A19: 5 | B19: Tamizaje predial | C19: Predios interceptados | D19: Máximo 19 predios rurales interceptados por bloque. | E19: Catastro rural (predios) | F19: Bloques con viabilidad de saneamiento
A20: 5 | B20: Tamizaje predial | C20: Uso agrícola | D20: Exclusión de áreas agrícolas. | E20: Imágenes satelitales; catastro | F20: Bloques sin conflicto de uso
... A22: 6 | B22: Verificación de campo | C22: Riesgo social y aceptación | D22: Riesgo social, aceptación de titulares y posesionarios (fichas F-DS y F-LA de liberación de áreas: identificación de prediantes, actas). | E22: Equipo social y legal | F22: Bloques con aceptación; codificación M#-B#

Sheet A3_Poblacion_CCPP
A1: AUTORIDAD NACIONAL DE INFRAESTRUCTURA - ANIN
A2: DIRECCIÓN DE INTERVENCIONES MULTISECTORIALES Y DE EMERGENCIA - DIME
A3: SUBDIRECCIÓN DE ESTUDIOS DE INVERSIÓN - SESDI
A4: A3. CENTROS POBLADOS ASOCIADOS A LOS BLOQUES V6 — POBLACIÓN Y VIVIENDAS
A5: PROYECTO IN PIURA | CUI 2669244 | Cuenca Alta del Río Piura | UTM WGS 84 Zona 17S (EPSG:32717)
A6: Fuente: INEI, capa de centros poblados con población censal; asociación centro poblado–bloque del equipo social (CentrosPoblados-INEI-Bloques_v5, 24.09.2026, y bloques adicionales 83-87)
A8: IDCCPP | B8: Centro poblado | C8: Provincia | D8: Distrito | E8: Bloques asociados | F8: N.° bloques | G8: Tipo | H8: Población total | I8: Hombres | J8: Mujeres | K8: Población vulnerable | L8: Viviendas particulares | M8: ESTE (m) | N8: NORTE (m) | O8: Control UTM | P8: Observación
A9: 2002020073 | B9: Banda de la Cruz | C9: Ayabaca | D9: Frías | E9: 56 | F9: 1 | G9: Rural | H9: 75 | I9: 35 | J9: 40 | K9: 13 | L9: 19 | M9: 619831.93 | N9: 9452099.2 | O9: OK
A10: 2002020092 | B10: El Guabo | C10: Ayabaca | D10: Frías | E10: M17B5, M17B6 | F10: 2 | G10: Rural | H10: 74 | I10: 43 | J10: 31 | K10: 11 | L10: 20 | M10: 606700.07 | N10: 9445746.9 | O10: OK | P10: Datos tomados del mismo centro poblado en otro bloque
A11: 2002020123 | B11: El Mirador | C11: Ayabaca | D11: Frías | E11: 3 | F11: 1 | G11: Rural | H11: 25 | I11: 16 | J11: 9 | K11: 3 | L11: 6 | M11: 605865.68 | N11: 9459026.7 | O11: OK
A12: 2002020057 | B12: Guabal | C12: Ayabaca | D12: Frías | E12: 6, 36 | F12: 2 | G12: Rural | H12: 280 | I12: 133 | J12: 147 | K12: 47 | L12: 88 | M12: 607202.67 | N12: 9454584.6 | O12: OK
A13: 2002020060 | B13: Guanabano Alto | C13: Ayabaca | D13: Frías | E13: 6 | F13: 1 | G13: Rural | H13: 248 | I13: 120 | J13: 128 | K13: 28 | L13: 75 | M13: 604359.22 | N13: 9454523.1 | O13: OK
A14: 2002020107 | B14: Huasipe de Geraldo | C14: Ayabaca | D14: Frías | E14: 3 | F14: 1 | G14: Rural | H14: 116 | I14: 55 | J14: 61 | K14: 25 | L14: 35 | M14: 608730.61 | N14: 9459375.4 | O14: OK
A15: 2002020019 | B15: Huayabal | C15: Ayabaca | D15: Frías | E15: 3 | F15: 1 | G15: Rural | H15: 47 | I15: 25 | J15: 22 | K15: 4 | L15: 20 | M15: 605127.04 | N15: 9458671 | O15: OK
A16: 2002020085 | B16: La Cria | C16: Ayabaca | D16: Frías | E16: 39 | F16: 1 | G16: Rural | H16: 327 | I16: 166 | J16: 161 | K16: 35 | L16: 85 | M16: 619276.57 | N16: 9449240.8 | O16: OK
A17: 2002020127 | B17: Linderos de Misquis | C17: Ayabaca | D17: Frías | E17: 27 | F17: 1 | G17: Rural | H17: 28 | I17: 13 | J17: 15 | K17: 7 | L17: 14 | M17: 612421.49 | N17: 9450333.3 | O17: OK
A18: 2002020018 | B18: Los Checches | C18: Ayabaca | D18: Frías | E18: 3 | F18: 1 | G18: Rural | H18: 191 | I18: 96 | J18: 95 | K18: 32 | L18: 53 | M18: 607045.09 | N18: 9459366.3 | O18: OK
A19: 2002020058 | B19: Nogal | C19: Ayabaca | D19: Frías | E19: 6 | F19: 1 | G19: Rural | H19: 9 | I19: 4 | J19: 5 | K19: 0 | L19: 3 | M19: 605223.43 | N19: 9454965.5 | O19: OK
A20: 2002020126 | B20: Nueva Esperanza de Misquis | C20: Ayabaca | D20: Frías | E20: 27 | F20: 1 | G20: Rural | H20: 83 | I20: 41 | J20: 42 | K20: 16 | L20: 25 | M20: 612288.24 | N20: 9449603.1 | O20: OK
A21: 2002020089 | B21: Pampa de Ramada | C21: Ayabaca | D21: Frías | E21: M17B7 | F21: 1 | G21: Rural | H21: 107 | I21: 51 | J21: 56 | K21: 21 | L21: 32 | M21: 609224.33 | N21: 9449680.7 | O21: OK
A22: 2002020091 | B22: Platanal Alto | C22: Ayabaca | D22: Frías | E22: M17B6 | F22: 1 | G22: Rural | H22: 155 | I22: 84 | J22: 71 | K22: 36 | L22: 65 | M22: 606024.3 | N22: 9446104.8 | O22: OK
... A125: 2004070001 | B125: Bigote | C125: Morropón | D125: San Juan de Bigote | E125: M3B3 | F125: 1 | G125: Urbano | H125: 0 | I125: 0 | J125: 0 | K125: 0 | L125: 0 | M125: 634502.21 | N125: 9411898.4 | O125: OK
B126: Cardal | C126: Morropón | D126: San Juan de Bigote | E126: 87 | F126: 1 | G126: Rural | H126: 400 | O126: SIN COORDENADAS | P126: Solo población total (sin desagregar por sexo, población vulnerable ni viviendas); Sin coordenadas en la fuente
B127: Dótor | C127: Morropón | D127: San Juan de Bigote | E127: 85, 87 | F127: 2 | G127: Rural | H127: 240 | O127: SIN COORDENADAS | P127: Solo población total (sin desagregar por sexo, población vulnerable ni viviendas); Sin coordenadas en la fuente
A128: 2004070011 | B128: La Pareja | C128: Morropón | D128: San Juan de Bigote | E128: M11B3 | F128: 1 | G128: Urbano | H128: 0 | I128: 0 | J128: 0 | K128: 0 | L128: 0 | M128: 639952.07 | N128: 9413029.8 | O128: OK
A129: 2004070019 | B129: Manzanares | C129: Morropón | D129: San Juan de Bigote | E129: M3B6 | F129: 1 | G129: Rural | H129: 117 | I129: 64 | J129: 53 | K129: 21 | L129: 38 | M129: 637332.87 | N129: 9412499 | O129: OK
A130: 2004070022 | B130: Miguel Pampa | C130: Morropón | D130: San Juan de Bigote | E130: 77, 83, 84 | F130: 3 | G130: Rural | H130: 188 | I130: 95 | J130: 93 | K130: 21 | L130: 74 | M130: 639388.81 | N130: 9410923.7 | O130: OK
B131: Nueva Esperanza | C131: Morropón | D131: San Juan de Bigote | E131: 86, 87 | F131: 2 | G131: Rural | H131: 65 | O131: SIN COORDENADAS | P131: Solo población total (sin desagregar por sexo, población vulnerable ni viviendas); Sin coordenadas en la fuente
A132: 2004070024 | B132: Polluco | C132: Morropón | D132: San Juan de Bigote | E132: M3B7 | F132: 1 | G132: Rural | H132: 45 | I132: 19 | J132: 26 | K132: 4 | L132: 22 | M132: 637525.13 | N132: 9414333.6 | O132: OK
A133: 2004070012 | B133: Quemazon | C133: Morropón | D133: San Juan de Bigote | E133: M11B3 | F133: 1 | G133: Urbano | H133: 0 | I133: 0 | J133: 0 | K133: 0 | L133: 0 | M133: 641647.19 | N133: 9412507 | O133: OK
A134: 2004070027 | B134: San Juan Bautista | C134: Morropón | D134: San Juan de Bigote | E134: M3B5 | F134: 1 | G134: Rural | H134: 116 | I134: 51 | J134: 65 | K134: 7 | L134: 33 | M134: 635861.76 | N134: 9411993.2 | O134: OK
A135: 2004070009 | B135: Santa Rosa | C135: Morropón | D135: San Juan de Bigote | E135: M3B8 | F135: 1 | G135: Rural | H135: 178 | I135: 91 | J135: 87 | K135: 17 | L135: 67 | M135: 632130.33 | N135: 9414106.7 | O135: OK
A136: 2004070041 | B136: Sinai | C136: Morropón | D136: San Juan de Bigote | E136: M3B7 | F136: 1 | G136: Rural | H136: 23 | I136: 12 | J136: 11 | K136: 2 | L136: 16 | M136: 639929.96 | N136: 9416155.7 | O136: OK
A137: 2004080014 | B137: La Laja | C137: Morropón | D137: Santa Catalina de Mossa | E137: 14 | F137: 1 | G137: Rural | H137: 22 | I137: 11 | J137: 11 | K137: 8 | L137: 12 | M137: 624674.36 | N137: 9437695.8 | O137: OK
A138: 2004080031 | B138: Linderos de Maray | C138: Morropón | D138: Santa Catalina de Mossa | E138: 58 | F138: 1 | G138: Urbano | H138: 0 | I138: 0 | J138: 0 | K138: 0 | L138: 0 | M138: 621488.19 | N138: 9427193.8 | O138: OK
A139: 2004080035 | B139: Maray | C139: Morropón | D139: Santa Catalina de Mossa | E139: 58, M32B3 | F139: 2 | G139: Rural | H139: 329 | I139: 165 | J139: 164 | K139: 55 | L139: 138 | M139: 618786.21 | N139: 9426010.8 | O139: OK
A140: 2004080015 | B140: Overazal | C140: Morropón | D140: Santa Catalina de Mossa | E140: 14 | F140: 1 | G140: Rural | H140: 16 | I140: 7 | J140: 9 | K140: 4 | L140: 8 | M140: 624064.49 | N140: 9437299.4 | O140: OK
A141: 2004080019 | B141: Santa Rosa de Chirimoyos | C141: Morropón | D141: Santa Catalina de Mossa | E141: 42, M36B2 | F141: 2 | G141: Rural | H141: 131 | I141: 63 | J141: 68 | K141: 29 | L141: 53 | M141: 625716.5 | N141: 9434887.2 | O141: OK
A142: 2004090047 | B142: Botijas | C142: Morropón | D142: Santo Domingo | E142: M8B2 | F142: 1 | G142: Rural | H142: 192 | I142: 100 | J142: 92 | K142: 54 | L142: 71 | M142: 615378.57 | N142: 9435504.5 | O142: OK
A143: 2004090015 | B143: Chacayo | C143: Morropón | D143: Santo Domingo | E143: 12 | F143: 1 | G143: Rural | H143: 105 | I143: 55 | J143: 50 | K143: 43 | L143: 85 | M143: 625612.13 | N143: 9443771.5 | O143: OK
...

Sheet A3_Poblacion_Distrito
A1: AUTORIDAD NACIONAL DE INFRAESTRUCTURA - ANIN
A2: DIRECCIÓN DE INTERVENCIONES MULTISECTORIALES Y DE EMERGENCIA - DIME
A3: SUBDIRECCIÓN DE ESTUDIOS DE INVERSIÓN - SESDI
A4: A3. POBLACIÓN DE LOS CENTROS POBLADOS ASOCIADOS A LOS BLOQUES V6, POR DISTRITO
A5: PROYECTO IN PIURA | CUI 2669244 | Cuenca Alta del Río Piura | UTM WGS 84 Zona 17S (EPSG:32717)
A6: Fuente: INEI, capa de centros poblados con población censal; asociación centro poblado–bloque del equipo social (CentrosPoblados-INEI-Bloques_v5, 24.09.2026, y bloques adicionales 83-87)
A8: Provincia | B8: Distrito | C8: N.° CCPP | D8: Población total | E8: Hombres | F8: Mujeres | G8: Población vulnerable | H8: Viviendas particulares | I8: % de la población
A9: Ayabaca | B9: Frías | C9: =COUNTIFS('A3_Poblacion_CCPP'!$D$9:$D$160,B9) | D9: =SUMIFS('A3_Poblacion_CCPP'!$H$9:$H$160,'A3_Poblacion_CCPP'!$D$9:$D$160,B9) | E9: =SUMIFS('A3_Poblacion_CCPP'!$I$9:$I$160,'A3_Poblacion_CCPP'!$D$9:$D$160,B9) | F9: =SUMIFS('A3_Poblacion_CCPP'!$J$9:$J$160,'A3_Poblacion_CCPP'!$D$9:$D$160,B9) | G9: =SUMIFS('A3_Poblacion_CCPP'!$K$9:$K$160,'A3_Poblacion_CCPP'!$D$9:$D$160,B9) | H9: =SUMIFS('A3_Poblacion_CCPP'!$L$9:$L$160,'A3_Poblacion_CCPP'!$D$9:$D$160,B9) | I9: =D9/$D$24
A10: Huancabamba | B10: Canchaque | C10: =COUNTIFS('A3_Poblacion_CCPP'!$D$9:$D$160,B10) | D10: =SUMIFS('A3_Poblacion_CCPP'!$H$9:$H$160,'A3_Poblacion_CCPP'!$D$9:$D$160,B10) | E10: =SUMIFS('A3_Poblacion_CCPP'!$I$9:$I$160,'A3_Poblacion_CCPP'!$D$9:$D$160,B10) | F10: =SUMIFS('A3_Poblacion_CCPP'!$J$9:$J$160,'A3_Poblacion_CCPP'!$D$9:$D$160,B10) | G10: =SUMIFS('A3_Poblacion_CCPP'!$K$9:$K$160,'A3_Poblacion_CCPP'!$D$9:$D$160,B10) | H10: =SUMIFS('A3_Poblacion_CCPP'!$L$9:$L$160,'A3_Poblacion_CCPP'!$D$9:$D$160,B10) | I10: =D10/$D$24
A11: Huancabamba | B11: Huancabamba | C11: =COUNTIFS('A3_Poblacion_CCPP'!$D$9:$D$160,B11) | D11: =SUMIFS('A3_Poblacion_CCPP'!$H$9:$H$160,'A3_Poblacion_CCPP'!$D$9:$D$160,B11) | E11: =SUMIFS('A3_Poblacion_CCPP'!$I$9:$I$160,'A3_Poblacion_CCPP'!$D$9:$D$160,B11) | F11: =SUMIFS('A3_Poblacion_CCPP'!$J$9:$J$160,'A3_Poblacion_CCPP'!$D$9:$D$160,B11) | G11: =SUMIFS('A3_Poblacion_CCPP'!$K$9:$K$160,'A3_Poblacion_CCPP'!$D$9:$D$160,B11) | H11: =SUMIFS('A3_Poblacion_CCPP'!$L$9:$L$160,'A3_Poblacion_CCPP'!$D$9:$D$160,B11) | I11: =D11/$D$24
A12: Huancabamba | B12: Huarmaca | C12: =COUNTIFS('A3_Poblacion_CCPP'!$D$9:$D$160,B12) | D12: =SUMIFS('A3_Poblacion_CCPP'!$H$9:$H$160,'A3_Poblacion_CCPP'!$D$9:$D$160,B12) | E12: =SUMIFS('A3_Poblacion_CCPP'!$I$9:$I$160,'A3_Poblacion_CCPP'!$D$9:$D$160,B12) | F12: =SUMIFS('A3_Poblacion_CCPP'!$J$9:$J$160,'A3_Poblacion_CCPP'!$D$9:$D$160,B12) | G12: =SUMIFS('A3_Poblacion_CCPP'!$K$9:$K$160,'A3_Poblacion_CCPP'!$D$9:$D$160,B12) | H12: =SUMIFS('A3_Poblacion_CCPP'!$L$9:$L$160,'A3_Poblacion_CCPP'!$D$9:$D$160,B12) | I12: =D12/$D$24
A13: Huancabamba | B13: Lalaquiz | C13: =COUNTIFS('A3_Poblacion_CCPP'!$D$9:$D$160,B13) | D13: =SUMIFS('A3_Poblacion_CCPP'!$H$9:$H$160,'A3_Poblacion_CCPP'!$D$9:$D$160,B13) | E13: =SUMIFS('A3_Poblacion_CCPP'!$I$9:$I$160,'A3_Poblacion_CCPP'!$D$9:$D$160,B13) | F13: =SUMIFS('A3_Poblacion_CCPP'!$J$9:$J$160,'A3_Poblacion_CCPP'!$D$9:$D$160,B13) | G13: =SUMIFS('A3_Poblacion_CCPP'!$K$9:$K$160,'A3_Poblacion_CCPP'!$D$9:$D$160,B13) | H13: =SUMIFS('A3_Poblacion_CCPP'!$L$9:$L$160,'A3_Poblacion_CCPP'!$D$9:$D$160,B13) | I13: =D13/$D$24
A14: Huancabamba | B14: San Miguel de El Faique | C14: =COUNTIFS('A3_Poblacion_CCPP'!$D$9:$D$160,B14) | D14: =SUMIFS('A3_Poblacion_CCPP'!$H$9:$H$160,'A3_Poblacion_CCPP'!$D$9:$D$160,B14) | E14: =SUMIFS('A3_Poblacion_CCPP'!$I$9:$I$160,'A3_Poblacion_CCPP'!$D$9:$D$160,B14) | F14: =SUMIFS('A3_Poblacion_CCPP'!$J$9:$J$160,'A3_Poblacion_CCPP'!$D$9:$D$160,B14) | G14: =SUMIFS('A3_Poblacion_CCPP'!$K$9:$K$160,'A3_Poblacion_CCPP'!$D$9:$D$160,B14) | H14: =SUMIFS('A3_Poblacion_CCPP'!$L$9:$L$160,'A3_Poblacion_CCPP'!$D$9:$D$160,B14) | I14: =D14/$D$24
A15: Morropón | B15: Buenos Aires | C15: =COUNTIFS('A3_Poblacion_CCPP'!$D$9:$D$160,B15) | D15: =SUMIFS('A3_Poblacion_CCPP'!$H$9:$H$160,'A3_Poblacion_CCPP'!$D$9:$D$160,B15) | E15: =SUMIFS('A3_Poblacion_CCPP'!$I$9:$I$160,'A3_Poblacion_CCPP'!$D$9:$D$160,B15) | F15: =SUMIFS('A3_Poblacion_CCPP'!$J$9:$J$160,'A3_Poblacion_CCPP'!$D$9:$D$160,B15) | G15: =SUMIFS('A3_Poblacion_CCPP'!$K$9:$K$160,'A3_Poblacion_CCPP'!$D$9:$D$160,B15) | H15: =SUMIFS('A3_Poblacion_CCPP'!$L$9:$L$160,'A3_Poblacion_CCPP'!$D$9:$D$160,B15) | I15: =D15/$D$24
A16: Morropón | B16: Chalaco | C16: =COUNTIFS('A3_Poblacion_CCPP'!$D$9:$D$160,B16) | D16: =SUMIFS('A3_Poblacion_CCPP'!$H$9:$H$160,'A3_Poblacion_CCPP'!$D$9:$D$160,B16) | E16: =SUMIFS('A3_Poblacion_CCPP'!$I$9:$I$160,'A3_Poblacion_CCPP'!$D$9:$D$160,B16) | F16: =SUMIFS('A3_Poblacion_CCPP'!$J$9:$J$160,'A3_Poblacion_CCPP'!$D$9:$D$160,B16) | G16: =SUMIFS('A3_Poblacion_CCPP'!$K$9:$K$160,'A3_Poblacion_CCPP'!$D$9:$D$160,B16) | H16: =SUMIFS('A3_Poblacion_CCPP'!$L$9:$L$160,'A3_Poblacion_CCPP'!$D$9:$D$160,B16) | I16: =D16/$D$24
A17: Morropón | B17: Chulucanas | C17: =COUNTIFS('A3_Poblacion_CCPP'!$D$9:$D$160,B17) | D17: =SUMIFS('A3_Poblacion_CCPP'!$H$9:$H$160,'A3_Poblacion_CCPP'!$D$9:$D$160,B17) | E17: =SUMIFS('A3_Poblacion_CCPP'!$I$9:$I$160,'A3_Poblacion_CCPP'!$D$9:$D$160,B17) | F17: =SUMIFS('A3_Poblacion_CCPP'!$J$9:$J$160,'A3_Poblacion_CCPP'!$D$9:$D$160,B17) | G17: =SUMIFS('A3_Poblacion_CCPP'!$K$9:$K$160,'A3_Poblacion_CCPP'!$D$9:$D$160,B17) | H17: =SUMIFS('A3_Poblacion_CCPP'!$L$9:$L$160,'A3_Poblacion_CCPP'!$D$9:$D$160,B17) | I17: =D17/$D$24
A18: Morropón | B18: Morropón | C18: =COUNTIFS('A3_Poblacion_CCPP'!$D$9:$D$160,B18) | D18: =SUMIFS('A3_Poblacion_CCPP'!$H$9:$H$160,'A3_Poblacion_CCPP'!$D$9:$D$160,B18) | E18: =SUMIFS('A3_Poblacion_CCPP'!$I$9:$I$160,'A3_Poblacion_CCPP'!$D$9:$D$160,B18) | F18: =SUMIFS('A3_Poblacion_CCPP'!$J$9:$J$160,'A3_Poblacion_CCPP'!$D$9:$D$160,B18) | G18: =SUMIFS('A3_Poblacion_CCPP'!$K$9:$K$160,'A3_Poblacion_CCPP'!$D$9:$D$160,B18) | H18: =SUMIFS('A3_Poblacion_CCPP'!$L$9:$L$160,'A3_Poblacion_CCPP'!$D$9:$D$160,B18) | I18: =D18/$D$24
A19: Morropón | B19: Salitral | C19: =COUNTIFS('A3_Poblacion_CCPP'!$D$9:$D$160,B19) | D19: =SUMIFS('A3_Poblacion_CCPP'!$H$9:$H$160,'A3_Poblacion_CCPP'!$D$9:$D$160,B19) | E19: =SUMIFS('A3_Poblacion_CCPP'!$I$9:$I$160,'A3_Poblacion_CCPP'!$D$9:$D$160,B19) | F19: =SUMIFS('A3_Poblacion_CCPP'!$J$9:$J$160,'A3_Poblacion_CCPP'!$D$9:$D$160,B19) | G19: =SUMIFS('A3_Poblacion_CCPP'!$K$9:$K$160,'A3_Poblacion_CCPP'!$D$9:$D$160,B19) | H19: =SUMIFS('A3_Poblacion_CCPP'!$L$9:$L$160,'A3_Poblacion_CCPP'!$D$9:$D$160,B19) | I19: =D19/$D$24
A20: Morropón | B20: San Juan de Bigote | C20: =COUNTIFS('A3_Poblacion_CCPP'!$D$9:$D$160,B20) | D20: =SUMIFS('A3_Poblacion_CCPP'!$H$9:$H$160,'A3_Poblacion_CCPP'!$D$9:$D$160,B20) | E20: =SUMIFS('A3_Poblacion_CCPP'!$I$9:$I$160,'A3_Poblacion_CCPP'!$D$9:$D$160,B20) | F20: =SUMIFS('A3_Poblacion_CCPP'!$J$9:$J$160,'A3_Poblacion_CCPP'!$D$9:$D$160,B20) | G20: =SUMIFS('A3_Poblacion_CCPP'!$K$9:$K$160,'A3_Poblacion_CCPP'!$D$9:$D$160,B20) | H20: =SUMIFS('A3_Poblacion_CCPP'!$L$9:$L$160,'A3_Poblacion_CCPP'!$D$9:$D$160,B20) | I20: =D20/$D$24
... A23: Morropón | B23: Yamango | C23: =COUNTIFS('A3_Poblacion_CCPP'!$D$9:$D$160,B23) | D23: =SUMIFS('A3_Poblacion_CCPP'!$H$9:$H$160,'A3_Poblacion_CCPP'!$D$9:$D$160,B23) | E23: =SUMIFS('A3_Poblacion_CCPP'!$I$9:$I$160,'A3_Poblacion_CCPP'!$D$9:$D$160,B23) | F23: =SUMIFS('A3_Poblacion_CCPP'!$J$9:$J$160,'A3_Poblacion_CCPP'!$D$9:$D$160,B23) | G23: =SUMIFS('A3_Poblacion_CCPP'!$K$9:$K$160,'A3_Poblacion_CCPP'!$D$9:$D$160,B23) | H23: =SUMIFS('A3_Poblacion_CCPP'!$L$9:$L$160,'A3_Poblacion_CCPP'!$D$9:$D$160,B23) | I23: =D23/$D$24
A24: TOTAL | B24: 15 distritos | C24: =SUM(C9:C23) | D24: =SUM(D9:D23) | E24: =SUM(E9:E23) | F24: =SUM(F9:F23) | G24: =SUM(G9:G23) | H24: =SUM(H9:H23) | I24: =SUM(I9:I23)
A26: Resumen por provincia
A27: Provincia | B27: N.° CCPP | C27: Población total | D27: Hombres | E27: Mujeres | F27: Población vulnerable | G27: Viviendas particulares
A28: Ayabaca | B28: =SUMIFS($C$9:$C$23,$A$9:$A$23,A28) | C28: =SUMIFS($D$9:$D$23,$A$9:$A$23,A28) | D28: =SUMIFS($E$9:$E$23,$A$9:$A$23,A28) | E28: =SUMIFS($F$9:$F$23,$A$9:$A$23,A28) | F28: =SUMIFS($G$9:$G$23,$A$9:$A$23,A28) | G28: =SUMIFS($H$9:$H$23,$A$9:$A$23,A28)
A29: Huancabamba | B29: =SUMIFS($C$9:$C$23,$A$9:$A$23,A29) | C29: =SUMIFS($D$9:$D$23,$A$9:$A$23,A29) | D29: =SUMIFS($E$9:$E$23,$A$9:$A$23,A29) | E29: =SUMIFS($F$9:$F$23,$A$9:$A$23,A29) | F29: =SUMIFS($G$9:$G$23,$A$9:$A$23,A29) | G29: =SUMIFS($H$9:$H$23,$A$9:$A$23,A29)
A30: Morropón | B30: =SUMIFS($C$9:$C$23,$A$9:$A$23,A30) | C30: =SUMIFS($D$9:$D$23,$A$9:$A$23,A30) | D30: =SUMIFS($E$9:$E$23,$A$9:$A$23,A30) | E30: =SUMIFS($F$9:$F$23,$A$9:$A$23,A30) | F30: =SUMIFS($G$9:$G$23,$A$9:$A$23,A30) | G30: =SUMIFS($H$9:$H$23,$A$9:$A$23,A30)
A31: TOTAL | B31: =SUM(B28:B30) | C31: =SUM(C28:C30) | D31: =SUM(D28:D30) | E31: =SUM(E28:E30) | F31: =SUM(F28:F30) | G31: =SUM(G28:G30)
A33: Controles
A34: Población por distrito = A3_Poblacion_CCPP | C34: =IF(D24=SUM('A3_Poblacion_CCPP'!$H$9:$H$160),"OK","REVISAR")
A35: Resumen provincial = distrital | C35: =IF(C31=D24,"OK","REVISAR")
A37: El distrito es el del centro poblado (INEI), que puede diferir del distrito del bloque al que está asociado. Hombres, mujeres, población vulnerable y viviendas no incluyen los centros poblados de los bloques 83 a 87, cuya fuente solo trae la población total.

Sheet A3_Avance_Social
A1: AUTORIDAD NACIONAL DE INFRAESTRUCTURA - ANIN
A2: DIRECCIÓN DE INTERVENCIONES MULTISECTORIALES Y DE EMERGENCIA - DIME
A3: SUBDIRECCIÓN DE ESTUDIOS DE INVERSIÓN - SESDI
A4: A3/A5. DISEÑO MUESTRAL Y AVANCE DEL DIAGNÓSTICO SOCIAL (F-DS) POR CENTRO POBLADO Y BLOQUE
A5: PROYECTO IN PIURA | CUI 2669244 | Cuenca Alta del Río Piura | UTM WGS 84 Zona 17S (EPSG:32717)
A6: Fuente: Hoja de control «Muestra pob inei+sigrid» del equipo social (CentrosPoblados-INEI-Bloques_v5, 24.09.2026); solo bloques V6
A8: Diseño muestral (población finita; muestreo estratificado por centro poblado con asignación proporcional a las viviendas)
A9: N — viviendas particulares del marco muestral | C9: 8865.9
A10: Z — nivel de confianza 95 % | C10: 1.96
A11: e — margen de error | C11: 0.05
A12: p — proporción esperada | C12: 0.5
A13: q — 1 − p | C13: =1-C12
A14: n — tamaño de muestra = N·Z²·p·q / (e²·(N−1) + Z²·p·q) | C14: =ROUND(C9*C10^2*C12*C13/(C11^2*(C9-1)+C10^2*C12*C13),0)
A16: Avance de campo (bloques V6)
A17: Registros centro poblado–bloque (V6) | C17: =COUNTA($C$25:$C$195)
A18: Tamaño de muestra calculado (n) | C18: =C14
A19: Fichas F-DS-01 (socioeconómica) reportadas | C19: =SUM($G$25:$G$195)
A20: Registros con F-DS-01 COMPLETO | C20: =COUNTIF($H$25:$H$195,"COMPLETO")
A21: Registros con F-DS-03 (entrevista a autoridades) COMPLETO | C21: =COUNTIF($J$25:$J$195,"COMPLETO")
A22: Registros con ficha de saberes ancestrales COMPLETO | C22: =COUNTIF($L$25:$L$195,"COMPLETO")
A24: Provincia | B24: Distrito | C24: Centro poblado | D24: Bloque | E24: Viviendas (N_h) | F24: Muestra asignada + ajuste | G24: F-DS-01 reportadas | H24: Estado F-DS-01 | I24: F-DS-03 reportadas | J24: Estado F-DS-03 | K24: Saberes ancestrales reportados | L24: Estado saberes | M24: Fecha de evaluación | N24: Observaciones de campo
A25: Ayabaca | B25: Frías | C25: Banda De La Cruz | D25: 56 | E25: 19 | F25: 1 | G25: 1 | H25: COMPLETO | I25: 1 | J25: COMPLETO | K25: 0 | L25: PENDIENTE | M25: 46196
A26: Ayabaca | B26: Frías | C26: El Guabo | D26: M17B6 | E26: 20 | F26: 1 | G26: 1 | H26: COMPLETO | I26: 1 | J26: COMPLETO | K26: 0 | L26: PENDIENTE | M26: 46217
A27: Ayabaca | B27: Frías | C27: El Mirador | D27: 3 | E27: 6 | F27: 1 | H27: - | J27: - | L27: - | M27: - | N27: La ficha se aplicó en el caserío el Huayabal ya que es la misma autoridad que en el Mirador
A28: Ayabaca | B28: Frías | C28: Guabal | D28: 36 | E28: 88 | F28: 4 | G28: 4 | H28: COMPLETO | I28: 1 | J28: COMPLETO | K28: 0 | L28: PENDIENTE | M28: 46197
A29: Ayabaca | B29: Frías | C29: Guabal | D29: 6 | E29: 88 | F29: 4 | G29: 4 | H29: COMPLETO | I29: 1 | J29: COMPLETO | K29: 0 | L29: PENDIENTE | M29: 46197
A30: Ayabaca | B30: Frías | C30: Guanabano Alto | D30: 6 | E30: 75 | F30: 3 | G30: 4 | H30: COMPLETO | I30: 1 | J30: COMPLETO | K30: 0 | L30: PENDIENTE | M30: 46197
A31: Ayabaca | B31: Frías | C31: Huasipe De Geraldo | D31: 3 | E31: 35 | F31: 1 | G31: 2 | H31: COMPLETO | I31: 2 | J31: COMPLETO | K31: 0 | L31: PENDIENTE | M31: 46198
A32: Ayabaca | B32: Frías | C32: Huayabal | D32: 3 | E32: 20 | F32: 1 | G32: 1 | H32: COMPLETO | I32: 1 | J32: COMPLETO | K32: 0 | L32: PENDIENTE | M32: 46199
A33: Ayabaca | B33: Frías | C33: La Cria | D33: 39 | E33: 85 | F33: 4 | G33: 4 | H33: COMPLETO | I33: 1 | J33: COMPLETO | K33: 0 | L33: PENDIENTE | M33: 46269
A34: Ayabaca | B34: Frías | C34: Linderos De Misquis | D34: 27 | E34: 14 | F34: 1 | G34: 2 | H34: COMPLETO | I34: 1 | J34: COMPLETO | K34: 0 | L34: PENDIENTE | M34: 46218
A35: Ayabaca | B35: Frías | C35: Los Checches | D35: 3 | E35: 53 | F35: 2 | G35: 2 | H35: COMPLETO | I35: 1 | J35: COMPLETO | K35: 0 | L35: PENDIENTE | M35: 46199
A36: Ayabaca | B36: Frías | C36: Nogal | D36: 6 | E36: 3 | F36: 1 | H36: SIN REGISTRO | J36: SIN REGISTRO | L36: SIN REGISTRO
A37: Ayabaca | B37: Frías | C37: Nueva Esperanza De Misquis | D37: 27 | E37: 25 | F37: 1 | G37: 1 | H37: COMPLETO | I37: 1 | J37: COMPLETO | K37: 0 | L37: PENDIENTE | M37: 46218
A38: Ayabaca | B38: Frías | C38: Pampa De Ramada | D38: M17B7 | E38: 32 | F38: 1 | G38: 2 | H38: COMPLETO | I38: 2 | J38: COMPLETO | K38: 0 | L38: PENDIENTE | M38: 46197
A39: Ayabaca | B39: Frías | C39: Platanal Alto | D39: M17B6 | E39: 65 | F39: 3 | G39: 3 | H39: COMPLETO | I39: 1 | J39: COMPLETO | K39: 0 | L39: PENDIENTE | M39: 46217
A40: Ayabaca | B40: Frías | C40: Putagas | D40: 56 | E40: 55 | F40: 2 | G40: 2 | H40: COMPLETO | I40: 1 | J40: COMPLETO | K40: 0 | L40: PENDIENTE | M40: 46196
A41: Ayabaca | B41: Frías | C41: Rincon De Geraldo | D41: 3 | E41: 29 | F41: 1 | G41: 2 | H41: COMPLETO | I41: 2 | J41: COMPLETO | K41: 0 | L41: PENDIENTE | M41: 46198
A42: Ayabaca | B42: Frías | C42: (En Blanco) | D42: M17B10 | E42: 0 | F42: 0 | G42: 0 | H42: COMPLETO | I42: 0 | J42: PENDIENTE | K42: 0 | L42: PENDIENTE
A43: Ayabaca | B43: Frías | C43: (En Blanco) | D43: M17B5 | E43: 0 | F43: 0 | G43: 0 | H43: COMPLETO | I43: 0 | J43: PENDIENTE | K43: 0 | L43: PENDIENTE
...

Sheet A4_UP_Ecosistemas
A1: AUTORIDAD NACIONAL DE INFRAESTRUCTURA - ANIN
A2: DIRECCIÓN DE INTERVENCIONES MULTISECTORIALES Y DE EMERGENCIA - DIME
A3: SUBDIRECCIÓN DE ESTUDIOS DE INVERSIÓN - SESDI
A4: A4. UNIDAD PRODUCTORA — ECOSISTEMAS EN LOS 117 BLOQUES V6
A5: PROYECTO IN PIURA | CUI 2669244 | Cuenca Alta del Río Piura | UTM WGS 84 Zona 17S (EPSG:32717)
A6: Fuente: Mapa Nacional de Ecosistemas del Perú, MINAM 2018 (R.M. N.° 440-2018-MINAM), recorte al ámbito. Bloques V6 (Bloques V6.kml) y catálogo V6 (datos/unidades_liberacion_areas.csv), ANIN-DIME-SESDI 2026
A8: Ecosistema | B8: Símbolo | C8: Área en el ámbito (ha) | D8: N.° de bloques | E8: Área en bloques (ha) | F8: % de los bloques | G8: % del ecosistema en el ámbito intervenido
A9: Bosque estacionalmente seco de colina y montaña | B9: Bes-cm | C9: 188280.25 | D9: =COUNTIFS('A4_UP_Eco_Bloque'!$E$9:$E$198,A9) | E9: =SUMIFS('A4_UP_Eco_Bloque'!$H$9:$H$198,'A4_UP_Eco_Bloque'!$E$9:$E$198,A9) | F9: =E9/$E$15 | G9: =IF(C9>0,E9/C9,"—")
A10: Zona agrícola | B10: Agri | C10: 155867.89 | D10: =COUNTIFS('A4_UP_Eco_Bloque'!$E$9:$E$198,A10) | E10: =SUMIFS('A4_UP_Eco_Bloque'!$H$9:$H$198,'A4_UP_Eco_Bloque'!$E$9:$E$198,A10) | F10: =E10/$E$15 | G10: =IF(C10>0,E10/C10,"—")
A11: Matorral andino | B11: Ma | C11: 31192.831 | D11: =COUNTIFS('A4_UP_Eco_Bloque'!$E$9:$E$198,A11) | E11: =SUMIFS('A4_UP_Eco_Bloque'!$H$9:$H$198,'A4_UP_Eco_Bloque'!$E$9:$E$198,A11) | F11: =E11/$E$15 | G11: =IF(C11>0,E11/C11,"—")
A12: Bosque relicto montano de vertiente occidental | B12: Br-mvoc | C12: 6281.805 | D12: =COUNTIFS('A4_UP_Eco_Bloque'!$E$9:$E$198,A12) | E12: =SUMIFS('A4_UP_Eco_Bloque'!$H$9:$H$198,'A4_UP_Eco_Bloque'!$E$9:$E$198,A12) | F12: =E12/$E$15 | G12: =IF(C12>0,E12/C12,"—")
A13: Páramo | B13: Pa | C13: 3843.332 | D13: =COUNTIFS('A4_UP_Eco_Bloque'!$E$9:$E$198,A13) | E13: =SUMIFS('A4_UP_Eco_Bloque'!$H$9:$H$198,'A4_UP_Eco_Bloque'!$E$9:$E$198,A13) | F13: =E13/$E$15 | G13: =IF(C13>0,E13/C13,"—")
A14: Sin información de ecosistema | D14: =COUNTIFS('A4_UP_Eco_Bloque'!$E$9:$E$198,A14) | E14: =SUMIFS('A4_UP_Eco_Bloque'!$H$9:$H$198,'A4_UP_Eco_Bloque'!$E$9:$E$198,A14) | F14: =E14/$E$15 | G14: =IF(C14>0,E14/C14,"—")
A15: TOTAL | C15: =SUM(C9:C14) | E15: =SUM(E9:E14) | F15: =SUM(F9:F14)
A17: Control: área en bloques = 12,270.235 ha | D17: =IF(ABS(E15-12270.235)<0.01,"OK","REVISAR")
A19: «Área en el ámbito» suma solo los ecosistemas presentes en los bloques; la capa recortada al ámbito cubre 388,809.780 ha e incluye además: Bosque estacionalmente seco de llanura, Bosque estacionalmente seco ribereño (Algarrobal), Río, Zona urbana.
A21: La Unidad Productora es el ecosistema en su totalidad; los bloques de intervención se ubican dentro de él. El Mapa Nacional de Ecosistemas es de escala regional: el ecosistema de cada bloque se confirma en campo con la ficha F-DT-03. «Zona agrícola» identifica superficie con uso agropecuario dentro de los bloques, a revisar en el tamizaje predial y en la verificación de campo.

Sheet A4_UP_Eco_Bloque
A1: AUTORIDAD NACIONAL DE INFRAESTRUCTURA - ANIN
A2: DIRECCIÓN DE INTERVENCIONES MULTISECTORIALES Y DE EMERGENCIA - DIME
A3: SUBDIRECCIÓN DE ESTUDIOS DE INVERSIÓN - SESDI
A4: A4. ECOSISTEMAS POR BLOQUE V6 (DETALLE)
A5: PROYECTO IN PIURA | CUI 2669244 | Cuenca Alta del Río Piura | UTM WGS 84 Zona 17S (EPSG:32717)
A6: Fuente: Mapa Nacional de Ecosistemas del Perú, MINAM 2018 (R.M. N.° 440-2018-MINAM), recorte al ámbito; áreas prorrateadas al área oficial del catálogo V6
A8: Bloque | B8: Microcuenca | C8: Provincia | D8: Distrito | E8: Ecosistema | F8: Símbolo | G8: Área del bloque (ha) | H8: Área del ecosistema en el bloque (ha) | I8: % del bloque
A9: 27 | B9: C1096-Q9556 | C9: Ayabaca | D9: Frías | E9: Zona agrícola | F9: Agri | G9: 78.154 | H9: 78.154 | I9: =H9/G9
A10: 3 | B10: C1096-Q9545 | C10: Ayabaca | D10: Frías | E10: Zona agrícola | F10: Agri | G10: 459.295 | H10: 434.19758 | I10: =H10/G10
A11: 3 | B11: C1096-Q9545 | C11: Ayabaca | D11: Frías | E11: Bosque estacionalmente seco de colina y montaña | F11: Bes-cm | G11: 459.295 | H11: 25.097422 | I11: =H11/G11
A12: 36 | B12: C1096-Q9547 | C12: Ayabaca | D12: Frías | E12: Zona agrícola | F12: Agri | G12: 24.843 | H12: 24.843 | I12: =H12/G12
A13: 39 | B13: C1096-Q9564 | C13: Ayabaca | D13: Frías | E13: Matorral andino | F13: Ma | G13: 68.569 | H13: 68.569 | I13: =H13/G13
A14: 56 | B14: C1096-Q9564 | C14: Ayabaca | D14: Frías | E14: Bosque relicto montano de vertiente occidental | F14: Br-mvoc | G14: 77.666 | H14: 41.848916 | I14: =H14/G14
A15: 56 | B15: C1096-Q9564 | C15: Ayabaca | D15: Frías | E15: Zona agrícola | F15: Agri | G15: 77.666 | H15: 35.817084 | I15: =H15/G15
A16: 6 | B16: C1096-Q9547 | C16: Ayabaca | D16: Frías | E16: Zona agrícola | F16: Agri | G16: 168.411 | H16: 164.23629 | I16: =H16/G16
A17: 6 | B17: C1096-Q9547 | C17: Ayabaca | D17: Frías | E17: Bosque estacionalmente seco de colina y montaña | F17: Bes-cm | G17: 168.411 | H17: 4.1747099 | I17: =H17/G17
A18: M17B10 | B18: C1096-Q9556 | C18: Ayabaca | D18: Frías | E18: Zona agrícola | F18: Agri | G18: 75.363 | H18: 43.31737 | I18: =H18/G18
A19: M17B10 | B19: C1096-Q9556 | C19: Ayabaca | D19: Frías | E19: Bosque estacionalmente seco de colina y montaña | F19: Bes-cm | G19: 75.363 | H19: 32.04563 | I19: =H19/G19
A20: M17B5 | B20: C1096-Q9556 | C20: Ayabaca | D20: Frías | E20: Bosque estacionalmente seco de colina y montaña | F20: Bes-cm | G20: 74.028 | H20: 52.458871 | I20: =H20/G20
... A111: M6B2-3 | B111: C1077-Q9566 | C111: Morropón | D111: Buenos Aires | E111: Bosque estacionalmente seco de colina y montaña | F111: Bes-cm | G111: 160.978 | H111: 160.6706 | I111: =H111/G111
A112: M6B2-3 | B112: C1077-Q9566 | C112: Morropón | D112: Buenos Aires | E112: Sin información de ecosistema | G112: 160.978 | H112: 0.30739924 | I112: =H112/G112
A113: 57 | B113: C1086-Q9576 | C113: Morropón | D113: Chalaco | E113: Matorral andino | F113: Ma | G113: 25.668 | H113: 21.261083 | I113: =H113/G113
A114: 57 | B114: C1086-Q9576 | C114: Morropón | D114: Chalaco | E114: Zona agrícola | F114: Agri | G114: 25.668 | H114: 4.4069172 | I114: =H114/G114
A115: 59 | B115: C1086-Q9570 | C115: Morropón | D115: Chalaco | E115: Bosque relicto montano de vertiente occidental | F115: Br-mvoc | G115: 13.554 | H115: 8.1272 | I115: =H115/G115
A116: 59 | B116: C1086-Q9570 | C116: Morropón | D116: Chalaco | E116: Zona agrícola | F116: Agri | G116: 13.554 | H116: 5.4268 | I116: =H116/G116
A117: 2 | B117: C1096-Q9558 | C117: Morropón | D117: Chulucanas | E117: Bosque estacionalmente seco de colina y montaña | F117: Bes-cm | G117: 330.599 | H117: 330.599 | I117: =H117/G117
A118: 22 | B118: C1096-Q9556 | C118: Morropón | D118: Chulucanas | E118: Bosque estacionalmente seco de colina y montaña | F118: Bes-cm | G118: 79.33 | H118: 79.33 | I118: =H118/G118
A119: M10B4 | B119: C1096-Q9547 | C119: Morropón | D119: Chulucanas | E119: Bosque estacionalmente seco de colina y montaña | F119: Bes-cm | G119: 68.887 | H119: 68.458297 | I119: =H119/G119
A120: M10B4 | B120: C1096-Q9547 | C120: Morropón | D120: Chulucanas | E120: Sin información de ecosistema | G120: 68.887 | H120: 0.42870311 | I120: =H120/G120
A121: M17B1 | B121: C1096-Q9556 | C121: Morropón | D121: Chulucanas | E121: Bosque estacionalmente seco de colina y montaña | F121: Bes-cm | G121: 42.449 | H121: 42.449 | I121: =H121/G121
A122: M17B4 | B122: C1096-Q9556 | C122: Morropón | D122: Chulucanas | E122: Bosque estacionalmente seco de colina y montaña | F122: Bes-cm | G122: 124.709 | H122: 124.709 | I122: =H122/G122
A123: M27B1 | B123: C1096-Q9557 | C123: Morropón | D123: Chulucanas | E123: Bosque estacionalmente seco de colina y montaña | F123: Bes-cm | G123: 448.804 | H123: 443.8304 | I123: =H123/G123
A124: M27B1 | B124: C1096-Q9557 | C124: Morropón | D124: Chulucanas | E124: Zona agrícola | F124: Agri | G124: 448.804 | H124: 4.9736033 | I124: =H124/G124
A125: M9B1 | B125: C1096-Q9545 | C125: Morropón | D125: Chulucanas | E125: Bosque estacionalmente seco de colina y montaña | F125: Bes-cm | G125: 355.364 | H125: 355.364 | I125: =H125/G125
A126: M19B2 | B126: C1086-Q9570 | C126: Morropón | D126: Morropón | E126: Bosque estacionalmente seco de colina y montaña | F126: Bes-cm | G126: 74.372 | H126: 74.372 | I126: =H126/G126
A127: M32B3 | B127: C1086-Q9569 | C127: Morropón | D127: Morropón | E127: Bosque estacionalmente seco de colina y montaña | F127: Bes-cm | G127: 50.972 | H127: 50.972 | I127: =H127/G127
A128: M18B3 | B128: C1077-Q9579 | C128: Morropón | D128: Salitral | E128: Bosque estacionalmente seco de colina y montaña | F128: Bes-cm | G128: 373.807 | H128: 373.6991 | I128: =H128/G128
A129: M18B3 | B129: C1077-Q9579 | C129: Morropón | D129: Salitral | E129: Zona agrícola | F129: Agri | G129: 373.807 | H129: 0.1079 | I129: =H129/G129
A130: M2B1 | B130: C1076-Q9584 | C130: Morropón | D130: Salitral | E130: Bosque estacionalmente seco de colina y montaña | F130: Bes-cm | G130: 81.795 | H130: 81.795 | I130: =H130/G130
A131: M2B5 | B131: C1076-Q9584 | C131: Morropón | D131: Salitral | E131: Bosque estacionalmente seco de colina y montaña | F131: Bes-cm | G131: 30.909 | H131: 30.370593 | I131: =H131/G131
...

Sheet A4_UP_MSAVI
A1: AUTORIDAD NACIONAL DE INFRAESTRUCTURA - ANIN
A2: DIRECCIÓN DE INTERVENCIONES MULTISECTORIALES Y DE EMERGENCIA - DIME
A3: SUBDIRECCIÓN DE ESTUDIOS DE INVERSIÓN - SESDI
A4: A4. COBERTURA VEGETAL — MSAVI 2024 POR CLASE (DN) Y BLOQUE V6
A5: PROYECTO IN PIURA | CUI 2669244 | Cuenca Alta del Río Piura | UTM WGS 84 Zona 17S (EPSG:32717)
A6: Fuente: AREAS_MSAVI_BLOQUES_V6_REV_HSCM.xlsx (exportación SIG) y traspaso MSAVI V6 (datos/traspaso_msavi_117.json)
A8: Bloque | B8: Provincia | C8: Distrito | D8: DN 1 ≤ 0.2650 (ha) | E8: DN 2 0.2650-0.3813 (ha) | F8: DN 3 0.3813-0.4976 (ha) | G8: DN 4 0.4976-0.6139 (ha) | H8: DN 5 > 0.6139 (ha) | I8: Total MSAVI (ha) | J8: MSAVI media | K8: DN dominante | L8: Sup. MSAVI ≤ 0.4976 (ha) | M8: % bajo umbral
A9: 27 | B9: Ayabaca | C9: Frías | D9: 0 | E9: 0.8039 | F9: 28.5017 | G9: 36.4791 | H9: 12.3693 | I9: =SUM(D9:H9) | J9: 0.53228 | K9: 4 | L9: =SUM(D9:F9) | M9: =L9/I9
A10: 3 | B10: Ayabaca | C10: Frías | D10: 0.0022 | E10: 5.6207 | F10: 127.8584 | G10: 174.9372 | H10: 150.8762 | I10: =SUM(D10:H10) | J10: 0.567707 | K10: 4 | L10: =SUM(D10:F10) | M10: =L10/I10
A11: 36 | B11: Ayabaca | C11: Frías | D11: 0 | E11: 0.3467 | F11: 8.5054 | G11: 11.2948 | H11: 4.6963 | I11: =SUM(D11:H11) | J11: 0.539458 | K11: 4 | L11: =SUM(D11:F11) | M11: =L11/I11
A12: 39 | B12: Ayabaca | C12: Frías | D12: 0 | E12: 0 | F12: 2.6356 | G12: 9.5146 | H12: 56.4189 | I12: =SUM(D12:H12) | J12: 0.701601 | K12: 5 | L12: =SUM(D12:F12) | M12: =L12/I12
A13: 56 | B13: Ayabaca | C13: Frías | D13: 0 | E13: 0.0198 | F13: 2.1511 | G13: 14.1789 | H13: 61.3158 | I13: =SUM(D13:H13) | J13: 0.677658 | K13: 5 | L13: =SUM(D13:F13) | M13: =L13/I13
A14: 6 | B14: Ayabaca | C14: Frías | D14: 0.0644 | E14: 4.2168 | F14: 55.3534 | G14: 77.1185 | H14: 31.6575 | I14: =SUM(D14:H14) | J14: 0.538144 | K14: 4 | L14: =SUM(D14:F14) | M14: =L14/I14
A15: M17B10 | B15: Ayabaca | C15: Frías | D15: 0 | E15: 2.3459 | F15: 52.9188 | G15: 15.5782 | H15: 4.5205 | I15: =SUM(D15:H15) | J15: 0.472466 | K15: 3 | L15: =SUM(D15:F15) | M15: =L15/I15
A16: M17B5 | B16: Ayabaca | C16: Frías | D16: 0 | E16: 0.4355 | F16: 20.9904 | G16: 36.7832 | H16: 15.8188 | I16: =SUM(D16:H16) | J16: 0.54817 | K16: 4 | L16: =SUM(D16:F16) | M16: =L16/I16
A17: M17B6 | B17: Ayabaca | C17: Frías | D17: 0.0179 | E17: 13.3443 | F17: 73.8064 | G17: 17.6783 | H17: 1.6916 | I17: =SUM(D17:H17) | J17: 0.446441 | K17: 3 | L17: =SUM(D17:F17) | M17: =L17/I17
A18: M17B7 | B18: Ayabaca | C18: Frías | D18: 0.0042 | E18: 15.0575 | F18: 110.2042 | G18: 97.9917 | H18: 35.5796 | I18: =SUM(D18:H18) | J18: 0.508715 | K18: 3 | L18: =SUM(D18:F18) | M18: =L18/I18
A19: 21 | B19: Huancabamba | C19: Canchaque | D19: 0 | E19: 0.0099 | F19: 4.3472 | G19: 38.6852 | H19: 41.1843 | I19: =SUM(D19:H19) | J19: 0.620078 | K19: 5 | L19: =SUM(D19:F19) | M19: =L19/I19
A20: 24 | B20: Huancabamba | C20: Canchaque | D20: 0 | E20: 0 | F20: 2.0611 | G20: 20.0145 | H20: 68.0839 | I20: =SUM(D20:H20) | J20: 0.674839 | K20: 5 | L20: =SUM(D20:F20) | M20: =L20/I20
... A125: M28B4 | B125: Morropón | C125: Yamango | D125: 0.4355 | E125: 103.9897 | F125: 107.5985 | G125: 69.2422 | H125: 2.1624 | I125: =SUM(D125:H125) | J125: 0.42751 | K125: 3 | L125: =SUM(D125:F125) | M125: =L125/I125
A126: TOTAL | D126: =SUM(D9:D125) | E126: =SUM(E9:E125) | F126: =SUM(F9:F125) | G126: =SUM(G9:G125) | H126: =SUM(H9:H125) | I126: =SUM(I9:I125) | L126: =SUM(L9:L125) | M126: =L126/I126
A128: MSAVI: índice de vegetación ajustado al suelo modificado (Sentinel-2, 2024). Clases DN 1 (menor cobertura) a DN 5 (mayor cobertura) con los cortes indicados; verificación de la equivalencia DN→clase sobre 117 bloques: r = 0.9965, error absoluto medio = 0.0091. «Sup. MSAVI ≤ 0.4976» (clases DN 1 a 3) es un indicador preliminar de baja cobertura vegetal; la condición de degradación se confirma con la ficha F-DT-04 y el procedimiento MINAM de áreas degradadas. El total MSAVI puede diferir ligeramente del área del catálogo por el borde del ráster.

Sheet A4_UP_Carcavas
A1: AUTORIDAD NACIONAL DE INFRAESTRUCTURA - ANIN
A2: DIRECCIÓN DE INTERVENCIONES MULTISECTORIALES Y DE EMERGENCIA - DIME
A3: SUBDIRECCIÓN DE ESTUDIOS DE INVERSIÓN - SESDI
A4: A4. CÁRCAVAS CARACTERIZADAS EN LOS BLOQUES V6
A5: PROYECTO IN PIURA | CUI 2669244 | Cuenca Alta del Río Piura | UTM WGS 84 Zona 17S (EPSG:32717)
A6: Fuente: Caracterización de cárcavas (gabinete SIG: DEM y NDVI), ANIN-DIME-SESDI 2026
A8: Código | B8: Bloque | C8: Microcuenca | D8: Provincia | E8: Distrito | F8: ESTE (m) | G8: NORTE (m) | H8: Longitud (m) | I8: Altitud mín. (msnm) | J8: Altitud máx. (msnm) | K8: Altitud media (msnm) | L8: Pendiente media (%) | M8: Índice de irregularidad | N8: NDVI medio | O8: Clase morfológica | P8: Clase de vegetación (NDVI)
A9: CV 1 - 56 | B9: 56 | C9: C1096-Q9564 | D9: Ayabaca | E9: Frías | F9: 621265.31 | G9: 9452783 | H9: 5.82 | I9: 2342 | J9: 2345 | K9: 2344.46 | L9: 16.89 | M9: 10.03 | N9: 0.69 | O9: Pendiente moderada | P9: Vegetación alta
A10: CV 2 - M2B8 | B10: M2B8 | C10: C1076-Q9584 | D10: Huancabamba | E10: San Miguel de El Faique | F10: 638208.15 | G10: 9398133 | H10: 20.13 | I10: 248 | J10: 249 | K10: 248.5 | L10: 5.17 | M10: 3.08 | N10: 0.34 | O10: Pendiente suave | P10: Vegetación mediana
A11: CV 3 - M17B5 | B11: M17B5 | C11: C1096-Q9556 | D11: Ayabaca | E11: Frías | F11: 608596.92 | G11: 9445929.3 | H11: 24.9 | I11: 836 | J11: 837 | K11: 836.5 | L11: 6.66 | M11: 5.04 | N11: 0.54 | O11: Pendiente moderada | P11: Vegetación alta
A12: CV 4 - M6B2-1 | B12: M6B2-1 | C12: C1077-Q9566 | D12: Morropón | E12: Buenos Aires | F12: 613884.7 | G12: 9411595.5 | H12: 32.97 | I12: 265 | J12: 268 | K12: 266.33 | L12: 7.82 | M12: 4.87 | N12: 0.2 | O12: Pendiente moderada | P12: Vegetación ligera
A13: CV 5 - M2B8 | B13: M2B8 | C13: C1076-Q9584 | D13: Huancabamba | E13: San Miguel de El Faique | F13: 638998.57 | G13: 9398855.3 | H13: 50.61 | I13: 249 | J13: 252 | K13: 250.5 | L13: 4.36 | M13: 2.71 | N13: 0.25 | O13: Pendiente suave | P13: Vegetación ligera
A14: CV 6 - M6B2-2 | B14: M6B2-2 | C14: C1077-Q9566 | D14: Morropón | E14: Buenos Aires | F14: 611538.51 | G14: 9417753.5 | H14: 54.76 | I14: 237 | J14: 243 | K14: 240 | L14: 8.55 | M14: 5.27 | N14: 0.15 | O14: Pendiente moderada | P14: Tierra desnuda
A15: CV 7 - M17B7 | B15: M17B7 | C15: C1096-Q9556 | D15: Ayabaca | E15: Frías | F15: 608652.95 | G15: 9448359.5 | H15: 64.8 | I15: 799 | J15: 816 | K15: 807.4 | L15: 16.59 | M15: 9.95 | N15: 0.51 | O15: Pendiente moderada | P15: Vegetación alta
A16: CV 8 - M11B3 | B16: M11B3 | C16: C1081-Q9583 | D16: Morropón | E16: San Juan de Bigote | F16: 641568.33 | G16: 9413262.9 | H16: 65.38 | I16: 279 | J16: 286 | K16: 282.33 | L16: 6.44 | M16: 3.75 | N16: 0.3 | O16: Pendiente moderada | P16: Vegetación mediana
A17: CV 9 - M3B8 | B17: M3B8 | C17: C1081-Q9582 | D17: Morropón | E17: San Juan de Bigote | F17: 632155.23 | G17: 9414996 | H17: 69.33 | I17: 221 | J17: 222 | K17: 221.6 | L17: 3.57 | M17: 2.27 | N17: 0.19 | O17: Pendiente suave | P17: Vegetación ligera
