Workbook

Sheet Índice de mapas
A1: AUTORIDAD NACIONAL DE INFRAESTRUCTURA – ANIN
A2: DIRECCIÓN DE INTERVENCIONES MULTISECTORIALES Y DE EMERGENCIA – DIME
A3: SUBDIRECCIÓN DE ESTUDIOS DE INVERSIÓN – SESDI
A4: Proyecto IN Piura · CUI 2669244 · Entregable 2 · Subentregable 2.2: Expediente preliminar de liberación de áreas
A5: Índice de mapas de situación predial de los 117 bloques V6 (A3, UTM WGS 84 Zona 17S), con centros poblados y red vial departamental y vecinal — información de gabinete
A6: Superficie sin registro en las capas de comunidades campesinas (GEORURAL–MIDAGRI) y predios rurales (COFOPRI): se asume Tierras del Estado y/o posesionarios. Tolerancia cartográfica: 5 %.
A8: Lámina | B8: Bloque | C8: Provincia | D8: Distrito | E8: Asistente | F8: Superficie (ha) | G8: C. C. (ha) | H8: Predios COFOPRI fuera de C. C. (ha) | I8: Estado y/o posesionarios (ha) | J8: % C. C. | K8: % predios | L8: % Estado y/o posesionarios | M8: Situación predial | N8: Comunidad(es) campesina(s) | O8: N° predios COFOPRI | P8: Escala (A3) | Q8: Archivo | R8: N° CCPP asociados | S8: Centros poblados asociados (distancia al bloque) | T8: Fuente de la asociación | U8: Población de los CCPP (hab.)
A9: SP-001 | B9: 3 | C9: Ayabaca | D9: Frías | E9: AP-1 | F9: 459.295 | G9: 459.295 | H9: 0 | I9: =MAX(0,F9-G9-H9) | J9: =IF(F9=0,0,G9/F9) | K9: =IF(F9=0,0,H9/F9) | L9: =IF(F9=0,0,I9/F9) | M9: Comunal | N9: CASTRO POZO DE GERALDO; 24 DE JUNIO LAS CUEVAS | O9: 0 | P9: 1:20,000 | Q9: SP-001_Bloque_3.png | R9: 5 | S9: EL MIRADOR (0 m); LOS CHECCHES (7 m); HUAYABAL (64 m); HUASIPE DE GERALDO (196 m); RINCON DE GERALDO (285 m) | T9: Matriz CCPP-INEI v5 | U9: 495
A10: SP-002 | B10: 6 | C10: Ayabaca | D10: Frías | E10: AP-1 | F10: 168.411 | G10: 143.8 | H10: 0 | I10: =MAX(0,F10-G10-H10) | J10: =IF(F10=0,0,G10/F10) | K10: =IF(F10=0,0,H10/F10) | L10: =IF(F10=0,0,I10/F10) | M10: Parcialmente comunal | N10: 24 DE JUNIO LAS CUEVAS | O10: 0 | P10: 1:15,000 | Q10: SP-002_Bloque_6.png | R10: 3 | S10: GUANABANO ALTO (83 m); NOGAL (262 m); GUABAL (401 m) | T10: Matriz CCPP-INEI v5 | U10: 537
A11: SP-003 | B11: 27 | C11: Ayabaca | D11: Frías | E11: AP-1 | F11: 78.154 | G11: 71.322 | H11: 0 | I11: =MAX(0,F11-G11-H11) | J11: =IF(F11=0,0,G11/F11) | K11: =IF(F11=0,0,H11/F11) | L11: =IF(F11=0,0,I11/F11) | M11: Parcialmente comunal | N11: Sin nombre (ID 1508) | O11: 0 | P11: 1:7,500 | Q11: SP-003_Bloque_27.png | R11: 2 | S11: NUEVA ESPERANZA DE MISQUIS (475 m); LINDEROS DE MISQUIS (566 m) | T11: Matriz CCPP-INEI v5 | U11: 111
A12: SP-004 | B12: 36 | C12: Ayabaca | D12: Frías | E12: AP-1 | F12: 24.843 | G12: 1.133 | H12: 0 | I12: =MAX(0,F12-G12-H12) | J12: =IF(F12=0,0,G12/F12) | K12: =IF(F12=0,0,H12/F12) | L12: =IF(F12=0,0,I12/F12) | M12: Tierras del Estado y/o posesionarios | N12: 24 DE JUNIO LAS CUEVAS | O12: 0 | P12: 1:5,000 | Q12: SP-004_Bloque_36.png | R12: 1 | S12: GUABAL (526 m) | T12: Matriz CCPP-INEI v5 | U12: 280
A13: SP-005 | B13: 39 | C13: Ayabaca | D13: Frías | E13: AP-1 | F13: 68.569 | G13: 68.569 | H13: 0 | I13: =MAX(0,F13-G13-H13) | J13: =IF(F13=0,0,G13/F13) | K13: =IF(F13=0,0,H13/F13) | L13: =IF(F13=0,0,I13/F13) | M13: Comunal | N13: Sin nombre (ID 1508) | O13: 0 | P13: 1:6,000 | Q13: SP-005_Bloque_39.png | R13: 1 | S13: LA CRIA (404 m) | T13: Matriz CCPP-INEI v5 | U13: 327
A14: SP-006 | B14: 56 | C14: Ayabaca | D14: Frías | E14: AP-1 | F14: 77.666 | G14: 77.666 | H14: 0 | I14: =MAX(0,F14-G14-H14) | J14: =IF(F14=0,0,G14/F14) | K14: =IF(F14=0,0,H14/F14) | L14: =IF(F14=0,0,I14/F14) | M14: Comunal | N14: Sin nombre (ID 1508) | O14: 0 | P14: 1:12,500 | Q14: SP-006_Bloque_56.png | R14: 2 | S14: BANDA DE LA CRUZ (1462 m); PUTAGAS (1478 m) | T14: Matriz CCPP-INEI v5 | U14: 375
A15: SP-007 | B15: M17B5 | C15: Ayabaca | D15: Frías | E15: AP-1 | F15: 74.028 | G15: 74.028 | H15: 0 | I15: =MAX(0,F15-G15-H15) | J15: =IF(F15=0,0,G15/F15) | K15: =IF(F15=0,0,H15/F15) | L15: =IF(F15=0,0,I15/F15) | M15: Comunal | N15: SAN JOSE; MISQUIS | O15: 0 | P15: 1:6,000 | Q15: SP-007_Bloque_M17B5.png | R15: 0 | S15: Ref.: EL GUABO (40 m) | T15: Sin CCPP en la matriz
A16: SP-008 | B16: M17B6 | C16: Ayabaca | D16: Frías | E16: AP-1 | F16: 106.538 | G16: 103.586 | H16: 0 | I16: =MAX(0,F16-G16-H16) | J16: =IF(F16=0,0,G16/F16) | K16: =IF(F16=0,0,H16/F16) | L16: =IF(F16=0,0,I16/F16) | M16: Comunal | N16: MISQUIS | O16: 0 | P16: 1:15,000 | Q16: SP-008_Bloque_M17B6.png | R16: 3 | S16: PLATANAL ALTO (171 m); CHILILIQUE ALTO (262 m); EL GUABO (629 m) | T16: Matriz CCPP-INEI v5 | U16: 589
A17: SP-009 | B17: M17B7 | C17: Ayabaca | D17: Frías | E17: AP-1 | F17: 258.837 | G17: 167.601 | H17: 0 | I17: =MAX(0,F17-G17-H17) | J17: =IF(F17=0,0,G17/F17) | K17: =IF(F17=0,0,H17/F17) | L17: =IF(F17=0,0,I17/F17) | M17: Parcialmente comunal | N17: MISQUIS | O17: 0 | P17: 1:20,000 | Q17: SP-009_Bloque_M17B7.png | R17: 1 | S17: PAMPA DE RAMADA (284 m) | T17: Matriz CCPP-INEI v5 | U17: 107
A18: SP-010 | B18: M17B10 | C18: Ayabaca | D18: Frías | E18: AP-1 | F18: 75.363 | G18: 0 | H18: 0 | I18: =MAX(0,F18-G18-H18) | J18: =IF(F18=0,0,G18/F18) | K18: =IF(F18=0,0,H18/F18) | L18: =IF(F18=0,0,I18/F18) | M18: Tierras del Estado y/o posesionarios | O18: 0 | P18: 1:7,500 | Q18: SP-010_Bloque_M17B10.png | R18: 0 | S18: Ref.: PLATANAL ALTO (691 m) | T18: Sin CCPP en la matriz
A19: SP-011 | B19: 21 | C19: Huancabamba | D19: Canchaque | E19: AP-5 | F19: 84.227 | G19: 0 | H19: 0 | I19: =MAX(0,F19-G19-H19) | J19: =IF(F19=0,0,G19/F19) | K19: =IF(F19=0,0,H19/F19) | L19: =IF(F19=0,0,I19/F19) | M19: Tierras del Estado y/o posesionarios | O19: 0 | P19: 1:6,000 | Q19: SP-011_Bloque_21.png | R19: 1 | S19: HUAMALA ALTO (46 m) | T19: Matriz CCPP-INEI v5 | U19: 47
A20: SP-012 | B20: 24 | C20: Huancabamba | D20: Canchaque | E20: AP-5 | F20: 90.159 | G20: 2.067 | H20: 0 | I20: =MAX(0,F20-G20-H20) | J20: =IF(F20=0,0,G20/F20) | K20: =IF(F20=0,0,H20/F20) | L20: =IF(F20=0,0,I20/F20) | M20: Tierras del Estado y/o posesionarios | N20: Sin nombre (ID 2327) | O20: 0 | P20: 1:7,500 | Q20: SP-012_Bloque_24.png | R20: 1 | S20: COYONA (575 m) | T20: Matriz CCPP-INEI v5 | U20: 443
A21: SP-013 | B21: 28 | C21: Huancabamba | D21: Canchaque | E21: AP-5 | F21: 52.966 | G21: 0 | H21: 14.252 | I21: =MAX(0,F21-G21-H21) | J21: =IF(F21=0,0,G21/F21) | K21: =IF(F21=0,0,H21/F21) | L21: =IF(F21=0,0,I21/F21) | M21: Parcialmente privada | O21: 17 | P21: 1:7,500 | Q21: SP-013_Bloque_28.png | R21: 1 | S21: ABALQUE (215 m) | T21: Matriz CCPP-INEI v5 | U21: 66
A22: SP-014 | B22: 30 | C22: Huancabamba | D22: Canchaque | E22: AP-5 | F22: 34.874 | G22: 0 | H22: 33.133 | I22: =MAX(0,F22-G22-H22) | J22: =IF(F22=0,0,G22/F22) | K22: =IF(F22=0,0,H22/F22) | L22: =IF(F22=0,0,I22/F22) | M22: Privada | O22: 10 | P22: 1:10,000 | Q22: SP-014_Bloque_30.png | R22: 2 | S22: SAPCE (992 m); CHAMELICO (1505 m) | T22: Matriz CCPP-INEI v5 | U22: 168
A23: SP-015 | B23: 40 | C23: Huancabamba | D23: Canchaque | E23: AP-5 | F23: 28.523 | G23: 0 | H23: 15.262 | I23: =MAX(0,F23-G23-H23) | J23: =IF(F23=0,0,G23/F23) | K23: =IF(F23=0,0,H23/F23) | L23: =IF(F23=0,0,I23/F23) | M23: Parcialmente privada | O23: 12 | P23: 1:4,000 | Q23: SP-015_Bloque_40.png | R23: 2 | S23: CHACCHACAL (87 m); CHORRO BLANCO (96 m) | T23: Matriz CCPP-INEI v5 | U23: 58
A24: SP-016 | B24: 60 | C24: Huancabamba | D24: Canchaque | E24: AP-5 | F24: 40.132 | G24: 0 | H24: 39.963 | I24: =MAX(0,F24-G24-H24) | J24: =IF(F24=0,0,G24/F24) | K24: =IF(F24=0,0,H24/F24) | L24: =IF(F24=0,0,I24/F24) | M24: Privada | O24: 14 | P24: 1:7,500 | Q24: SP-016_Bloque_60.png | R24: 1 | S24: FLOR DE CAFE (574 m) | T24: Matriz CCPP-INEI v5 | U24: 111
A25: SP-017 | B25: 63 | C25: Huancabamba | D25: Canchaque | E25: AP-5 | F25: 50.459 | G25: 50.459 | H25: 0 | I25: =MAX(0,F25-G25-H25) | J25: =IF(F25=0,0,G25/F25) | K25: =IF(F25=0,0,H25/F25) | L25: =IF(F25=0,0,I25/F25) | M25: Comunal | N25: Sin nombre (ID 2790) | O25: 0 | P25: 1:5,000 | Q25: SP-017_Bloque_63.png | R25: 1 | S25: SHUTURUMBE (108 m) | T25: Matriz CCPP-INEI v5 | U25: 87
A26: SP-018 | B26: 66 | C26: Huancabamba | D26: Canchaque | E26: AP-5 | F26: 102.335 | G26: 0 | H26: 0 | I26: =MAX(0,F26-G26-H26) | J26: =IF(F26=0,0,G26/F26) | K26: =IF(F26=0,0,H26/F26) | L26: =IF(F26=0,0,I26/F26) | M26: Tierras del Estado y/o posesionarios | O26: 0 | P26: 1:10,000 | Q26: SP-018_Bloque_66.png | R26: 1 | S26: HUAMALA BAJA (220 m) | T26: Matriz CCPP-INEI v5 | U26: 45
A27: SP-019 | B27: 79 | C27: Huancabamba | D27: Canchaque | E27: AP-5 | F27: 94.812 | G27: 94.812 | H27: 0 | I27: =MAX(0,F27-G27-H27) | J27: =IF(F27=0,0,G27/F27) | K27: =IF(F27=0,0,H27/F27) | L27: =IF(F27=0,0,I27/F27) | M27: Comunal | N27: Sin nombre (ID 2790) | O27: 0 | P27: 1:12,500 | Q27: SP-019_Bloque_79.png | R27: 2 | S27: HUABAL (740 m); ALMIRANTE MIGUEL GRAU (1043 m) | T27: Matriz CCPP-INEI v5 | U27: 219
A28: SP-020 | B28: 81 | C28: Huancabamba | D28: Canchaque | E28: AP-5 | F28: 8.929 | G28: 8.929 | H28: 0 | I28: =MAX(0,F28-G28-H28) | J28: =IF(F28=0,0,G28/F28) | K28: =IF(F28=0,0,H28/F28) | L28: =IF(F28=0,0,I28/F28) | M28: Comunal | N28: Sin nombre (ID 2790) | O28: 0 | P28: 1:3,000 | Q28: SP-020_Bloque_81.png | R28: 1 | S28: HUALTACAL (129 m) | T28: Matriz CCPP-INEI v5 | U28: 80
A29: SP-021 | B29: 64 | C29: Huancabamba | D29: Huancabamba | E29: AP-5 | F29: 35.774 | G29: 0 | H29: 0 | I29: =MAX(0,F29-G29-H29) | J29: =IF(F29=0,0,G29/F29) | K29: =IF(F29=0,0,H29/F29) | L29: =IF(F29=0,0,I29/F29) | M29: Tierras del Estado y/o posesionarios | O29: 0 | P29: 1:7,500 | Q29: SP-021_Bloque_64.png | R29: 1 | S29: PARIAMARCA CENTRO (887 m) | T29: Matriz CCPP-INEI v5 | U29: 311
A30: SP-022 | B30: M30B5 | C30: Huancabamba | D30: Huancabamba | E30: AP-5 | F30: 90.903 | G30: 0 | H30: 0 | I30: =MAX(0,F30-G30-H30) | J30: =IF(F30=0,0,G30/F30) | K30: =IF(F30=0,0,H30/F30) | L30: =IF(F30=0,0,I30/F30) | M30: Tierras del Estado y/o posesionarios | O30: 0 | P30: 1:10,000 | Q30: SP-022_Bloque_M30B5.png | R30: 0 | S30: Ref.: PARIAMARCA CENTRO (1250 m) | T30: Sin CCPP en la matriz
A31: SP-023 | B31: 4 | C31: Huancabamba | D31: Huarmaca | E31: AP-5 | F31: 230.098 | G31: 0 | H31: 14.559 | I31: =MAX(0,F31-G31-H31) | J31: =IF(F31=0,0,G31/F31) | K31: =IF(F31=0,0,H31/F31) | L31: =IF(F31=0,0,I31/F31) | M31: Parcialmente privada | O31: 37 | P31: 1:20,000 | Q31: SP-023_Bloque_4.png | R31: 2 | S31: LA RINCONADA (1066 m); SAN ANTONIO DE SUCCHIRCA (1176 m) | T31: Matriz CCPP-INEI v5 | U31: 385
A32: SP-024 | B32: 8 | C32: Huancabamba | D32: Huarmaca | E32: AP-5 | F32: 126.952 | G32: 0 | H32: 0 | I32: =MAX(0,F32-G32-H32) | J32: =IF(F32=0,0,G32/F32) | K32: =IF(F32=0,0,H32/F32) | L32: =IF(F32=0,0,I32/F32) | M32: Tierras del Estado y/o posesionarios | O32: 0 | P32: 1:10,000 | Q32: SP-024_Bloque_8.png | R32: 1 | S32: PIRGA (414 m) | T32: Matriz CCPP-INEI v5 | U32: 322
A33: SP-025 | B33: 10 | C33: Huancabamba | D33: Huarmaca | E33: AP-5 | F33: 150.214 | G33: 0 | H33: 0 | I33: =MAX(0,F33-G33-H33) | J33: =IF(F33=0,0,G33/F33) | K33: =IF(F33=0,0,H33/F33) | L33: =IF(F33=0,0,I33/F33) | M33: Tierras del Estado y/o posesionarios | O33: 0 | P33: 1:12,500 | Q33: SP-025_Bloque_10.png | R33: 1 | S33: LA PEÑA (113 m) | T33: Matriz CCPP-INEI v5 | U33: 146
A34: SP-026 | B34: 16 | C34: Huancabamba | D34: Huarmaca | E34: AP-5 | F34: 83.327 | G34: 0 | H34: 0 | I34: =MAX(0,F34-G34-H34) | J34: =IF(F34=0,0,G34/F34) | K34: =IF(F34=0,0,H34/F34) | L34: =IF(F34=0,0,I34/F34) | M34: Tierras del Estado y/o posesionarios | O34: 0 | P34: 1:12,500 | Q34: SP-026_Bloque_16.png | R34: 1 | S34: LAGUNA DE PALTAMA (287 m) | T34: Matriz CCPP-INEI v5 | U34: 153
A35: SP-027 | B35: 18 | C35: Huancabamba | D35: Huarmaca | E35: AP-6 | F35: 103.617 | G35: 0 | H35: 11.017 | I35: =MAX(0,F35-G35-H35) | J35: =IF(F35=0,0,G35/F35) | K35: =IF(F35=0,0,H35/F35) | L35: =IF(F35=0,0,I35/F35) | M35: Parcialmente privada | O35: 7 | P35: 1:10,000 | Q35: SP-027_Bloque_18.png | R35: 1 | S35: PIEDRA BLANCA (378 m) | T35: Matriz CCPP-INEI v5 | U35: 28
A36: SP-028 | B36: 19 | C36: Huancabamba | D36: Huarmaca | E36: AP-6 | F36: 82.088 | G36: 82.088 | H36: 0 | I36: =MAX(0,F36-G36-H36) | J36: =IF(F36=0,0,G36/F36) | K36: =IF(F36=0,0,H36/F36) | L36: =IF(F36=0,0,I36/F36) | M36: Comunal | N36: SEGUNDA | O36: 0 | P36: 1:10,000 | Q36: SP-028_Bloque_19.png | R36: 2 | S36: NUEVO PROGRESO (169 m); TABLURAN (593 m) | T36: Matriz CCPP-INEI v5 | U36: 132
A37: SP-029 | B37: 20 | C37: Huancabamba | D37: Huarmaca | E37: AP-5 | F37: 81.334 | G37: 0 | H37: 0 | I37: =MAX(0,F37-G37-H37) | J37: =IF(F37=0,0,G37/F37) | K37: =IF(F37=0,0,H37/F37) | L37: =IF(F37=0,0,I37/F37) | M37: Tierras del Estado y/o posesionarios | O37: 0 | P37: 1:7,500 | Q37: SP-029_Bloque_20.png | R37: 1 | S37: TUPAC AMARU (249 m) | T37: Matriz CCPP-INEI v5 | U37: 149
A38: SP-030 | B38: 31 | C38: Huancabamba | D38: Huarmaca | E38: AP-6 | F38: 47.581 | G38: 0 | H38: 1.069 | I38: =MAX(0,F38-G38-H38) | J38: =IF(F38=0,0,G38/F38) | K38: =IF(F38=0,0,H38/F38) | L38: =IF(F38=0,0,I38/F38) | M38: Tierras del Estado y/o posesionarios | O38: 7 | P38: 1:10,000 | Q38: SP-030_Bloque_31.png | R38: 0 | S38: Ref.: LIMON (1511 m) | T38: Sin CCPP en la matriz
A39: SP-031 | B39: 41 | C39: Huancabamba | D39: Huarmaca | E39: AP-6 | F39: 64.923 | G39: 0 | H39: 8.077 | I39: =MAX(0,F39-G39-H39) | J39: =IF(F39=0,0,G39/F39) | K39: =IF(F39=0,0,H39/F39) | L39: =IF(F39=0,0,I39/F39) | M39: Parcialmente privada | O39: 10 | P39: 1:10,000 | Q39: SP-031_Bloque_41.png | R39: 1 | S39: CAMBRURAN (110 m) | T39: Matriz CCPP-INEI v5 | U39: 54
A40: SP-032 | B40: 51 | C40: Huancabamba | D40: Huarmaca | E40: AP-5 | F40: 22.927 | G40: 0 | H40: 19.635 | I40: =MAX(0,F40-G40-H40) | J40: =IF(F40=0,0,G40/F40) | K40: =IF(F40=0,0,H40/F40) | L40: =IF(F40=0,0,I40/F40) | M40: Parcialmente privada | O40: 12 | P40: 1:7,500 | Q40: SP-032_Bloque_51.png | R40: 2 | S40: TALLA (275 m); SHAIN (1013 m) | T40: Matriz CCPP-INEI v5 | U40: 348
A41: SP-033 | B41: 53 | C41: Huancabamba | D41: Huarmaca | E41: AP-6 | F41: 13.065 | G41: 0 | H41: 4.613 | I41: =MAX(0,F41-G41-H41) | J41: =IF(F41=0,0,G41/F41) | K41: =IF(F41=0,0,H41/F41) | L41: =IF(F41=0,0,I41/F41) | M41: Parcialmente privada | O41: 5 | P41: 1:4,000 | Q41: SP-033_Bloque_53.png | R41: 1 | S41: ZURURAN (209 m) | T41: Matriz CCPP-INEI v5 | U41: 140
...

Sheet Resumen
A1: AUTORIDAD NACIONAL DE INFRAESTRUCTURA – ANIN
A2: DIRECCIÓN DE INTERVENCIONES MULTISECTORIALES Y DE EMERGENCIA – DIME
A3: SUBDIRECCIÓN DE ESTUDIOS DE INVERSIÓN – SESDI
A5: Situación predial de los bloques V6 (fórmulas sobre la hoja «Índice de mapas»)
A7: Situación predial | B7: Bloques | C7: Superficie (ha) | D7: % de la superficie | E7: C. C. (ha) | F7: Estado y/o posesionarios (ha)
A8: Comunal | B8: =COUNTIF('Índice de mapas'!$M$9:$M$125,A8) | C8: =SUMIF('Índice de mapas'!$M$9:$M$125,A8,'Índice de mapas'!$F$9:$F$125) | D8: =C8/C$14 | E8: =SUMIF('Índice de mapas'!$M$9:$M$125,A8,'Índice de mapas'!$G$9:$G$125) | F8: =SUMIF('Índice de mapas'!$M$9:$M$125,A8,'Índice de mapas'!$I$9:$I$125)
A9: Parcialmente comunal | B9: =COUNTIF('Índice de mapas'!$M$9:$M$125,A9) | C9: =SUMIF('Índice de mapas'!$M$9:$M$125,A9,'Índice de mapas'!$F$9:$F$125) | D9: =C9/C$14 | E9: =SUMIF('Índice de mapas'!$M$9:$M$125,A9,'Índice de mapas'!$G$9:$G$125) | F9: =SUMIF('Índice de mapas'!$M$9:$M$125,A9,'Índice de mapas'!$I$9:$I$125)
A10: Mixta | B10: =COUNTIF('Índice de mapas'!$M$9:$M$125,A10) | C10: =SUMIF('Índice de mapas'!$M$9:$M$125,A10,'Índice de mapas'!$F$9:$F$125) | D10: =C10/C$14 | E10: =SUMIF('Índice de mapas'!$M$9:$M$125,A10,'Índice de mapas'!$G$9:$G$125) | F10: =SUMIF('Índice de mapas'!$M$9:$M$125,A10,'Índice de mapas'!$I$9:$I$125)
A11: Privada | B11: =COUNTIF('Índice de mapas'!$M$9:$M$125,A11) | C11: =SUMIF('Índice de mapas'!$M$9:$M$125,A11,'Índice de mapas'!$F$9:$F$125) | D11: =C11/C$14 | E11: =SUMIF('Índice de mapas'!$M$9:$M$125,A11,'Índice de mapas'!$G$9:$G$125) | F11: =SUMIF('Índice de mapas'!$M$9:$M$125,A11,'Índice de mapas'!$I$9:$I$125)
A12: Parcialmente privada | B12: =COUNTIF('Índice de mapas'!$M$9:$M$125,A12) | C12: =SUMIF('Índice de mapas'!$M$9:$M$125,A12,'Índice de mapas'!$F$9:$F$125) | D12: =C12/C$14 | E12: =SUMIF('Índice de mapas'!$M$9:$M$125,A12,'Índice de mapas'!$G$9:$G$125) | F12: =SUMIF('Índice de mapas'!$M$9:$M$125,A12,'Índice de mapas'!$I$9:$I$125)
A13: Tierras del Estado y/o posesionarios | B13: =COUNTIF('Índice de mapas'!$M$9:$M$125,A13) | C13: =SUMIF('Índice de mapas'!$M$9:$M$125,A13,'Índice de mapas'!$F$9:$F$125) | D13: =C13/C$14 | E13: =SUMIF('Índice de mapas'!$M$9:$M$125,A13,'Índice de mapas'!$G$9:$G$125) | F13: =SUMIF('Índice de mapas'!$M$9:$M$125,A13,'Índice de mapas'!$I$9:$I$125)
A14: Total | B14: =SUM(B8:B13) | C14: =SUM(C8:C13) | D14: =C14/C14 | E14: =SUM(E8:E13) | F14: =SUM(F8:F13)
