Workbook

Sheet Resumen_Ecosistema
A1: AUTORIDAD NACIONAL DE INFRAESTRUCTURA - ANIN
A2: DIRECCIÓN DE INTERVENCIONES MULTISECTORIALES Y DE EMERGENCIA - DIME
A3: SUBDIRECCIÓN DE ESTUDIOS DE INVERSIÓN - SESDI
A4: SUPERFICIE DE ECOSISTEMAS EN LOS 117 BLOQUES V6
A5: PROYECTO IN PIURA | CUI 2669244 | Cuenca Alta del Río Piura | UTM WGS 84 Zona 17S (EPSG:32717)
A6: Fuente: Ecosistemas: Mapa Nacional de Ecosistemas del Perú, MINAM 2018 (R.M. N.° 440-2018-MINAM): recorte a microcuencas, completado en M27B1 y M9B1 con el recorte a esos bloques. Bloques V6, ANIN-DIME-SESDI 2026 (sin 74 y 75)
A8: N.° | B8: Ecosistema | C8: Símbolo | D8: N.° de bloques | E8: Área en bloques (ha) | F8: % de los bloques | G8: Área en el ámbito (ha) | H8: % del ecosistema intervenido
A9: 1 | B9: Bosque estacionalmente seco de colina y montaña | C9: Bes-cm | D9: =COUNTIF(Bloque_Ecosistema!$F$9:$F$198,B9) | E9: =SUMIF(Bloque_Ecosistema!$F$9:$F$198,B9,Bloque_Ecosistema!$K$9:$K$198) | F9: =E9/E$15 | G9: 188280.25 | H9: =IF(N(G9)=0,"",E9/G9)
A10: 2 | B10: Zona agrícola | C10: Agri | D10: =COUNTIF(Bloque_Ecosistema!$F$9:$F$198,B10) | E10: =SUMIF(Bloque_Ecosistema!$F$9:$F$198,B10,Bloque_Ecosistema!$K$9:$K$198) | F10: =E10/E$15 | G10: 155867.89 | H10: =IF(N(G10)=0,"",E10/G10)
A11: 3 | B11: Matorral andino | C11: Ma | D11: =COUNTIF(Bloque_Ecosistema!$F$9:$F$198,B11) | E11: =SUMIF(Bloque_Ecosistema!$F$9:$F$198,B11,Bloque_Ecosistema!$K$9:$K$198) | F11: =E11/E$15 | G11: 31192.831 | H11: =IF(N(G11)=0,"",E11/G11)
A12: 4 | B12: Bosque relicto montano de vertiente occidental | C12: Br-mvoc | D12: =COUNTIF(Bloque_Ecosistema!$F$9:$F$198,B12) | E12: =SUMIF(Bloque_Ecosistema!$F$9:$F$198,B12,Bloque_Ecosistema!$K$9:$K$198) | F12: =E12/E$15 | G12: 6281.805 | H12: =IF(N(G12)=0,"",E12/G12)
A13: 5 | B13: Páramo | C13: Pa | D13: =COUNTIF(Bloque_Ecosistema!$F$9:$F$198,B13) | E13: =SUMIF(Bloque_Ecosistema!$F$9:$F$198,B13,Bloque_Ecosistema!$K$9:$K$198) | F13: =E13/E$15 | G13: 3843.332 | H13: =IF(N(G13)=0,"",E13/G13)
A14: 6 | B14: Sin información de ecosistema | D14: =COUNTIF(Bloque_Ecosistema!$F$9:$F$198,B14) | E14: =SUMIF(Bloque_Ecosistema!$F$9:$F$198,B14,Bloque_Ecosistema!$K$9:$K$198) | F14: =E14/E$15 | H14: =IF(N(G14)=0,"",E14/G14)
A15: TOTAL | E15: =SUM(E9:E14) | F15: =SUM(F9:F14) | G15: =SUM(G9:G14)
B17: =IF(ABS(E15-12270.235)<0.01,"OK: suma 12,270.235 ha","REVISAR: no suma 12,270.235 ha")

Sheet Ecosistema_Provincia
A1: AUTORIDAD NACIONAL DE INFRAESTRUCTURA - ANIN
A2: DIRECCIÓN DE INTERVENCIONES MULTISECTORIALES Y DE EMERGENCIA - DIME
A3: SUBDIRECCIÓN DE ESTUDIOS DE INVERSIÓN - SESDI
A4: ECOSISTEMAS EN LOS BLOQUES V6 POR PROVINCIA (ha)
A5: PROYECTO IN PIURA | CUI 2669244 | Cuenca Alta del Río Piura | UTM WGS 84 Zona 17S (EPSG:32717)
A6: Fuente: Ecosistemas: Mapa Nacional de Ecosistemas del Perú, MINAM 2018 (R.M. N.° 440-2018-MINAM): recorte a microcuencas, completado en M27B1 y M9B1 con el recorte a esos bloques. Bloques V6, ANIN-DIME-SESDI 2026 (sin 74 y 75)
A8: Ecosistema | B8: Ayabaca (ha) | C8: Huancabamba (ha) | D8: Morropón (ha) | E8: Total (ha)
A9: Bosque estacionalmente seco de colina y montaña | B9: =SUMIFS(Bloque_Ecosistema!$K$9:$K$198,Bloque_Ecosistema!$F$9:$F$198,$A9,Bloque_Ecosistema!$D$9:$D$198,"Ayabaca") | C9: =SUMIFS(Bloque_Ecosistema!$K$9:$K$198,Bloque_Ecosistema!$F$9:$F$198,$A9,Bloque_Ecosistema!$D$9:$D$198,"Huancabamba") | D9: =SUMIFS(Bloque_Ecosistema!$K$9:$K$198,Bloque_Ecosistema!$F$9:$F$198,$A9,Bloque_Ecosistema!$D$9:$D$198,"Morropón") | E9: =SUM(B9:D9)
A10: Zona agrícola | B10: =SUMIFS(Bloque_Ecosistema!$K$9:$K$198,Bloque_Ecosistema!$F$9:$F$198,$A10,Bloque_Ecosistema!$D$9:$D$198,"Ayabaca") | C10: =SUMIFS(Bloque_Ecosistema!$K$9:$K$198,Bloque_Ecosistema!$F$9:$F$198,$A10,Bloque_Ecosistema!$D$9:$D$198,"Huancabamba") | D10: =SUMIFS(Bloque_Ecosistema!$K$9:$K$198,Bloque_Ecosistema!$F$9:$F$198,$A10,Bloque_Ecosistema!$D$9:$D$198,"Morropón") | E10: =SUM(B10:D10)
A11: Matorral andino | B11: =SUMIFS(Bloque_Ecosistema!$K$9:$K$198,Bloque_Ecosistema!$F$9:$F$198,$A11,Bloque_Ecosistema!$D$9:$D$198,"Ayabaca") | C11: =SUMIFS(Bloque_Ecosistema!$K$9:$K$198,Bloque_Ecosistema!$F$9:$F$198,$A11,Bloque_Ecosistema!$D$9:$D$198,"Huancabamba") | D11: =SUMIFS(Bloque_Ecosistema!$K$9:$K$198,Bloque_Ecosistema!$F$9:$F$198,$A11,Bloque_Ecosistema!$D$9:$D$198,"Morropón") | E11: =SUM(B11:D11)
A12: Bosque relicto montano de vertiente occidental | B12: =SUMIFS(Bloque_Ecosistema!$K$9:$K$198,Bloque_Ecosistema!$F$9:$F$198,$A12,Bloque_Ecosistema!$D$9:$D$198,"Ayabaca") | C12: =SUMIFS(Bloque_Ecosistema!$K$9:$K$198,Bloque_Ecosistema!$F$9:$F$198,$A12,Bloque_Ecosistema!$D$9:$D$198,"Huancabamba") | D12: =SUMIFS(Bloque_Ecosistema!$K$9:$K$198,Bloque_Ecosistema!$F$9:$F$198,$A12,Bloque_Ecosistema!$D$9:$D$198,"Morropón") | E12: =SUM(B12:D12)
A13: Páramo | B13: =SUMIFS(Bloque_Ecosistema!$K$9:$K$198,Bloque_Ecosistema!$F$9:$F$198,$A13,Bloque_Ecosistema!$D$9:$D$198,"Ayabaca") | C13: =SUMIFS(Bloque_Ecosistema!$K$9:$K$198,Bloque_Ecosistema!$F$9:$F$198,$A13,Bloque_Ecosistema!$D$9:$D$198,"Huancabamba") | D13: =SUMIFS(Bloque_Ecosistema!$K$9:$K$198,Bloque_Ecosistema!$F$9:$F$198,$A13,Bloque_Ecosistema!$D$9:$D$198,"Morropón") | E13: =SUM(B13:D13)
A14: Sin información de ecosistema | B14: =SUMIFS(Bloque_Ecosistema!$K$9:$K$198,Bloque_Ecosistema!$F$9:$F$198,$A14,Bloque_Ecosistema!$D$9:$D$198,"Ayabaca") | C14: =SUMIFS(Bloque_Ecosistema!$K$9:$K$198,Bloque_Ecosistema!$F$9:$F$198,$A14,Bloque_Ecosistema!$D$9:$D$198,"Huancabamba") | D14: =SUMIFS(Bloque_Ecosistema!$K$9:$K$198,Bloque_Ecosistema!$F$9:$F$198,$A14,Bloque_Ecosistema!$D$9:$D$198,"Morropón") | E14: =SUM(B14:D14)
A15: TOTAL | B15: =SUM(B9:B14) | C15: =SUM(C9:C14) | D15: =SUM(D9:D14) | E15: =SUM(E9:E14)

Sheet Bloques
A1: AUTORIDAD NACIONAL DE INFRAESTRUCTURA - ANIN
A2: DIRECCIÓN DE INTERVENCIONES MULTISECTORIALES Y DE EMERGENCIA - DIME
A3: SUBDIRECCIÓN DE ESTUDIOS DE INVERSIÓN - SESDI
A4: ECOSISTEMA DOMINANTE POR BLOQUE V6
A5: PROYECTO IN PIURA | CUI 2669244 | Cuenca Alta del Río Piura | UTM WGS 84 Zona 17S (EPSG:32717)
A6: Fuente: Ecosistemas: Mapa Nacional de Ecosistemas del Perú, MINAM 2018 (R.M. N.° 440-2018-MINAM): recorte a microcuencas, completado en M27B1 y M9B1 con el recorte a esos bloques. Bloques V6, ANIN-DIME-SESDI 2026 (sin 74 y 75)
A8: N.° | B8: Bloque | C8: Microcuenca | D8: Provincia | E8: Distrito | F8: Área catálogo (ha) | G8: N.° de ecosistemas | H8: Ecosistema dominante | I8: % del dominante | J8: Otros ecosistemas
A9: 1 | B9: 27 | C9: C1096-Q9556 | D9: Ayabaca | E9: Frías | F9: 78.154 | G9: =COUNTIF(Bloque_Ecosistema!$B$9:$B$198,B9) | H9: Zona agrícola | I9: 1
A10: 2 | B10: 3 | C10: C1096-Q9545 | D10: Ayabaca | E10: Frías | F10: 459.295 | G10: =COUNTIF(Bloque_Ecosistema!$B$9:$B$198,B10) | H10: Zona agrícola | I10: 0.9454 | J10: Bosque estacionalmente seco de colina y montaña (5%)
A11: 3 | B11: 36 | C11: C1096-Q9547 | D11: Ayabaca | E11: Frías | F11: 24.843 | G11: =COUNTIF(Bloque_Ecosistema!$B$9:$B$198,B11) | H11: Zona agrícola | I11: 1
A12: 4 | B12: 39 | C12: C1096-Q9564 | D12: Ayabaca | E12: Frías | F12: 68.569 | G12: =COUNTIF(Bloque_Ecosistema!$B$9:$B$198,B12) | H12: Matorral andino | I12: 1
A13: 5 | B13: 56 | C13: C1096-Q9564 | D13: Ayabaca | E13: Frías | F13: 77.666 | G13: =COUNTIF(Bloque_Ecosistema!$B$9:$B$198,B13) | H13: Bosque relicto montano de vertiente occidental | I13: 0.5388 | J13: Zona agrícola (46%)
A14: 6 | B14: 6 | C14: C1096-Q9547 | D14: Ayabaca | E14: Frías | F14: 168.411 | G14: =COUNTIF(Bloque_Ecosistema!$B$9:$B$198,B14) | H14: Zona agrícola | I14: 0.9752 | J14: Bosque estacionalmente seco de colina y montaña (2%)
A15: 7 | B15: M17B10 | C15: C1096-Q9556 | D15: Ayabaca | E15: Frías | F15: 75.363 | G15: =COUNTIF(Bloque_Ecosistema!$B$9:$B$198,B15) | H15: Zona agrícola | I15: 0.5748 | J15: Bosque estacionalmente seco de colina y montaña (43%)
A16: 8 | B16: M17B5 | C16: C1096-Q9556 | D16: Ayabaca | E16: Frías | F16: 74.028 | G16: =COUNTIF(Bloque_Ecosistema!$B$9:$B$198,B16) | H16: Bosque estacionalmente seco de colina y montaña | I16: 0.7086 | J16: Zona agrícola (29%)
A17: 9 | B17: M17B6 | C17: C1096-Q9556 | D17: Ayabaca | E17: Frías | F17: 106.538 | G17: =COUNTIF(Bloque_Ecosistema!$B$9:$B$198,B17) | H17: Bosque estacionalmente seco de colina y montaña | I17: 1
A18: 10 | B18: M17B7 | C18: C1096-Q9556 | D18: Ayabaca | E18: Frías | F18: 258.837 | G18: =COUNTIF(Bloque_Ecosistema!$B$9:$B$198,B18) | H18: Zona agrícola | I18: 0.559 | J18: Bosque estacionalmente seco de colina y montaña (44%)
A19: 11 | B19: 21 | C19: C1081-Q9591 | D19: Huancabamba | E19: Canchaque | F19: 84.227 | G19: =COUNTIF(Bloque_Ecosistema!$B$9:$B$198,B19) | H19: Zona agrícola | I19: 0.5607 | J19: Matorral andino (44%)
A20: 12 | B20: 24 | C20: C1081-Q9583 | D20: Huancabamba | E20: Canchaque | F20: 90.159 | G20: =COUNTIF(Bloque_Ecosistema!$B$9:$B$198,B20) | H20: Zona agrícola | I20: 0.6608 | J20: Matorral andino (18%); Bosque estacionalmente seco de colina y montaña (15%)
A21: 13 | B21: 28 | C21: C1081-Q9591 | D21: Huancabamba | E21: Canchaque | F21: 52.966 | G21: =COUNTIF(Bloque_Ecosistema!$B$9:$B$198,B21) | H21: Zona agrícola | I21: 0.6032 | J21: Matorral andino (40%)
A22: 14 | B22: 30 | C22: C1081-Q9591 | D22: Huancabamba | E22: Canchaque | F22: 34.874 | G22: =COUNTIF(Bloque_Ecosistema!$B$9:$B$198,B22) | H22: Zona agrícola | I22: 0.7743 | J22: Matorral andino (23%)
A23: 15 | B23: 40 | C23: C1081-Q9591 | D23: Huancabamba | E23: Canchaque | F23: 28.523 | G23: =COUNTIF(Bloque_Ecosistema!$B$9:$B$198,B23) | H23: Zona agrícola | I23: 0.5954 | J23: Matorral andino (40%)
A24: 16 | B24: 60 | C24: C1081-Q9591 | D24: Huancabamba | E24: Canchaque | F24: 40.132 | G24: =COUNTIF(Bloque_Ecosistema!$B$9:$B$198,B24) | H24: Matorral andino | I24: 0.5911 | J24: Zona agrícola (41%)
A25: 17 | B25: 63 | C25: C1081-Q9583 | D25: Huancabamba | E25: Canchaque | F25: 50.459 | G25: =COUNTIF(Bloque_Ecosistema!$B$9:$B$198,B25) | H25: Matorral andino | I25: 1
A26: 18 | B26: 66 | C26: C1081-Q9591 | D26: Huancabamba | E26: Canchaque | F26: 102.335 | G26: =COUNTIF(Bloque_Ecosistema!$B$9:$B$198,B26) | H26: Zona agrícola | I26: 0.7529 | J26: Bosque estacionalmente seco de colina y montaña (19%); Matorral andino (6%)
A27: 19 | B27: 79 | C27: C1076-Q9587 | D27: Huancabamba | E27: Canchaque | F27: 94.812 | G27: =COUNTIF(Bloque_Ecosistema!$B$9:$B$198,B27) | H27: Bosque estacionalmente seco de colina y montaña | I27: 1
A28: 20 | B28: 81 | C28: C1076-Q9585 | D28: Huancabamba | E28: Canchaque | F28: 8.929 | G28: =COUNTIF(Bloque_Ecosistema!$B$9:$B$198,B28) | H28: Bosque estacionalmente seco de colina y montaña | I28: 1
A29: 21 | B29: 64 | C29: C1081-Q9591 | D29: Huancabamba | E29: Huancabamba | F29: 35.774 | G29: =COUNTIF(Bloque_Ecosistema!$B$9:$B$198,B29) | H29: Zona agrícola | I29: 1
A30: 22 | B30: M30B5 | C30: C1081-Q9591 | D30: Huancabamba | E30: Huancabamba | F30: 90.903 | G30: =COUNTIF(Bloque_Ecosistema!$B$9:$B$198,B30) | H30: Zona agrícola | I30: 0.821 | J30: Matorral andino (18%)
A31: 23 | B31: 10 | C31: C1076-Q9593 | D31: Huancabamba | E31: Huarmaca | F31: 150.214 | G31: =COUNTIF(Bloque_Ecosistema!$B$9:$B$198,B31) | H31: Bosque estacionalmente seco de colina y montaña | I31: 0.8613 | J31: Zona agrícola (14%)
A32: 24 | B32: 16 | C32: C1076-Q9593 | D32: Huancabamba | E32: Huarmaca | F32: 83.327 | G32: =COUNTIF(Bloque_Ecosistema!$B$9:$B$198,B32) | H32: Zona agrícola | I32: 0.5477 | J32: Bosque estacionalmente seco de colina y montaña (45%)
A33: 25 | B33: 18 | C33: C1076-Q9592 | D33: Huancabamba | E33: Huarmaca | F33: 103.617 | G33: =COUNTIF(Bloque_Ecosistema!$B$9:$B$198,B33) | H33: Bosque estacionalmente seco de colina y montaña | I33: 0.9101 | J33: Zona agrícola (9%)
A34: 26 | B34: 19 | C34: C1076-Q9592 | D34: Huancabamba | E34: Huarmaca | F34: 82.088 | G34: =COUNTIF(Bloque_Ecosistema!$B$9:$B$198,B34) | H34: Matorral andino | I34: 0.5146 | J34: Zona agrícola (49%)
A35: 27 | B35: 20 | C35: C1076-Q9593 | D35: Huancabamba | E35: Huarmaca | F35: 81.334 | G35: =COUNTIF(Bloque_Ecosistema!$B$9:$B$198,B35) | H35: Bosque estacionalmente seco de colina y montaña | I35: 0.5199 | J35: Matorral andino (48%)
A36: 28 | B36: 31 | C36: C1076-Q9592 | D36: Huancabamba | E36: Huarmaca | F36: 47.581 | G36: =COUNTIF(Bloque_Ecosistema!$B$9:$B$198,B36) | H36: Matorral andino | I36: 1
A37: 29 | B37: 4 | C37: C1076-Q9588 | D37: Huancabamba | E37: Huarmaca | F37: 230.098 | G37: =COUNTIF(Bloque_Ecosistema!$B$9:$B$198,B37) | H37: Zona agrícola | I37: 1
A38: 30 | B38: 41 | C38: C1076-Q9592 | D38: Huancabamba | E38: Huarmaca | F38: 64.923 | G38: =COUNTIF(Bloque_Ecosistema!$B$9:$B$198,B38) | H38: Zona agrícola | I38: 1
A39: 31 | B39: 51 | C39: C1076-Q9593 | D39: Huancabamba | E39: Huarmaca | F39: 22.927 | G39: =COUNTIF(Bloque_Ecosistema!$B$9:$B$198,B39) | H39: Zona agrícola | I39: 0.8824 | J39: Matorral andino (12%)
A40: 32 | B40: 53 | C40: C1076-Q9592 | D40: Huancabamba | E40: Huarmaca | F40: 13.065 | G40: =COUNTIF(Bloque_Ecosistema!$B$9:$B$198,B40) | H40: Matorral andino | I40: 1
A41: 33 | B41: 69 | C41: C1076-Q9592 | D41: Huancabamba | E41: Huarmaca | F41: 19.425 | G41: =COUNTIF(Bloque_Ecosistema!$B$9:$B$198,B41) | H41: Matorral andino | I41: 0.9797 | J41: Zona agrícola (2%)
...

Sheet Bloque_Ecosistema
A1: AUTORIDAD NACIONAL DE INFRAESTRUCTURA - ANIN
A2: DIRECCIÓN DE INTERVENCIONES MULTISECTORIALES Y DE EMERGENCIA - DIME
A3: SUBDIRECCIÓN DE ESTUDIOS DE INVERSIÓN - SESDI
A4: ECOSISTEMAS POR BLOQUE DE INTERVENCIÓN V6 — DETALLE
A5: PROYECTO IN PIURA | CUI 2669244 | Cuenca Alta del Río Piura | UTM WGS 84 Zona 17S (EPSG:32717)
A6: Fuente: Ecosistemas: Mapa Nacional de Ecosistemas del Perú, MINAM 2018 (R.M. N.° 440-2018-MINAM): recorte a microcuencas, completado en M27B1 y M9B1 con el recorte a esos bloques. Bloques V6, ANIN-DIME-SESDI 2026 (sin 74 y 75)
A8: N.° | B8: Bloque | C8: Microcuenca | D8: Provincia | E8: Distrito | F8: Ecosistema | G8: Símbolo | H8: Área geométrica (ha) | I8: % del bloque | J8: Área del bloque, catálogo (ha) | K8: Área prorrateada (ha)
A9: 1 | B9: 27 | C9: C1096-Q9556 | D9: Ayabaca | E9: Frías | F9: Zona agrícola | G9: Agri | H9: 78.154 | I9: =H9/SUMIF($B$9:$B$198,B9,$H$9:$H$198) | J9: 78.154 | K9: =I9*J9
A10: 2 | B10: 3 | C10: C1096-Q9545 | D10: Ayabaca | E10: Frías | F10: Zona agrícola | G10: Agri | H10: 434.197 | I10: =H10/SUMIF($B$9:$B$198,B10,$H$9:$H$198) | J10: 459.295 | K10: =I10*J10
A11: 3 | B11: 3 | C11: C1096-Q9545 | D11: Ayabaca | E11: Frías | F11: Bosque estacionalmente seco de colina y montaña | G11: Bes-cm | H11: 25.097 | I11: =H11/SUMIF($B$9:$B$198,B11,$H$9:$H$198) | J11: 459.295 | K11: =I11*J11
A12: 4 | B12: 36 | C12: C1096-Q9547 | D12: Ayabaca | E12: Frías | F12: Zona agrícola | G12: Agri | H12: 24.843 | I12: =H12/SUMIF($B$9:$B$198,B12,$H$9:$H$198) | J12: 24.843 | K12: =I12*J12
A13: 5 | B13: 39 | C13: C1096-Q9564 | D13: Ayabaca | E13: Frías | F13: Matorral andino | G13: Ma | H13: 68.569 | I13: =H13/SUMIF($B$9:$B$198,B13,$H$9:$H$198) | J13: 68.569 | K13: =I13*J13
A14: 6 | B14: 56 | C14: C1096-Q9564 | D14: Ayabaca | E14: Frías | F14: Bosque relicto montano de vertiente occidental | G14: Br-mvoc | H14: 41.849 | I14: =H14/SUMIF($B$9:$B$198,B14,$H$9:$H$198) | J14: 77.666 | K14: =I14*J14
A15: 7 | B15: 56 | C15: C1096-Q9564 | D15: Ayabaca | E15: Frías | F15: Zona agrícola | G15: Agri | H15: 35.817 | I15: =H15/SUMIF($B$9:$B$198,B15,$H$9:$H$198) | J15: 77.666 | K15: =I15*J15
A16: 8 | B16: 6 | C16: C1096-Q9547 | D16: Ayabaca | E16: Frías | F16: Zona agrícola | G16: Agri | H16: 164.236 | I16: =H16/SUMIF($B$9:$B$198,B16,$H$9:$H$198) | J16: 168.411 | K16: =I16*J16
A17: 9 | B17: 6 | C17: C1096-Q9547 | D17: Ayabaca | E17: Frías | F17: Bosque estacionalmente seco de colina y montaña | G17: Bes-cm | H17: 4.175 | I17: =H17/SUMIF($B$9:$B$198,B17,$H$9:$H$198) | J17: 168.411 | K17: =I17*J17
A18: 10 | B18: M17B10 | C18: C1096-Q9556 | D18: Ayabaca | E18: Frías | F18: Zona agrícola | G18: Agri | H18: 43.318 | I18: =H18/SUMIF($B$9:$B$198,B18,$H$9:$H$198) | J18: 75.363 | K18: =I18*J18
A19: 11 | B19: M17B10 | C19: C1096-Q9556 | D19: Ayabaca | E19: Frías | F19: Bosque estacionalmente seco de colina y montaña | G19: Bes-cm | H19: 32.046 | I19: =H19/SUMIF($B$9:$B$198,B19,$H$9:$H$198) | J19: 75.363 | K19: =I19*J19
A20: 12 | B20: M17B5 | C20: C1096-Q9556 | D20: Ayabaca | E20: Frías | F20: Bosque estacionalmente seco de colina y montaña | G20: Bes-cm | H20: 52.459 | I20: =H20/SUMIF($B$9:$B$198,B20,$H$9:$H$198) | J20: 74.028 | K20: =I20*J20
... A111: 103 | B111: M6B2-3 | C111: C1077-Q9566 | D111: Morropón | E111: Buenos Aires | F111: Bosque estacionalmente seco de colina y montaña | G111: Bes-cm | H111: 160.671 | I111: =H111/SUMIF($B$9:$B$198,B111,$H$9:$H$198) | J111: 160.978 | K111: =I111*J111
A112: 104 | B112: M6B2-3 | C112: C1077-Q9566 | D112: Morropón | E112: Buenos Aires | F112: Sin información de ecosistema | H112: 0.307 | I112: =H112/SUMIF($B$9:$B$198,B112,$H$9:$H$198) | J112: 160.978 | K112: =I112*J112
A113: 105 | B113: 57 | C113: C1086-Q9576 | D113: Morropón | E113: Chalaco | F113: Matorral andino | G113: Ma | H113: 21.261 | I113: =H113/SUMIF($B$9:$B$198,B113,$H$9:$H$198) | J113: 25.668 | K113: =I113*J113
A114: 106 | B114: 57 | C114: C1086-Q9576 | D114: Morropón | E114: Chalaco | F114: Zona agrícola | G114: Agri | H114: 4.407 | I114: =H114/SUMIF($B$9:$B$198,B114,$H$9:$H$198) | J114: 25.668 | K114: =I114*J114
A115: 107 | B115: 59 | C115: C1086-Q9570 | D115: Morropón | E115: Chalaco | F115: Bosque relicto montano de vertiente occidental | G115: Br-mvoc | H115: 8.127 | I115: =H115/SUMIF($B$9:$B$198,B115,$H$9:$H$198) | J115: 13.554 | K115: =I115*J115
A116: 108 | B116: 59 | C116: C1086-Q9570 | D116: Morropón | E116: Chalaco | F116: Zona agrícola | G116: Agri | H116: 5.427 | I116: =H116/SUMIF($B$9:$B$198,B116,$H$9:$H$198) | J116: 13.554 | K116: =I116*J116
A117: 109 | B117: 2 | C117: C1096-Q9558 | D117: Morropón | E117: Chulucanas | F117: Bosque estacionalmente seco de colina y montaña | G117: Bes-cm | H117: 330.599 | I117: =H117/SUMIF($B$9:$B$198,B117,$H$9:$H$198) | J117: 330.599 | K117: =I117*J117
A118: 110 | B118: 22 | C118: C1096-Q9556 | D118: Morropón | E118: Chulucanas | F118: Bosque estacionalmente seco de colina y montaña | G118: Bes-cm | H118: 79.33 | I118: =H118/SUMIF($B$9:$B$198,B118,$H$9:$H$198) | J118: 79.33 | K118: =I118*J118
A119: 111 | B119: M10B4 | C119: C1096-Q9547 | D119: Morropón | E119: Chulucanas | F119: Bosque estacionalmente seco de colina y montaña | G119: Bes-cm | H119: 68.458 | I119: =H119/SUMIF($B$9:$B$198,B119,$H$9:$H$198) | J119: 68.887 | K119: =I119*J119
A120: 112 | B120: M10B4 | C120: C1096-Q9547 | D120: Morropón | E120: Chulucanas | F120: Sin información de ecosistema | H120: 0.429 | I120: =H120/SUMIF($B$9:$B$198,B120,$H$9:$H$198) | J120: 68.887 | K120: =I120*J120
A121: 113 | B121: M17B1 | C121: C1096-Q9556 | D121: Morropón | E121: Chulucanas | F121: Bosque estacionalmente seco de colina y montaña | G121: Bes-cm | H121: 42.449 | I121: =H121/SUMIF($B$9:$B$198,B121,$H$9:$H$198) | J121: 42.449 | K121: =I121*J121
A122: 114 | B122: M17B4 | C122: C1096-Q9556 | D122: Morropón | E122: Chulucanas | F122: Bosque estacionalmente seco de colina y montaña | G122: Bes-cm | H122: 124.709 | I122: =H122/SUMIF($B$9:$B$198,B122,$H$9:$H$198) | J122: 124.709 | K122: =I122*J122
A123: 115 | B123: M27B1 | C123: C1096-Q9557 | D123: Morropón | E123: Chulucanas | F123: Bosque estacionalmente seco de colina y montaña | G123: Bes-cm | H123: 443.83 | I123: =H123/SUMIF($B$9:$B$198,B123,$H$9:$H$198) | J123: 448.804 | K123: =I123*J123
A124: 116 | B124: M27B1 | C124: C1096-Q9557 | D124: Morropón | E124: Chulucanas | F124: Zona agrícola | G124: Agri | H124: 4.974 | I124: =H124/SUMIF($B$9:$B$198,B124,$H$9:$H$198) | J124: 448.804 | K124: =I124*J124
A125: 117 | B125: M9B1 | C125: C1096-Q9545 | D125: Morropón | E125: Chulucanas | F125: Bosque estacionalmente seco de colina y montaña | G125: Bes-cm | H125: 355.364 | I125: =H125/SUMIF($B$9:$B$198,B125,$H$9:$H$198) | J125: 355.364 | K125: =I125*J125
A126: 118 | B126: M19B2 | C126: C1086-Q9570 | D126: Morropón | E126: Morropón | F126: Bosque estacionalmente seco de colina y montaña | G126: Bes-cm | H126: 74.372 | I126: =H126/SUMIF($B$9:$B$198,B126,$H$9:$H$198) | J126: 74.372 | K126: =I126*J126
A127: 119 | B127: M32B3 | C127: C1086-Q9569 | D127: Morropón | E127: Morropón | F127: Bosque estacionalmente seco de colina y montaña | G127: Bes-cm | H127: 50.972 | I127: =H127/SUMIF($B$9:$B$198,B127,$H$9:$H$198) | J127: 50.972 | K127: =I127*J127
A128: 120 | B128: M18B3 | C128: C1077-Q9579 | D128: Morropón | E128: Salitral | F128: Bosque estacionalmente seco de colina y montaña | G128: Bes-cm | H128: 373.699 | I128: =H128/SUMIF($B$9:$B$198,B128,$H$9:$H$198) | J128: 373.807 | K128: =I128*J128
A129: 121 | B129: M18B3 | C129: C1077-Q9579 | D129: Morropón | E129: Salitral | F129: Zona agrícola | G129: Agri | H129: 0.108 | I129: =H129/SUMIF($B$9:$B$198,B129,$H$9:$H$198) | J129: 373.807 | K129: =I129*J129
A130: 122 | B130: M2B1 | C130: C1076-Q9584 | D130: Morropón | E130: Salitral | F130: Bosque estacionalmente seco de colina y montaña | G130: Bes-cm | H130: 81.795 | I130: =H130/SUMIF($B$9:$B$198,B130,$H$9:$H$198) | J130: 81.795 | K130: =I130*J130
A131: 123 | B131: M2B5 | C131: C1076-Q9584 | D131: Morropón | E131: Salitral | F131: Bosque estacionalmente seco de colina y montaña | G131: Bes-cm | H131: 30.37 | I131: =H131/SUMIF($B$9:$B$198,B131,$H$9:$H$198) | J131: 30.909 | K131: =I131*J131
...

Sheet Notas
A1: NOTAS Y CONTROLES
A2: Capa de ecosistemas: Mapa Nacional de Ecosistemas del Perú, MINAM 2018 (R.M. N.° 440-2018-MINAM): recorte a microcuencas, completado en M27B1 y M9B1 con el recorte a esos bloques.
A3: Los ecosistemas se recortaron al ámbito de 15 distritos (INEI, capa simplificada) y se reproyectaron a UTM WGS84 Zona 17S (EPSG:32717). Áreas calculadas en UTM.
A4: Bloque_Ecosistema: intersección de cada bloque V6 con los ecosistemas. «% del bloque» = área geométrica del tramo / área geométrica del bloque (fórmula SUMIF).
A5: «Área prorrateada» = % del bloque × área del bloque en el catálogo V6, para que el total coincida con 12,270.235 ha. Los resúmenes usan esta área.
A6: «Sin información de ecosistema»: parte del bloque que la capa de ecosistemas no cubre (si aparece, revise la capa).
A7: % del ecosistema intervenido = área del ecosistema en bloques / área del ecosistema en el ámbito (15 distritos).
A8: Se excluyen los bloques retirados 74 y 75 (ver README_LIBERACION_AREAS.md).
A9: Escala: el Mapa Nacional de Ecosistemas es de escala regional; el ecosistema de cada bloque debe confirmarse en campo (F-DT-03, «Tipo de ecosistema (UP)»).
