Workbook

Sheet RESUMEN
A1: AUTORIDAD NACIONAL DE INFRAESTRUCTURA - ANIN
A2: DIRECCIÓN DE INTERVENCIONES MULTISECTORIALES Y DE EMERGENCIA - DIME
A3: SUBDIRECCIÓN DE ESTUDIOS DE INVERSIÓN
A4: PROYECTO IN PIURA – CUI 2669244 · Motor de costos paramétrico – RESUMEN (versión piloto v1)
A5: Generado el 18-oct-2026. Todas las cifras se recalculan desde PARAMETROS, PAQUETES y BLOQUES. Celdas amarillas = supuestos por calibrar.
A7: Indicador | B7: Piloto (5 bloques) | C7: Cartera (117 bloques) | D7: Unidad
A8: Bloques | B8: =COUNTIF(B_PIL,"Sí") -> 5 | C8: =COUNTA(B_ID) -> 117 | D8: n°
A9: Superficie de bloques | B9: =C_HA_P -> 538.323 | C9: =C_HA_T -> 12270.235 | D9: ha
A10: Plantación activa R1 (MSAVI DN 1–2) | B10: =C_R1_P -> 216.151 | C10: =C_R1_T -> 5503.444 | D10: ha
A11: Enriquecimiento R2 (MSAVI DN 3) | B11: =C_R2_P -> 94.297 | C11: =C_R2_T -> 2838.422 | D11: ha
A12: Plantas a instalar | B12: =C_PL_P -> 172906.33 | C12: =C_PL_T -> 4508650.6 | D12: und
A13: Zanjas de infiltración | B13: =C_KZ_P -> 871.50623 | C13: =C_KZ_T -> 17971.711 | D13: km
A14: Terrazas de formación lenta | B14: =C_KT_P -> 28.272113 | C14: =C_KT_T -> 705.49002 | D14: km
A15: Cerco perimétrico | B15: =C_CE_P -> 26234.8 | C15: =C_CE_T -> 577845.6 | D15: m
A16: Cárcavas (diques) | B16: =C_KC_P -> 0 | C16: =C_KC_T -> 0 | D16: km
A17: Costo directo | B17: =C_CD_P -> 13344299 | C17: =C_CD_T -> 2.9810789e+08 | D17: S/
A18: Inversión total (CD + GG + sup. + ET) | B18: =C_INV_P -> 15356266 | C18: =C_INV_T -> 3.4305467e+08 | D18: S/
A19: · infraestructura verde | B19: =C_VER_P -> 2788611.8 | C19: =C_VER_T -> 71180513 | D19: S/
A20: · infraestructura marrón | B20: =C_MAR_P -> 12567654 | C20: =C_MAR_T -> 2.7187415e+08 | D20: S/
A21: Inversión por ha de bloque | B21: =C_INV_P/C_HA_P -> 28526.119 | C21: =C_INV_T/C_HA_T -> 27958.28 | D21: S/ / ha
A22: O&M – primer año de operación | B22: =OYM!K21 -> 1911221.6 | C22: =OYM!J21 -> 46347297 | D22: S/ / año
A23: O&M – 15 años (sin descontar) | B23: =SUM(FLUJO!C26:V26) -> 12826725 | C23: =SUM(FLUJO!C13:V13) -> 2.8167704e+08 | D23: S/
A24: Inversión + O&M 15 años (sin descontar) | B24: =B18+B23 -> 28182991 | C24: =C18+C23 -> 6.2473171e+08 | D24: S/
A25: Referencia: techo del proyecto (incluye preinversión y ET) | C25: =P_TECHO -> 372442809 | D25: S/
A26: Cartera / techo | C26: =C24/P_TECHO -> 1.6773896 | D26: %
A27: VAC social (TSD 8 %) | B27: =FLUJO!B54 -> 9511139.7 | C27: =FLUJO!B47 -> 2.1364061e+08 | D27: S/
A28: Costo-efectividad (VAC social / ha plantada) | B28: =FLUJO!B58 -> 30636.821 | C28: =FLUJO!B51 -> 25610.65 | D28: S/ / ha
A29: VANS | B29: =FLUJO!B56 -> Pendiente de beneficios | C29: =FLUJO!B49 -> Pendiente de beneficios | D29: S/
A31: Bloque piloto | B31: Tipología | C31: Área (ha) | D31: R1 + R2 (ha) | E31: Plantas | F31: Zanjas / terrazas (km) | G31: Inversión (S/) | H31: S/ por ha | I31: Dist. media acarreo (m) | J31: Grupo · degradación
A32: 21 | B32: =INDEX(CALCULO!$B$7:$B$123,MATCH("21",CALCULO!$A$7:$A$123,0)) -> T6 | C32: =INDEX(CALCULO!$D$7:$D$123,MATCH("21",CALCULO!$A$7:$A$123,0)) -> 84.227 | D32: =INDEX(CALCULO!$E$7:$E$123,MATCH("21",CALCULO!$A$7:$A$123,0))+INDEX(CALCULO!$F$7:$F$123,MATCH("21",CALCULO!$A$7:$A$123,0)) -> 4.357 | E32: =INDEX(CALCULO!$J$7:$J$123,MATCH("21",CALCULO!$A$7:$A$123,0)) -> 1419.275 | F32: =INDEX(CALCULO!$K$7:$K$123,MATCH("21",CALCULO!$A$7:$A$123,0))+INDEX(CALCULO!$L$7:$L$123,MATCH("21",CALCULO!$A$7:$A$123,0)) -> 5.1768207 | G32: =INDEX(CALCULO!$AA$7:$AA$123,MATCH("21",CALCULO!$A$7:$A$123,0)) -> 646128.48 | H32: =INDEX(CALCULO!$AB$7:$AB$123,MATCH("21",CALCULO!$A$7:$A$123,0)) -> 7671.275 | I32: =INDEX(BLOQUES!$AB$7:$AB$123,MATCH("21",CALCULO!$A$7:$A$123,0)) -> 579 | J32: =INDEX(BLOQUES!$AG$7:$AG$123,MATCH("21",CALCULO!$A$7:$A$123,0))&" · "&INDEX(BLOQUES!$AH$7:$AH$123,MATCH("21",CALCULO!$A$7:$A$123,0)) -> MOSAICO · Moderada
A33: 66 | B33: =INDEX(CALCULO!$B$7:$B$123,MATCH("66",CALCULO!$A$7:$A$123,0)) -> T6 | C33: =INDEX(CALCULO!$D$7:$D$123,MATCH("66",CALCULO!$A$7:$A$123,0)) -> 102.335 | D33: =INDEX(CALCULO!$E$7:$E$123,MATCH("66",CALCULO!$A$7:$A$123,0))+INDEX(CALCULO!$F$7:$F$123,MATCH("66",CALCULO!$A$7:$A$123,0)) -> 9.047 | E33: =INDEX(CALCULO!$J$7:$J$123,MATCH("66",CALCULO!$A$7:$A$123,0)) -> 3119.025 | F33: =INDEX(CALCULO!$K$7:$K$123,MATCH("66",CALCULO!$A$7:$A$123,0))+INDEX(CALCULO!$L$7:$L$123,MATCH("66",CALCULO!$A$7:$A$123,0)) -> 10.759243 | G33: =INDEX(CALCULO!$AA$7:$AA$123,MATCH("66",CALCULO!$A$7:$A$123,0)) -> 1284667.1 | H33: =INDEX(CALCULO!$AB$7:$AB$123,MATCH("66",CALCULO!$A$7:$A$123,0)) -> 12553.546 | I33: =INDEX(BLOQUES!$AB$7:$AB$123,MATCH("66",CALCULO!$A$7:$A$123,0)) -> 663 | J33: =INDEX(BLOQUES!$AG$7:$AG$123,MATCH("66",CALCULO!$A$7:$A$123,0))&" · "&INDEX(BLOQUES!$AH$7:$AH$123,MATCH("66",CALCULO!$A$7:$A$123,0)) -> MOSAICO · Moderada
A34: 73 | B34: =INDEX(CALCULO!$B$7:$B$123,MATCH("73",CALCULO!$A$7:$A$123,0)) -> T6 | C34: =INDEX(CALCULO!$D$7:$D$123,MATCH("73",CALCULO!$A$7:$A$123,0)) -> 54.29 | D34: =INDEX(CALCULO!$E$7:$E$123,MATCH("73",CALCULO!$A$7:$A$123,0))+INDEX(CALCULO!$F$7:$F$123,MATCH("73",CALCULO!$A$7:$A$123,0)) -> 10.28 | E34: =INDEX(CALCULO!$J$7:$J$123,MATCH("73",CALCULO!$A$7:$A$123,0)) -> 3653.65 | F34: =INDEX(CALCULO!$K$7:$K$123,MATCH("73",CALCULO!$A$7:$A$123,0))+INDEX(CALCULO!$L$7:$L$123,MATCH("73",CALCULO!$A$7:$A$123,0)) -> 12.336049 | G34: =INDEX(CALCULO!$AA$7:$AA$123,MATCH("73",CALCULO!$A$7:$A$123,0)) -> 1408810.3 | H34: =INDEX(CALCULO!$AB$7:$AB$123,MATCH("73",CALCULO!$A$7:$A$123,0)) -> 25949.72 | I34: =INDEX(BLOQUES!$AB$7:$AB$123,MATCH("73",CALCULO!$A$7:$A$123,0)) -> 598 | J34: =INDEX(BLOQUES!$AG$7:$AG$123,MATCH("73",CALCULO!$A$7:$A$123,0))&" · "&INDEX(BLOQUES!$AH$7:$AH$123,MATCH("73",CALCULO!$A$7:$A$123,0)) -> MOSAICO · Moderada
A35: 31 | B35: =INDEX(CALCULO!$B$7:$B$123,MATCH("31",CALCULO!$A$7:$A$123,0)) -> T3 | C35: =INDEX(CALCULO!$D$7:$D$123,MATCH("31",CALCULO!$A$7:$A$123,0)) -> 47.581 | D35: =INDEX(CALCULO!$E$7:$E$123,MATCH("31",CALCULO!$A$7:$A$123,0))+INDEX(CALCULO!$F$7:$F$123,MATCH("31",CALCULO!$A$7:$A$123,0)) -> 37.311 | E35: =INDEX(CALCULO!$J$7:$J$123,MATCH("31",CALCULO!$A$7:$A$123,0)) -> 17665.535 | F35: =INDEX(CALCULO!$K$7:$K$123,MATCH("31",CALCULO!$A$7:$A$123,0))+INDEX(CALCULO!$L$7:$L$123,MATCH("31",CALCULO!$A$7:$A$123,0)) -> 129.54856 | G35: =INDEX(CALCULO!$AA$7:$AA$123,MATCH("31",CALCULO!$A$7:$A$123,0)) -> 1799213.7 | H35: =INDEX(CALCULO!$AB$7:$AB$123,MATCH("31",CALCULO!$A$7:$A$123,0)) -> 37813.701 | I35: =INDEX(BLOQUES!$AB$7:$AB$123,MATCH("31",CALCULO!$A$7:$A$123,0)) -> 774 | J35: =INDEX(BLOQUES!$AG$7:$AG$123,MATCH("31",CALCULO!$A$7:$A$123,0))&" · "&INDEX(BLOQUES!$AH$7:$AH$123,MATCH("31",CALCULO!$A$7:$A$123,0)) -> ANDINO · Alta
A36: M6B10 | B36: =INDEX(CALCULO!$B$7:$B$123,MATCH("M6B10",CALCULO!$A$7:$A$123,0)) -> T1 | C36: =INDEX(CALCULO!$D$7:$D$123,MATCH("M6B10",CALCULO!$A$7:$A$123,0)) -> 249.89 | D36: =INDEX(CALCULO!$E$7:$E$123,MATCH("M6B10",CALCULO!$A$7:$A$123,0))+INDEX(CALCULO!$F$7:$F$123,MATCH("M6B10",CALCULO!$A$7:$A$123,0)) -> 249.453 | E36: =INDEX(CALCULO!$J$7:$J$123,MATCH("M6B10",CALCULO!$A$7:$A$123,0)) -> 147048.85 | F36: =INDEX(CALCULO!$K$7:$K$123,MATCH("M6B10",CALCULO!$A$7:$A$123,0))+INDEX(CALCULO!$L$7:$L$123,MATCH("M6B10",CALCULO!$A$7:$A$123,0)) -> 741.95766 | G36: =INDEX(CALCULO!$AA$7:$AA$123,MATCH("M6B10",CALCULO!$A$7:$A$123,0)) -> 10217446 | H36: =INDEX(CALCULO!$AB$7:$AB$123,MATCH("M6B10",CALCULO!$A$7:$A$123,0)) -> 40887.775 | I36: =INDEX(BLOQUES!$AB$7:$AB$123,MATCH("M6B10",CALCULO!$A$7:$A$123,0)) -> 1200 | J36: =INDEX(BLOQUES!$AG$7:$AG$123,MATCH("M6B10",CALCULO!$A$7:$A$123,0))&" · "&INDEX(BLOQUES!$AH$7:$AH$123,MATCH("M6B10",CALCULO!$A$7:$A$123,0)) -> BES · Alta
A38: Tipología | B38: Descripción | C38: N° bloques | D38: Área (ha) | E38: Inversión (S/) | F38: S/ por ha
A39: T1 | B39: =INDEX(PAQUETES!$C$7:$C$12,1)&" · "&INDEX(PAQUETES!$D$7:$D$12,1) -> Bosque estacionalmente seco de colina y montaña · Alta | C39: =COUNTIF(B_TIP,"T1") -> 47 | D39: =SUMIFS(B_AREA,B_TIP,"T1") -> 7645.154 | E39: =SUMIFS(CALCULO!$AA$7:$AA$123,CALCULO!$B$7:$B$123,"T1") -> 2.4559308e+08 | F39: =IF(D39=0,0,E39/D39) -> 32124.02
A40: T2 | B40: =INDEX(PAQUETES!$C$7:$C$12,2)&" · "&INDEX(PAQUETES!$D$7:$D$12,2) -> Bosque estacionalmente seco de colina y montaña · Moderada | C40: =COUNTIF(B_TIP,"T2") -> 7 | D40: =SUMIFS(B_AREA,B_TIP,"T2") -> 596.926 | E40: =SUMIFS(CALCULO!$AA$7:$AA$123,CALCULO!$B$7:$B$123,"T2") -> 6054815.5 | F40: =IF(D40=0,0,E40/D40) -> 10143.327
A41: T3 | B41: =INDEX(PAQUETES!$C$7:$C$12,3)&" · "&INDEX(PAQUETES!$D$7:$D$12,3) -> Andino (matorral andino + páramo + relicto montano) · Alta | C41: =COUNTIF(B_TIP,"T3") -> 3 | D41: =SUMIFS(B_AREA,B_TIP,"T3") -> 95.24 | E41: =SUMIFS(CALCULO!$AA$7:$AA$123,CALCULO!$B$7:$B$123,"T3") -> 3188724.4 | F41: =IF(D41=0,0,E41/D41) -> 33480.936
A42: T4 | B42: =INDEX(PAQUETES!$C$7:$C$12,4)&" · "&INDEX(PAQUETES!$D$7:$D$12,4) -> Andino (matorral andino + páramo + relicto montano) · Moderada | C42: =COUNTIF(B_TIP,"T4") -> 20 | D42: =SUMIFS(B_AREA,B_TIP,"T4") -> 1000.648 | E42: =SUMIFS(CALCULO!$AA$7:$AA$123,CALCULO!$B$7:$B$123,"T4") -> 8146657.6 | F42: =IF(D42=0,0,E42/D42) -> 8141.382
A43: T5 | B43: =INDEX(PAQUETES!$C$7:$C$12,5)&" · "&INDEX(PAQUETES!$D$7:$D$12,5) -> Mosaico agroforestal (zona agrícola MINAM) · Alta | C43: =COUNTIF(B_TIP,"T5") -> 3 | D43: =SUMIFS(B_AREA,B_TIP,"T5") -> 106.884 | E43: =SUMIFS(CALCULO!$AA$7:$AA$123,CALCULO!$B$7:$B$123,"T5") -> 8982524.4 | F43: =IF(D43=0,0,E43/D43) -> 84039.934
...

Sheet LEEME
A1: AUTORIDAD NACIONAL DE INFRAESTRUCTURA - ANIN
A2: DIRECCIÓN DE INTERVENCIONES MULTISECTORIALES Y DE EMERGENCIA - DIME
A3: SUBDIRECCIÓN DE ESTUDIOS DE INVERSIÓN
A4: PROYECTO IN PIURA – CUI 2669244 · Guía de uso y fuentes
A5: Motor de costos paramétrico para el Estudio de Perfil (Invierte.pe).
A7: PROPÓSITO | B7: Pasar de la tipología de cada bloque a metas físicas, costos de inversión, O&M y flujos a precios privados y sociales con fórmulas vivas y trazables.
A8: CADENA DE CÁLCULO | B8: BLOQUES (SIG) → tipología (grupo × degradación) → PAQUETES (coeficientes) → CALCULO (metas y costos) ← CU_COMP ← PARTIDAS ← APU_BASE (ANIN actualizado) → OYM → FLUJO → RESUMEN.
A9: CONVENCIONES | B9: Texto azul sobre fondo amarillo = supuesto o dato editable. Texto negro = fórmula. Verde = vínculo a otra hoja. "POR DEFINIR / POR DETERMINAR" = dato faltante; no se inventan valores.
A10: TIPOLOGÍAS | B10: Grupo dominante por superficie: BES, ANDINO (matorral andino + páramo + relicto montano) o MOSAICO (zona agrícola MINAM). Degradación ALTA si ≥ 50 % del bloque está bajo el umbral MSAVI 0.4976 (DN 1–3).
A11: MODALIDADES | B11: R1 = plantación plena (MSAVI DN 1–2); R2 = enriquecimiento (DN 3); C = protección (DN 4–5, cerco). Marrón: zanjas (BES/ANDINO) o terrazas (MOSAICO) en celdas R1/R2 con PMM alto o muy alto (DN 4–5).
A12: PRECIOS | B12: Base ANIN (S10, 10/12/2020, Lima). MO: jornal rural S/ 100/día (peón); capataz, operario y oficial mantienen la relación ANIN. Materiales, equipos y servicios: factor IPC Lima dic-2020 → set-2026 (BCRP PN01272PM). Plantón: producción en vivero propio (ficha ANIN algarrobo).
A13: FLETE | B13: Rural: metodología Sierra Azul (40 kg por viaje, 5/8 km/h, 8 min, 95 %) con distancia media de acarreo SIG a vía motorizable (vecinal MTC + trocha carrozable MTC). Terrestre: solo insumos; el transporte de plantones ≤ 20 km está en el APU 04.01.02.
A14: EVALUACIÓN | B14: TSD 8 %, FC MO no calificada Sierra 0.42, MO calificada 0.79, bienes ÷ 1.18, divisa 1.08 y carbono US$ 30/tCO2e (MEF, Anexo 11, act. 27-03-2024). Costo-beneficio: beneficios POR DETERMINAR; mientras tanto se reporta costo-efectividad.
A15: FUENTES SIG | B15: Relación de bloques V6 – versión normalizada (Bloques_V7_Normalizado.xlsx, corte 09/10/2026): 117 bloques (M6B2 en 3 partes), 12 270.235 ha; geometría del KMZ B6 (se excluyen los polígonos 74 y 75, ausentes en la relación normalizada). MSAVI vectorizado V6 (38 988 polígonos). Peligro por movimientos en masa (239 462 polígonos, DN 1–5). Intersección Bloques V6 × ecosistemas MINAM. Red vial vecinal MTC (dic-2018) y trochas MTC (2026).
A16: FUENTES DE COSTOS | B16: ANIN – Fichas de infraestructura natural: reforestación con producción de plantones, zanjas de infiltración, terrazas de formación lenta, control de cárcavas (ANEXOS 05–11). Fondo Sierra Azul – Chacaya (planilla de metrados y flete) y Marachanca (calendario valorizado).
A17: VALIDACIÓN | B17: APU ANIN: Σ parciales = CU en 126 partidas y 19 subpartidas; presupuestos reconstruidos = CD reportado (reforestación 8 254 042.50; zanjas 4 977 678.14; terrazas 14 076 518.93; cárcavas 9 954 031.83). Control en PARTIDAS!G (CU 2020 recalculado).
A18: LIMITACIONES v1 | B18: Coeficientes de densidad, espaciamiento de zanjas/terrazas, cerco y años de O&M son supuestos referenciales a calibrar con el piloto. La distancia de acarreo es en línea recta (factor de sinuosidad 1.0). No incluye viveros permanentes/temporales como infraestructura separada (el costo del plantón ya amortiza el vivero ANIN), gobernanza ni gestión del proyecto.

Sheet PARAMETROS
A1: AUTORIDAD NACIONAL DE INFRAESTRUCTURA - ANIN
A2: DIRECCIÓN DE INTERVENCIONES MULTISECTORIALES Y DE EMERGENCIA - DIME
A3: SUBDIRECCIÓN DE ESTUDIOS DE INVERSIÓN
A4: PROYECTO IN PIURA – CUI 2669244 · Parámetros globales del motor
A5: Celdas en azul con fondo amarillo = supuestos editables. Fuente indicada en cada fila. Precios base ANIN: 10/12/2020 (Lima).
A6: Nombre | B6: Parámetro | C6: Valor | D6: Unidad | E6: Fuente / nota | G6: Categoría MO | H6: hh ANIN 2020 (S/) | I6: Ratio vs peón | J6: hh actualizado (S/)
A7: MANO DE OBRA Y PRECIOS | G7: CAPATAZ | H7: 25.81 | I7: =H7/$H$10 -> 1.5381406 | J7: =P_HH_PEON*I7 -> 19.226758
A8: P_JORNAL | B8: Jornal diario de mano de obra rural – peón (Administración Directa) | C8: 100 | D8: S/ / día | E8: Fijado por el Ing. H. S. Cahuas Miller (18-oct-2026): S/ 100 por jornal rural (reemplaza S/ 120). | G8: OPERARIO | H8: 23.46 | I8: =H8/$H$10 -> 1.398093 | J8: =P_HH_PEON*I8 -> 17.476162
A9: P_HORAS | B9: Horas efectivas por jornada | C9: 8 | D9: h / día | E9: Jornada estándar de 8 h (supuesto de cálculo de hh). | G9: OFICIAL | H9: 18.56 | I9: =H9/$H$10 -> 1.1060787 | J9: =P_HH_PEON*I9 -> 13.825983
A10: P_HH_PEON | B10: Costo hora-hombre peón | C10: =P_JORNAL/P_HORAS -> 12.5 | D10: S/ / hh | E10: Cálculo. | G10: PEON | H10: 16.78 | I10: =H10/$H$10 -> 1 | J10: =P_HH_PEON*I10 -> 12.5
A11: P_FACT_IPC | B11: Factor de actualización dic-2020 → set-2026 (materiales, equipos, servicios) | C11: =PRODUCT(PARAMETROS!$I$15:$I$20) -> 1.2862958 | D11: factor | E11: IPC Lima Metropolitana, var. % acumulada anual (BCRP, serie PN01272PM). Tabla en G13:I20. | G11: Supuesto: se mantiene la estructura salarial relativa de ANIN 2020; el peón se fija en S/ 100/día (jornal rural).
A12: P_TC | B12: Tipo de cambio referencial | C12: 3.4 | D12: S/ / US$ | E12: Estándar del proyecto IN Piura.
A13: P_IGV | B13: IGV | C13: 0.18 | D13: % | E13: Tasa vigente.
A14: PLANTACIÓN Y MANEJO (EJECUCIÓN) | G14: Año | H14: IPC Lima – var. % acumulada a diciembre | I14: Factor
A15: P_RECALCE | B15: Recalce (reposición por mortalidad) en ejecución | C15: 0.1 | D15: % de plantas | E15: ANIN reforestación: 65 000 recalces / 650 000 plantas. | G15: 2021 | H15: 6.4303872 | I15: =1+H15/100 -> 1.0643039
A16: P_RIEGOS | B16: Riegos manuales de establecimiento por planta | C16: 3 | D16: riegos | E16: ANIN reforestación: 1 950 000 riegos / 650 000 plantas. | G16: 2022 | H16: 8.459162 | I16: =1+H16/100 -> 1.0845916
A17: P_DESHIERBES | B17: Deshierbes manuales por ha en ejecución | C17: 4 | D17: veces | E17: ANIN reforestación: 4 000 ha-deshierbe / 1 000 ha. | G17: 2023 | H17: 3.2373826 | I17: =1+H17/100 -> 1.0323738
A18: P_PESO_PLANTON | B18: Peso de plantón en bolsa | C18: 1.5 | D18: kg / und | E18: Sierra Azul – Flete Chacaya (reforestación). | G18: 2024 | H18: 1.9663027 | I18: =1+H18/100 -> 1.019663
A19: P_PESO_INS | B19: Insumos de plantación por planta (humus, guano, fosfato, hidrogel) | C19: 0.17 | D19: kg / planta | E19: APU ANIN 04.01.04: 0.10 + 0.03 + 0.02 + 0.02 kg. | G19: 2025 | H19: 1.5087997 | I19: =1+H19/100 -> 1.015088
A20: FLETE (metodología Sierra Azul) | G20: 2026 (ene–set) | H20: 4.2825468 | I20: =1+H20/100 -> 1.0428255
A21: P_CARGA | B21: Carga por viaje en flete rural (a pie / acémila) | C21: 40 | D21: kg / viaje | E21: Sierra Azul – Flete Chacaya. | G21: Fuente: BCRPData, serie PN01272PM (consulta 18-oct-2026).
A22: P_VIDA | B22: Velocidad de ida cargado | C22: 5 | D22: km / h | E22: Sierra Azul – Flete Chacaya.
A23: P_VVUELTA | B23: Velocidad de vuelta | C23: 8 | D23: km / h | E23: Sierra Azul – Flete Chacaya.
A24: P_TCD | B24: Tiempo de carguío + descarga | C24: 8 | D24: min / viaje | E24: Sierra Azul – Flete Chacaya (4 + 4 min).
A25: P_EFIC | B25: Eficiencia de la jornada | C25: 0.95 | D25: % | E25: Sierra Azul – Flete Chacaya.
A26: P_SINUOS | B26: Factor de sinuosidad del acarreo (distancia SIG en línea recta) | C26: 1 | D26: factor | E26: SUPUESTO: 1.0 = sin ajuste. Calibrar con tracks GPS de campo.
A27: P_FT_VIAJE | B27: Flete terrestre por viaje de volquete | C27: 2500 | D27: S/ / viaje | E27: Sierra Azul – Flete Chacaya (referencia; ruta corta). Plantones: transporte incluido en APU 04.01.02 (≤ 20 km).
A28: P_FT_CAP | B28: Capacidad efectiva del volquete | C28: 15000 | D28: kg / viaje | E28: Sierra Azul – Flete Chacaya.
A29: P_FT_KG | B29: Flete terrestre por kg de insumo | C29: =P_FT_VIAJE/P_FT_CAP*P_FACT_IPC -> 0.21438264 | D29: S/ / kg | E29: Cálculo (actualizado con IPC).
A30: COSTOS INDIRECTOS (sobre costo directo)
A31: P_GG | B31: Gastos generales y obras provisionales | C31: =PARAMETROS!$C$70/PARAMETROS!$C$69 -> 0.15077351 | D31: % del CD | E31: Referencia ANIN reforestación: GG 1 244 490.96 / CD 8 254 042.50. DEFINIR para Administración Directa.
A32: P_SUP | B32: Supervisión de la ejecución | C32: 0 | D32: % del CD | E32: POR DEFINIR (0 % mientras no se fije).
A33: P_ET | B33: Expediente técnico / estudios definitivos | C33: 0 | D33: % del CD | E33: POR DEFINIR (0 % mientras no se fije).
A34: TIPOLOGÍAS
A35: P_UMBRAL | B35: Umbral MSAVI de degradación (referencial) | C35: 0.4976 | D35: MSAVI | E35: Estándar del proyecto (20-sep-2026). DN 1–3 < 0.4976 ≤ DN 4–5.
A36: P_CORTE | B36: Corte de degradación ALTA (% del bloque bajo el umbral) | C36: 0.5 | D36: % | E36: Propuesto y aceptado en sesión (18-oct-2026); calibrable.
A37: P_PMM_MARRON | B37: Clase PMM mínima que activa el paquete marrón | C37: 4 | D37: DN | E37: Decisión de sesión: PMM alto o muy alto (DN 4–5) sobre MSAVI DN 1–3.
A38: EVALUACIÓN SOCIAL (Anexo 11 Invierte.pe, act. 27-03-2024)
A39: P_TSD | B39: Tasa social de descuento (años 1–20) | C39: 0.08 | D39: % | E39: MEF, Anexo 11 – Parámetros de evaluación social. TSD-LP (5.5 %) solo desde el año 21.
A40: P_FC_MONC | B40: Factor de corrección MO no calificada – Sierra | C40: 0.42 | D40: factor | E40: MEF, Anexo 11, Tabla 03.
...

Sheet APU_BASE
A1: AUTORIDAD NACIONAL DE INFRAESTRUCTURA - ANIN
A2: DIRECCIÓN DE INTERVENCIONES MULTISECTORIALES Y DE EMERGENCIA - DIME
A3: SUBDIRECCIÓN DE ESTUDIOS DE INVERSIÓN
A4: PROYECTO IN PIURA – CUI 2669244 · Análisis de precios unitarios – base ANIN y actualización
A5: Fuente: ANIN, Fichas de proyectos de infraestructura natural (S10, presupuesto 10/12/2020, Lima). Columnas P–R recalculan con PARAMETROS (jornal rural S/ 100 y factor IPC).
A6: Clave | B6: Tipo | C6: Item | D6: Partida | E6: Und partida | F6: CU 2020 ANIN | G6: Sección | H6: Código | I6: Recurso | J6: Und | K6: Cuadrilla | L6: Cantidad | M6: Precio 2020 | N6: Parcial 2020 | O6: Cat. MO | P6: Precio actualizado | Q6: Parcial actualizado | R6: Base MO (para %mo)
A7: CARCAVAS|01.01 | B7: CARCAVAS | C7: 01.01 | D7: MOVILIZACION Y DESMOVILIZACION PARA CARCAVAS | E7: m3 | F7: 60135.17 | G7: SC | H7: 0402010005 | I7: SC MOVILIZACION Y DESMOVILIZACION PARA CARCAVAS | J7: glb | L7: 1 | M7: 60135.17 | N7: 60135.17 | P7: =IF(J7="%mo","",IF(G7="MO",IF(J7="hh",INDEX(MO_HH,MATCH(I7,MO_CAT,0)),M7*P_FACT_IPC),IF(G7="SUBPART",IFERROR(INDEX(APU_SUBP!$C$7:$C$40,MATCH(H7,APU_SUBP!$A$7:$A$40,0)),M7*P_FACT_IPC),M7*P_FACT_IPC))) -> 77351.619 | Q7: =IF(J7="%mo",L7/100*SUMIFS($R$7:$R$782,$A$7:$A$782,A7),L7*P7) -> 77351.619 | R7: =IF(G7="MO",L7*P7,0) -> 0
A8: CARCAVAS|01.02 | B8: CARCAVAS | C8: 01.02 | D8: CONSTRUCCION DE TROCHA CARROZABLE DE ACCESO | E8: km | F8: 27992.8 | G8: MO | H8: 0101010002 | I8: CAPATAZ | J8: hh | K8: 0.5 | L8: 16 | M8: 25.81 | N8: 412.96 | O8: C | P8: =IF(J8="%mo","",IF(G8="MO",IF(J8="hh",INDEX(MO_HH,MATCH(I8,MO_CAT,0)),M8*P_FACT_IPC),IF(G8="SUBPART",IFERROR(INDEX(APU_SUBP!$C$7:$C$40,MATCH(H8,APU_SUBP!$A$7:$A$40,0)),M8*P_FACT_IPC),M8*P_FACT_IPC))) -> 19.226758 | Q8: =IF(J8="%mo",L8/100*SUMIFS($R$7:$R$782,$A$7:$A$782,A8),L8*P8) -> 307.62813 | R8: =IF(G8="MO",L8*P8,0) -> 307.62813
A9: CARCAVAS|01.02 | B9: CARCAVAS | C9: 01.02 | D9: CONSTRUCCION DE TROCHA CARROZABLE DE ACCESO | E9: km | F9: 27992.8 | G9: MO | H9: 0101010004 | I9: OFICIAL | J9: hh | K9: 2 | L9: 64 | M9: 18.56 | N9: 1187.84 | O9: C | P9: =IF(J9="%mo","",IF(G9="MO",IF(J9="hh",INDEX(MO_HH,MATCH(I9,MO_CAT,0)),M9*P_FACT_IPC),IF(G9="SUBPART",IFERROR(INDEX(APU_SUBP!$C$7:$C$40,MATCH(H9,APU_SUBP!$A$7:$A$40,0)),M9*P_FACT_IPC),M9*P_FACT_IPC))) -> 13.825983 | Q9: =IF(J9="%mo",L9/100*SUMIFS($R$7:$R$782,$A$7:$A$782,A9),L9*P9) -> 884.86293 | R9: =IF(G9="MO",L9*P9,0) -> 884.86293
A10: CARCAVAS|01.02 | B10: CARCAVAS | C10: 01.02 | D10: CONSTRUCCION DE TROCHA CARROZABLE DE ACCESO | E10: km | F10: 27992.8 | G10: MO | H10: 0101010005 | I10: PEON | J10: hh | K10: 4 | L10: 128 | M10: 16.78 | N10: 2147.84 | O10: NC | P10: =IF(J10="%mo","",IF(G10="MO",IF(J10="hh",INDEX(MO_HH,MATCH(I10,MO_CAT,0)),M10*P_FACT_IPC),IF(G10="SUBPART",IFERROR(INDEX(APU_SUBP!$C$7:$C$40,MATCH(H10,APU_SUBP!$A$7:$A$40,0)),M10*P_FACT_IPC),M10*P_FACT_IPC))) -> 12.5 | Q10: =IF(J10="%mo",L10/100*SUMIFS($R$7:$R$782,$A$7:$A$782,A10),L10*P10) -> 1600 | R10: =IF(G10="MO",L10*P10,0) -> 1600
A11: CARCAVAS|01.02 | B11: CARCAVAS | C11: 01.02 | D11: CONSTRUCCION DE TROCHA CARROZABLE DE ACCESO | E11: km | F11: 27992.8 | G11: EQ | H11: 03011600010003 | I11: CARGADOR SOBRE LLANTAS DE 125-135 HP 3 yd3 | J11: hm | K11: 0.5 | L11: 16 | M11: 170.08 | N11: 2721.28 | P11: =IF(J11="%mo","",IF(G11="MO",IF(J11="hh",INDEX(MO_HH,MATCH(I11,MO_CAT,0)),M11*P_FACT_IPC),IF(G11="SUBPART",IFERROR(INDEX(APU_SUBP!$C$7:$C$40,MATCH(H11,APU_SUBP!$A$7:$A$40,0)),M11*P_FACT_IPC),M11*P_FACT_IPC))) -> 218.7732 | Q11: =IF(J11="%mo",L11/100*SUMIFS($R$7:$R$782,$A$7:$A$782,A11),L11*P11) -> 3500.3711 | R11: =IF(G11="MO",L11*P11,0) -> 0
A12: CARCAVAS|01.02 | B12: CARCAVAS | C12: 01.02 | D12: CONSTRUCCION DE TROCHA CARROZABLE DE ACCESO | E12: km | F12: 27992.8 | G12: EQ | H12: 0301190003 | I12: RODILLO VIBRATORIO LISO AUTOPROPULSADO 101-135 HP, 10-12 TN | J12: hm | K12: 1 | L12: 32 | M12: 159.96 | N12: 5118.72 | P12: =IF(J12="%mo","",IF(G12="MO",IF(J12="hh",INDEX(MO_HH,MATCH(I12,MO_CAT,0)),M12*P_FACT_IPC),IF(G12="SUBPART",IFERROR(INDEX(APU_SUBP!$C$7:$C$40,MATCH(H12,APU_SUBP!$A$7:$A$40,0)),M12*P_FACT_IPC),M12*P_FACT_IPC))) -> 205.75588 | Q12: =IF(J12="%mo",L12/100*SUMIFS($R$7:$R$782,$A$7:$A$782,A12),L12*P12) -> 6584.1882 | R12: =IF(G12="MO",L12*P12,0) -> 0
A13: CARCAVAS|01.02 | B13: CARCAVAS | C13: 01.02 | D13: CONSTRUCCION DE TROCHA CARROZABLE DE ACCESO | E13: km | F13: 27992.8 | G13: EQ | H13: 03012000010001 | I13: MOTONIVELADORA 130 - 135 HP | J13: hm | K13: 1 | L13: 32 | M13: 182.88 | N13: 5852.16 | P13: =IF(J13="%mo","",IF(G13="MO",IF(J13="hh",INDEX(MO_HH,MATCH(I13,MO_CAT,0)),M13*P_FACT_IPC),IF(G13="SUBPART",IFERROR(INDEX(APU_SUBP!$C$7:$C$40,MATCH(H13,APU_SUBP!$A$7:$A$40,0)),M13*P_FACT_IPC),M13*P_FACT_IPC))) -> 235.23778 | Q13: =IF(J13="%mo",L13/100*SUMIFS($R$7:$R$782,$A$7:$A$782,A13),L13*P13) -> 7527.6091 | R13: =IF(G13="MO",L13*P13,0) -> 0
A14: CARCAVAS|01.02 | B14: CARCAVAS | C14: 01.02 | D14: CONSTRUCCION DE TROCHA CARROZABLE DE ACCESO | E14: km | F14: 27992.8 | G14: EQ | H14: 03012200040006 | I14: CAMION VOLQUETE 6X4, 330 HP DE 10 m3 | J14: hm | K14: 1 | L14: 32 | M14: 188.87 | N14: 6043.84 | P14: =IF(J14="%mo","",IF(G14="MO",IF(J14="hh",INDEX(MO_HH,MATCH(I14,MO_CAT,0)),M14*P_FACT_IPC),IF(G14="SUBPART",IFERROR(INDEX(APU_SUBP!$C$7:$C$40,MATCH(H14,APU_SUBP!$A$7:$A$40,0)),M14*P_FACT_IPC),M14*P_FACT_IPC))) -> 242.9427 | Q14: =IF(J14="%mo",L14/100*SUMIFS($R$7:$R$782,$A$7:$A$782,A14),L14*P14) -> 7774.1663 | R14: =IF(G14="MO",L14*P14,0) -> 0
A15: CARCAVAS|01.02 | B15: CARCAVAS | C15: 01.02 | D15: CONSTRUCCION DE TROCHA CARROZABLE DE ACCESO | E15: km | F15: 27992.8 | G15: EQ | H15: 03012200050001 | I15: CAMION CISTERNA (2,500 GLNS.) | J15: hm | K15: 1 | L15: 32 | M15: 140.88 | N15: 4508.16 | P15: =IF(J15="%mo","",IF(G15="MO",IF(J15="hh",INDEX(MO_HH,MATCH(I15,MO_CAT,0)),M15*P_FACT_IPC),IF(G15="SUBPART",IFERROR(INDEX(APU_SUBP!$C$7:$C$40,MATCH(H15,APU_SUBP!$A$7:$A$40,0)),M15*P_FACT_IPC),M15*P_FACT_IPC))) -> 181.21336 | Q15: =IF(J15="%mo",L15/100*SUMIFS($R$7:$R$782,$A$7:$A$782,A15),L15*P15) -> 5798.8275 | R15: =IF(G15="MO",L15*P15,0) -> 0
A16: CARCAVAS|01.03 | B16: CARCAVAS | C16: 01.03 | D16: MEJORAMIENTO DE TROCHA CARROZABLE DE ACCESO | E16: km | F16: 4665.44 | G16: MO | H16: 0101010002 | I16: CAPATAZ | J16: hh | K16: 0.5 | L16: 2.6667 | M16: 25.81 | N16: 68.83 | O16: C | P16: =IF(J16="%mo","",IF(G16="MO",IF(J16="hh",INDEX(MO_HH,MATCH(I16,MO_CAT,0)),M16*P_FACT_IPC),IF(G16="SUBPART",IFERROR(INDEX(APU_SUBP!$C$7:$C$40,MATCH(H16,APU_SUBP!$A$7:$A$40,0)),M16*P_FACT_IPC),M16*P_FACT_IPC))) -> 19.226758 | Q16: =IF(J16="%mo",L16/100*SUMIFS($R$7:$R$782,$A$7:$A$782,A16),L16*P16) -> 51.271996 | R16: =IF(G16="MO",L16*P16,0) -> 51.271996
A17: CARCAVAS|01.03 | B17: CARCAVAS | C17: 01.03 | D17: MEJORAMIENTO DE TROCHA CARROZABLE DE ACCESO | E17: km | F17: 4665.44 | G17: MO | H17: 0101010004 | I17: OFICIAL | J17: hh | K17: 2 | L17: 10.6667 | M17: 18.56 | N17: 197.97 | O17: C | P17: =IF(J17="%mo","",IF(G17="MO",IF(J17="hh",INDEX(MO_HH,MATCH(I17,MO_CAT,0)),M17*P_FACT_IPC),IF(G17="SUBPART",IFERROR(INDEX(APU_SUBP!$C$7:$C$40,MATCH(H17,APU_SUBP!$A$7:$A$40,0)),M17*P_FACT_IPC),M17*P_FACT_IPC))) -> 13.825983 | Q17: =IF(J17="%mo",L17/100*SUMIFS($R$7:$R$782,$A$7:$A$782,A17),L17*P17) -> 147.47762 | R17: =IF(G17="MO",L17*P17,0) -> 147.47762
A18: CARCAVAS|01.03 | B18: CARCAVAS | C18: 01.03 | D18: MEJORAMIENTO DE TROCHA CARROZABLE DE ACCESO | E18: km | F18: 4665.44 | G18: MO | H18: 0101010005 | I18: PEON | J18: hh | K18: 4 | L18: 21.3333 | M18: 16.78 | N18: 357.97 | O18: NC | P18: =IF(J18="%mo","",IF(G18="MO",IF(J18="hh",INDEX(MO_HH,MATCH(I18,MO_CAT,0)),M18*P_FACT_IPC),IF(G18="SUBPART",IFERROR(INDEX(APU_SUBP!$C$7:$C$40,MATCH(H18,APU_SUBP!$A$7:$A$40,0)),M18*P_FACT_IPC),M18*P_FACT_IPC))) -> 12.5 | Q18: =IF(J18="%mo",L18/100*SUMIFS($R$7:$R$782,$A$7:$A$782,A18),L18*P18) -> 266.66625 | R18: =IF(G18="MO",L18*P18,0) -> 266.66625
A19: CARCAVAS|01.03 | B19: CARCAVAS | C19: 01.03 | D19: MEJORAMIENTO DE TROCHA CARROZABLE DE ACCESO | E19: km | F19: 4665.44 | G19: EQ | H19: 03011600010003 | I19: CARGADOR SOBRE LLANTAS DE 125-135 HP 3 yd3 | J19: hm | K19: 0.5 | L19: 2.6667 | M19: 170.08 | N19: 453.55 | P19: =IF(J19="%mo","",IF(G19="MO",IF(J19="hh",INDEX(MO_HH,MATCH(I19,MO_CAT,0)),M19*P_FACT_IPC),IF(G19="SUBPART",IFERROR(INDEX(APU_SUBP!$C$7:$C$40,MATCH(H19,APU_SUBP!$A$7:$A$40,0)),M19*P_FACT_IPC),M19*P_FACT_IPC))) -> 218.7732 | Q19: =IF(J19="%mo",L19/100*SUMIFS($R$7:$R$782,$A$7:$A$782,A19),L19*P19) -> 583.40248 | R19: =IF(G19="MO",L19*P19,0) -> 0
A20: CARCAVAS|01.03 | B20: CARCAVAS | C20: 01.03 | D20: MEJORAMIENTO DE TROCHA CARROZABLE DE ACCESO | E20: km | F20: 4665.44 | G20: EQ | H20: 0301190003 | I20: RODILLO VIBRATORIO LISO AUTOPROPULSADO 101-135 HP, 10-12 TN | J20: hm | K20: 1 | L20: 5.3333 | M20: 159.96 | N20: 853.11 | P20: =IF(J20="%mo","",IF(G20="MO",IF(J20="hh",INDEX(MO_HH,MATCH(I20,MO_CAT,0)),M20*P_FACT_IPC),IF(G20="SUBPART",IFERROR(INDEX(APU_SUBP!$C$7:$C$40,MATCH(H20,APU_SUBP!$A$7:$A$40,0)),M20*P_FACT_IPC),M20*P_FACT_IPC))) -> 205.75588 | Q20: =IF(J20="%mo",L20/100*SUMIFS($R$7:$R$782,$A$7:$A$782,A20),L20*P20) -> 1097.3578 | R20: =IF(G20="MO",L20*P20,0) -> 0
A21: CARCAVAS|01.03 | B21: CARCAVAS | C21: 01.03 | D21: MEJORAMIENTO DE TROCHA CARROZABLE DE ACCESO | E21: km | F21: 4665.44 | G21: EQ | H21: 03012000010001 | I21: MOTONIVELADORA 130 - 135 HP | J21: hm | K21: 1 | L21: 5.3333 | M21: 182.88 | N21: 975.35 | P21: =IF(J21="%mo","",IF(G21="MO",IF(J21="hh",INDEX(MO_HH,MATCH(I21,MO_CAT,0)),M21*P_FACT_IPC),IF(G21="SUBPART",IFERROR(INDEX(APU_SUBP!$C$7:$C$40,MATCH(H21,APU_SUBP!$A$7:$A$40,0)),M21*P_FACT_IPC),M21*P_FACT_IPC))) -> 235.23778 | Q21: =IF(J21="%mo",L21/100*SUMIFS($R$7:$R$782,$A$7:$A$782,A21),L21*P21) -> 1254.5937 | R21: =IF(G21="MO",L21*P21,0) -> 0
A22: CARCAVAS|01.03 | B22: CARCAVAS | C22: 01.03 | D22: MEJORAMIENTO DE TROCHA CARROZABLE DE ACCESO | E22: km | F22: 4665.44 | G22: EQ | H22: 03012200040006 | I22: CAMION VOLQUETE 6X4, 330 HP DE 10 m3 | J22: hm | K22: 1 | L22: 5.3333 | M22: 188.87 | N22: 1007.3 | P22: =IF(J22="%mo","",IF(G22="MO",IF(J22="hh",INDEX(MO_HH,MATCH(I22,MO_CAT,0)),M22*P_FACT_IPC),IF(G22="SUBPART",IFERROR(INDEX(APU_SUBP!$C$7:$C$40,MATCH(H22,APU_SUBP!$A$7:$A$40,0)),M22*P_FACT_IPC),M22*P_FACT_IPC))) -> 242.9427 | Q22: =IF(J22="%mo",L22/100*SUMIFS($R$7:$R$782,$A$7:$A$782,A22),L22*P22) -> 1295.6863 | R22: =IF(G22="MO",L22*P22,0) -> 0
A23: CARCAVAS|01.03 | B23: CARCAVAS | C23: 01.03 | D23: MEJORAMIENTO DE TROCHA CARROZABLE DE ACCESO | E23: km | F23: 4665.44 | G23: EQ | H23: 03012200050001 | I23: CAMION CISTERNA (2,500 GLNS.) | J23: hm | K23: 1 | L23: 5.3333 | M23: 140.88 | N23: 751.36 | P23: =IF(J23="%mo","",IF(G23="MO",IF(J23="hh",INDEX(MO_HH,MATCH(I23,MO_CAT,0)),M23*P_FACT_IPC),IF(G23="SUBPART",IFERROR(INDEX(APU_SUBP!$C$7:$C$40,MATCH(H23,APU_SUBP!$A$7:$A$40,0)),M23*P_FACT_IPC),M23*P_FACT_IPC))) -> 181.21336 | Q23: =IF(J23="%mo",L23/100*SUMIFS($R$7:$R$782,$A$7:$A$782,A23),L23*P23) -> 966.4652 | R23: =IF(G23="MO",L23*P23,0) -> 0
A24: CARCAVAS|01.04 | B24: CARCAVAS | C24: 01.04 | D24: TRAZO, NIVELACION Y REPLANTEO POR KILOMETRO | E24: km | F24: 583.87 | G24: MO | H24: 0101010003 | I24: OPERARIO | J24: hh | K24: 1 | L24: 5 | M24: 23.46 | N24: 117.3 | O24: C | P24: =IF(J24="%mo","",IF(G24="MO",IF(J24="hh",INDEX(MO_HH,MATCH(I24,MO_CAT,0)),M24*P_FACT_IPC),IF(G24="SUBPART",IFERROR(INDEX(APU_SUBP!$C$7:$C$40,MATCH(H24,APU_SUBP!$A$7:$A$40,0)),M24*P_FACT_IPC),M24*P_FACT_IPC))) -> 17.476162 | Q24: =IF(J24="%mo",L24/100*SUMIFS($R$7:$R$782,$A$7:$A$782,A24),L24*P24) -> 87.38081 | R24: =IF(G24="MO",L24*P24,0) -> 87.38081
A25: CARCAVAS|01.04 | B25: CARCAVAS | C25: 01.04 | D25: TRAZO, NIVELACION Y REPLANTEO POR KILOMETRO | E25: km | F25: 583.87 | G25: MO | H25: 0101010004 | I25: OFICIAL | J25: hh | K25: 1 | L25: 5 | M25: 18.56 | N25: 92.8 | O25: C | P25: =IF(J25="%mo","",IF(G25="MO",IF(J25="hh",INDEX(MO_HH,MATCH(I25,MO_CAT,0)),M25*P_FACT_IPC),IF(G25="SUBPART",IFERROR(INDEX(APU_SUBP!$C$7:$C$40,MATCH(H25,APU_SUBP!$A$7:$A$40,0)),M25*P_FACT_IPC),M25*P_FACT_IPC))) -> 13.825983 | Q25: =IF(J25="%mo",L25/100*SUMIFS($R$7:$R$782,$A$7:$A$782,A25),L25*P25) -> 69.129917 | R25: =IF(G25="MO",L25*P25,0) -> 69.129917
A26: CARCAVAS|01.04 | B26: CARCAVAS | C26: 01.04 | D26: TRAZO, NIVELACION Y REPLANTEO POR KILOMETRO | E26: km | F26: 583.87 | G26: MO | H26: 0101010005 | I26: PEON | J26: hh | K26: 3 | L26: 15 | M26: 16.78 | N26: 251.7 | O26: NC | P26: =IF(J26="%mo","",IF(G26="MO",IF(J26="hh",INDEX(MO_HH,MATCH(I26,MO_CAT,0)),M26*P_FACT_IPC),IF(G26="SUBPART",IFERROR(INDEX(APU_SUBP!$C$7:$C$40,MATCH(H26,APU_SUBP!$A$7:$A$40,0)),M26*P_FACT_IPC),M26*P_FACT_IPC))) -> 12.5 | Q26: =IF(J26="%mo",L26/100*SUMIFS($R$7:$R$782,$A$7:$A$782,A26),L26*P26) -> 187.5 | R26: =IF(G26="MO",L26*P26,0) -> 187.5
A27: CARCAVAS|01.04 | B27: CARCAVAS | C27: 01.04 | D27: TRAZO, NIVELACION Y REPLANTEO POR KILOMETRO | E27: km | F27: 583.87 | G27: MAT | H27: 02130300010001 | I27: YESO BOLSA 28 kg | J27: bol | L27: 0.003 | M27: 14.7 | N27: 0.04 | P27: =IF(J27="%mo","",IF(G27="MO",IF(J27="hh",INDEX(MO_HH,MATCH(I27,MO_CAT,0)),M27*P_FACT_IPC),IF(G27="SUBPART",IFERROR(INDEX(APU_SUBP!$C$7:$C$40,MATCH(H27,APU_SUBP!$A$7:$A$40,0)),M27*P_FACT_IPC),M27*P_FACT_IPC))) -> 18.908549 | Q27: =IF(J27="%mo",L27/100*SUMIFS($R$7:$R$782,$A$7:$A$782,A27),L27*P27) -> 0.056725647 | R27: =IF(G27="MO",L27*P27,0) -> 0
A28: CARCAVAS|01.04 | B28: CARCAVAS | C28: 01.04 | D28: TRAZO, NIVELACION Y REPLANTEO POR KILOMETRO | E28: km | F28: 583.87 | G28: MAT | H28: 0213030003 | I28: CORDEL | J28: rll | L28: 0.01 | M28: 1.63 | N28: 0.02 | P28: =IF(J28="%mo","",IF(G28="MO",IF(J28="hh",INDEX(MO_HH,MATCH(I28,MO_CAT,0)),M28*P_FACT_IPC),IF(G28="SUBPART",IFERROR(INDEX(APU_SUBP!$C$7:$C$40,MATCH(H28,APU_SUBP!$A$7:$A$40,0)),M28*P_FACT_IPC),M28*P_FACT_IPC))) -> 2.0966622 | Q28: =IF(J28="%mo",L28/100*SUMIFS($R$7:$R$782,$A$7:$A$782,A28),L28*P28) -> 0.020966622 | R28: =IF(G28="MO",L28*P28,0) -> 0
A29: CARCAVAS|01.04 | B29: CARCAVAS | C29: 01.04 | D29: TRAZO, NIVELACION Y REPLANTEO POR KILOMETRO | E29: km | F29: 583.87 | G29: MAT | H29: 0231040002 | I29: ESTACAS DE MADERA | J29: p2 | L29: 0.007 | M29: 1.63 | N29: 0.01 | P29: =IF(J29="%mo","",IF(G29="MO",IF(J29="hh",INDEX(MO_HH,MATCH(I29,MO_CAT,0)),M29*P_FACT_IPC),IF(G29="SUBPART",IFERROR(INDEX(APU_SUBP!$C$7:$C$40,MATCH(H29,APU_SUBP!$A$7:$A$40,0)),M29*P_FACT_IPC),M29*P_FACT_IPC))) -> 2.0966622 | Q29: =IF(J29="%mo",L29/100*SUMIFS($R$7:$R$782,$A$7:$A$782,A29),L29*P29) -> 0.014676636 | R29: =IF(G29="MO",L29*P29,0) -> 0
A30: CARCAVAS|01.04 | B30: CARCAVAS | C30: 01.04 | D30: TRAZO, NIVELACION Y REPLANTEO POR KILOMETRO | E30: km | F30: 583.87 | G30: MAT | H30: 0240020001 | I30: PINTURA ESMALTE | J30: gal | L30: 0.002 | M30: 34.07 | N30: 0.07 | P30: =IF(J30="%mo","",IF(G30="MO",IF(J30="hh",INDEX(MO_HH,MATCH(I30,MO_CAT,0)),M30*P_FACT_IPC),IF(G30="SUBPART",IFERROR(INDEX(APU_SUBP!$C$7:$C$40,MATCH(H30,APU_SUBP!$A$7:$A$40,0)),M30*P_FACT_IPC),M30*P_FACT_IPC))) -> 43.824099 | Q30: =IF(J30="%mo",L30/100*SUMIFS($R$7:$R$782,$A$7:$A$782,A30),L30*P30) -> 0.087648199 | R30: =IF(G30="MO",L30*P30,0) -> 0
A31: CARCAVAS|01.04 | B31: CARCAVAS | C31: 01.04 | D31: TRAZO, NIVELACION Y REPLANTEO POR KILOMETRO | E31: km | F31: 583.87 | G31: EQ | H31: 03010000020002 | I31: NIVEL TOPOGRAFICO | J31: he | K31: 0.5 | L31: 2.5 | M31: 9.71 | N31: 24.28 | P31: =IF(J31="%mo","",IF(G31="MO",IF(J31="hh",INDEX(MO_HH,MATCH(I31,MO_CAT,0)),M31*P_FACT_IPC),IF(G31="SUBPART",IFERROR(INDEX(APU_SUBP!$C$7:$C$40,MATCH(H31,APU_SUBP!$A$7:$A$40,0)),M31*P_FACT_IPC),M31*P_FACT_IPC))) -> 12.489933 | Q31: =IF(J31="%mo",L31/100*SUMIFS($R$7:$R$782,$A$7:$A$782,A31),L31*P31) -> 31.224832 | R31: =IF(G31="MO",L31*P31,0) -> 0
A32: CARCAVAS|01.04 | B32: CARCAVAS | C32: 01.04 | D32: TRAZO, NIVELACION Y REPLANTEO POR KILOMETRO | E32: km | F32: 583.87 | G32: EQ | H32: 0301000020 | I32: ESTACION TOTAL | J32: he | K32: 1 | L32: 5 | M32: 16.7 | N32: 83.5 | P32: =IF(J32="%mo","",IF(G32="MO",IF(J32="hh",INDEX(MO_HH,MATCH(I32,MO_CAT,0)),M32*P_FACT_IPC),IF(G32="SUBPART",IFERROR(INDEX(APU_SUBP!$C$7:$C$40,MATCH(H32,APU_SUBP!$A$7:$A$40,0)),M32*P_FACT_IPC),M32*P_FACT_IPC))) -> 21.481141 | Q32: =IF(J32="%mo",L32/100*SUMIFS($R$7:$R$782,$A$7:$A$782,A32),L32*P32) -> 107.4057 | R32: =IF(G32="MO",L32*P32,0) -> 0
A33: CARCAVAS|01.04 | B33: CARCAVAS | C33: 01.04 | D33: TRAZO, NIVELACION Y REPLANTEO POR KILOMETRO | E33: km | F33: 583.87 | G33: EQ | H33: 0301000021 | I33: MIRAS Y JALONES | J33: he | K33: 0.5 | L33: 2.5 | M33: 0.12 | N33: 0.3 | P33: =IF(J33="%mo","",IF(G33="MO",IF(J33="hh",INDEX(MO_HH,MATCH(I33,MO_CAT,0)),M33*P_FACT_IPC),IF(G33="SUBPART",IFERROR(INDEX(APU_SUBP!$C$7:$C$40,MATCH(H33,APU_SUBP!$A$7:$A$40,0)),M33*P_FACT_IPC),M33*P_FACT_IPC))) -> 0.1543555 | Q33: =IF(J33="%mo",L33/100*SUMIFS($R$7:$R$782,$A$7:$A$782,A33),L33*P33) -> 0.38588875 | R33: =IF(G33="MO",L33*P33,0) -> 0
A34: CARCAVAS|01.04 | B34: CARCAVAS | C34: 01.04 | D34: TRAZO, NIVELACION Y REPLANTEO POR KILOMETRO | E34: km | F34: 583.87 | G34: EQ | H34: 0301010006 | I34: HERRAMIENTAS MANUALES | J34: %mo | L34: 3 | M34: 461.8 | N34: 13.85 | P34: =IF(J34="%mo","",IF(G34="MO",IF(J34="hh",INDEX(MO_HH,MATCH(I34,MO_CAT,0)),M34*P_FACT_IPC),IF(G34="SUBPART",IFERROR(INDEX(APU_SUBP!$C$7:$C$40,MATCH(H34,APU_SUBP!$A$7:$A$40,0)),M34*P_FACT_IPC),M34*P_FACT_IPC))) | Q34: =IF(J34="%mo",L34/100*SUMIFS($R$7:$R$782,$A$7:$A$782,A34),L34*P34) -> 10.320322 | R34: =IF(G34="MO",L34*P34,0) -> 0
A35: CARCAVAS|01.05 | B35: CARCAVAS | C35: 01.05 | D35: LIMPIEZA MANUAL DE TERRENO | E35: ha | F35: 285.04 | G35: MO | H35: 0101010002 | I35: CAPATAZ | J35: hh | K35: 1 | L35: 0.32 | M35: 25.81 | N35: 8.26 | O35: C | P35: =IF(J35="%mo","",IF(G35="MO",IF(J35="hh",INDEX(MO_HH,MATCH(I35,MO_CAT,0)),M35*P_FACT_IPC),IF(G35="SUBPART",IFERROR(INDEX(APU_SUBP!$C$7:$C$40,MATCH(H35,APU_SUBP!$A$7:$A$40,0)),M35*P_FACT_IPC),M35*P_FACT_IPC))) -> 19.226758 | Q35: =IF(J35="%mo",L35/100*SUMIFS($R$7:$R$782,$A$7:$A$782,A35),L35*P35) -> 6.1525626 | R35: =IF(G35="MO",L35*P35,0) -> 6.1525626
A36: CARCAVAS|01.05 | B36: CARCAVAS | C36: 01.05 | D36: LIMPIEZA MANUAL DE TERRENO | E36: ha | F36: 285.04 | G36: MO | H36: 0101010005 | I36: PEON | J36: hh | K36: 50 | L36: 16 | M36: 16.78 | N36: 268.48 | O36: NC | P36: =IF(J36="%mo","",IF(G36="MO",IF(J36="hh",INDEX(MO_HH,MATCH(I36,MO_CAT,0)),M36*P_FACT_IPC),IF(G36="SUBPART",IFERROR(INDEX(APU_SUBP!$C$7:$C$40,MATCH(H36,APU_SUBP!$A$7:$A$40,0)),M36*P_FACT_IPC),M36*P_FACT_IPC))) -> 12.5 | Q36: =IF(J36="%mo",L36/100*SUMIFS($R$7:$R$782,$A$7:$A$782,A36),L36*P36) -> 200 | R36: =IF(G36="MO",L36*P36,0) -> 200
A37: CARCAVAS|01.05 | B37: CARCAVAS | C37: 01.05 | D37: LIMPIEZA MANUAL DE TERRENO | E37: ha | F37: 285.04 | G37: EQ | H37: 0301010006 | I37: HERRAMIENTAS MANUALES | J37: %mo | L37: 3 | M37: 276.74 | N37: 8.3 | P37: =IF(J37="%mo","",IF(G37="MO",IF(J37="hh",INDEX(MO_HH,MATCH(I37,MO_CAT,0)),M37*P_FACT_IPC),IF(G37="SUBPART",IFERROR(INDEX(APU_SUBP!$C$7:$C$40,MATCH(H37,APU_SUBP!$A$7:$A$40,0)),M37*P_FACT_IPC),M37*P_FACT_IPC))) | Q37: =IF(J37="%mo",L37/100*SUMIFS($R$7:$R$782,$A$7:$A$782,A37),L37*P37) -> 6.1845769 | R37: =IF(G37="MO",L37*P37,0) -> 0
A38: CARCAVAS|01.06 | B38: CARCAVAS | C38: 01.06 | D38: SENSIBILIZACION A LA POBLACION EN CARCAVAS | E38: und | F38: 6000 | G38: MO | H38: 0103010014 | I38: INGENIERO ESPECIALISTA EN DIQUES PARA CONTROL DE CARCAVAS | J38: glb | L38: 1 | M38: 6000 | N38: 6000 | O38: C | P38: =IF(J38="%mo","",IF(G38="MO",IF(J38="hh",INDEX(MO_HH,MATCH(I38,MO_CAT,0)),M38*P_FACT_IPC),IF(G38="SUBPART",IFERROR(INDEX(APU_SUBP!$C$7:$C$40,MATCH(H38,APU_SUBP!$A$7:$A$40,0)),M38*P_FACT_IPC),M38*P_FACT_IPC))) -> 7717.775 | Q38: =IF(J38="%mo",L38/100*SUMIFS($R$7:$R$782,$A$7:$A$782,A38),L38*P38) -> 7717.775 | R38: =IF(G38="MO",L38*P38,0) -> 7717.775
A39: CARCAVAS|02.01 | B39: CARCAVAS | C39: 02.01 | D39: CAMPAMENTO PROVISIONAL DE OBRA Y ALMACENES | E39: m2 | F39: 202.06 | G39: SC | H39: 04020100020004 | I39: SC MUROS Y COLUMNAS DE MADERA TORNILLO O SIMILAR | J39: m2 | L39: 1 | M39: 53.5 | N39: 53.5 | P39: =IF(J39="%mo","",IF(G39="MO",IF(J39="hh",INDEX(MO_HH,MATCH(I39,MO_CAT,0)),M39*P_FACT_IPC),IF(G39="SUBPART",IFERROR(INDEX(APU_SUBP!$C$7:$C$40,MATCH(H39,APU_SUBP!$A$7:$A$40,0)),M39*P_FACT_IPC),M39*P_FACT_IPC))) -> 68.816827 | Q39: =IF(J39="%mo",L39/100*SUMIFS($R$7:$R$782,$A$7:$A$782,A39),L39*P39) -> 68.816827 | R39: =IF(G39="MO",L39*P39,0) -> 0
A40: CARCAVAS|02.01 | B40: CARCAVAS | C40: 02.01 | D40: CAMPAMENTO PROVISIONAL DE OBRA Y ALMACENES | E40: m2 | F40: 202.06 | G40: SC | H40: 04020100020005 | I40: SC TECHOS DE CALAMINA METALICA, FIBROCEMENTO SOBRE VIGERIA METALICA | J40: m2 | L40: 1 | M40: 41.46 | N40: 41.46 | P40: =IF(J40="%mo","",IF(G40="MO",IF(J40="hh",INDEX(MO_HH,MATCH(I40,MO_CAT,0)),M40*P_FACT_IPC),IF(G40="SUBPART",IFERROR(INDEX(APU_SUBP!$C$7:$C$40,MATCH(H40,APU_SUBP!$A$7:$A$40,0)),M40*P_FACT_IPC),M40*P_FACT_IPC))) -> 53.329826 | Q40: =IF(J40="%mo",L40/100*SUMIFS($R$7:$R$782,$A$7:$A$782,A40),L40*P40) -> 53.329826 | R40: =IF(G40="MO",L40*P40,0) -> 0
...

Sheet APU_SUBP
A1: AUTORIDAD NACIONAL DE INFRAESTRUCTURA - ANIN
A2: DIRECCIÓN DE INTERVENCIONES MULTISECTORIALES Y DE EMERGENCIA - DIME
A3: SUBDIRECCIÓN DE ESTUDIOS DE INVERSIÓN
A4: PROYECTO IN PIURA – CUI 2669244 · Subpartidas de catálogo (lookup por código)
A5: Una fila por código de subpartida; el CU actualizado se toma de la primera definición encontrada en APU_BASE.
A6: Código | B6: Subpartida | C6: CU actualizado | D6: CU 2020 ANIN | E6: Clave usada | F6: Und
A7: 011002010124 | B7: TIERRA DE CULTIVO | C7: =SUMIFS(APU_BASE!$Q$7:$Q$782,APU_BASE!$A$7:$A$782,E7) -> 30.561493 | D7: 24.35 | E7: CARCAVAS_SUB|011002010124-1003001-01 | F7: m3
A8: 011002010133 | B8: AGUA PUESTA EN OBRA HASTA 10 KM | C8: =SUMIFS(APU_BASE!$Q$7:$Q$782,APU_BASE!$A$7:$A$782,E8) -> 22.743882 | D8: 21.15 | E8: CARCAVAS_SUB|011002010133-1003001-01 | F8: m3
A9: 011002010134 | B9: ARENA PUESTA EN OBRA | C9: =SUMIFS(APU_BASE!$Q$7:$Q$782,APU_BASE!$A$7:$A$782,E9) -> 69.142511 | D9: 56.6 | E9: CARCAVAS_SUB|011002010134-1003001-01 | F9: m3
A10: 011002010135 | B10: EXTRACCION Y APILAMIENTO DE MATERIAL GRAVO ARENOSO ARCILLOSO | C10: =SUMIFS(APU_BASE!$Q$7:$Q$782,APU_BASE!$A$7:$A$782,E10) -> 5.2439637 | D10: 4.33 | E10: CARCAVAS_SUB|011002010135-1003001-01 | F10: m3
A11: 011002010139 | B11: CARGUIO Y TRANSPORTE DE MATERIAL ARENOSO HASTA 40 KM | C11: =SUMIFS(APU_BASE!$Q$7:$Q$782,APU_BASE!$A$7:$A$782,E11) -> 63.898548 | D11: 52.27 | E11: CARCAVAS_SUB|011002010139-1003001-01 | F11: m3
A12: 011002010153 | B12: EXTRACCION Y APILAMIENTO DE TIERRA DE CULTIVO | C12: =SUMIFS(APU_BASE!$Q$7:$Q$782,APU_BASE!$A$7:$A$782,E12) -> 2.6155691 | D12: 2.08 | E12: CARCAVAS_SUB|011002010153-1003001-01 | F12: m3
A13: 011002010154 | B13: CARGUIO Y TRANSPORTE DE TIERRA DE CULTIVO HASTA 10 KM | C13: =SUMIFS(APU_BASE!$Q$7:$Q$782,APU_BASE!$A$7:$A$782,E13) -> 27.945924 | D13: 22.27 | E13: CARCAVAS_SUB|011002010154-1003001-01 | F13: m3
A14: 011002010193 | B14: ARENA ZARANDEADA | C14: =SUMIFS(APU_BASE!$Q$7:$Q$782,APU_BASE!$A$7:$A$782,E14) -> 64.499739 | D14: 86.3 | E14: CARCAVAS_SUB|011002010193-1003001-01 | F14: m3
A15: 011002010210 | B15: PIEDRA CANTEADA PUESTA EN OBRA DIA. MAX. 12" | C15: =SUMIFS(APU_BASE!$Q$7:$Q$782,APU_BASE!$A$7:$A$782,E15) -> 86.441692 | D15: 113.54 | E15: CARCAVAS_SUB|011002010210-1003001-01 | F15: m3
A16: 011002010211 | B16: RECOLECCION Y ACOPIO MANUAL DE PIEDRA DE 12" | C16: =SUMIFS(APU_BASE!$Q$7:$Q$782,APU_BASE!$A$7:$A$782,E16) -> 43.478522 | D16: 58.37 | E16: CARCAVAS_SUB|011002010211-1003001-01 | F16: m3
A17: 011002010212 | B17: CARGUIO Y TRANSPORTE DE PIEDRA DIA. MAX. 12" HASTA 5 KM | C17: =SUMIFS(APU_BASE!$Q$7:$Q$782,APU_BASE!$A$7:$A$782,E17) -> 7.2123485 | D17: 7.18 | E17: CARCAVAS_SUB|011002010212-1003001-01 | F17: m3
A18: 011002010216 | B18: CANTEO MANUAL DE PIEDRA DIA. MAX. 12" | C18: =SUMIFS(APU_BASE!$Q$7:$Q$782,APU_BASE!$A$7:$A$782,E18) -> 33.576895 | D18: 45.07 | E18: CARCAVAS_SUB|011002010216-1003001-01 | F18: m3
... A28: 011002010220 | B28: PIEDRA PUESTA EN OBRA, DIA. MAX 12" | C28: =SUMIFS(APU_BASE!$Q$7:$Q$782,APU_BASE!$A$7:$A$782,E28) -> 52.864797 | D28: 68.47 | E28: REFORESTACION_SUB|011002010220-1003001-01 | F28: m3

Sheet PARTIDAS
A1: AUTORIDAD NACIONAL DE INFRAESTRUCTURA - ANIN
A2: DIRECCIÓN DE INTERVENCIONES MULTISECTORIALES Y DE EMERGENCIA - DIME
A3: SUBDIRECCIÓN DE ESTUDIOS DE INVERSIÓN
A4: PROYECTO IN PIURA – CUI 2669244 · Costos unitarios por partida (2020 vs. actualizado) y desagregación para precios sociales
A5: CU actualizado = Σ parcial actualizado de APU_BASE. MO NC = peón; MO C = capataz, operario, oficial e ingeniería.
A6: Clave | B6: Tipo | C6: Item | D6: Partida | E6: Und | F6: CU 2020 ANIN | G6: CU 2020 recalculado (control) | H6: CU actualizado | I6: MO no calificada | J6: MO calificada | K6: Bienes, equipos y servicios | L6: Variación vs 2020
A7: CARCAVAS|01.01 | B7: CARCAVAS | C7: 01.01 | D7: MOVILIZACION Y DESMOVILIZACION PARA CARCAVAS | E7: m3 | F7: 60135.17 | G7: =SUMIFS(APU_BASE!$N$7:$N$782,APU_BASE!$A$7:$A$782,A7) -> 60135.17 | H7: =SUMIFS(APU_BASE!$Q$7:$Q$782,APU_BASE!$A$7:$A$782,A7) -> 77351.619 | I7: =SUMIFS(APU_BASE!$Q$7:$Q$782,APU_BASE!$A$7:$A$782,A7,APU_BASE!$O$7:$O$782,"NC") -> 0 | J7: =SUMIFS(APU_BASE!$Q$7:$Q$782,APU_BASE!$A$7:$A$782,A7,APU_BASE!$O$7:$O$782,"C") -> 0 | K7: =H7-I7-J7 -> 77351.619 | L7: =IF(F7=0,0,H7/F7-1) -> 0.28629584
A8: CARCAVAS|01.02 | B8: CARCAVAS | C8: 01.02 | D8: CONSTRUCCION DE TROCHA CARROZABLE DE ACCESO | E8: km | F8: 27992.8 | G8: =SUMIFS(APU_BASE!$N$7:$N$782,APU_BASE!$A$7:$A$782,A8) -> 27992.8 | H8: =SUMIFS(APU_BASE!$Q$7:$Q$782,APU_BASE!$A$7:$A$782,A8) -> 33977.653 | I8: =SUMIFS(APU_BASE!$Q$7:$Q$782,APU_BASE!$A$7:$A$782,A8,APU_BASE!$O$7:$O$782,"NC") -> 1600 | J8: =SUMIFS(APU_BASE!$Q$7:$Q$782,APU_BASE!$A$7:$A$782,A8,APU_BASE!$O$7:$O$782,"C") -> 1192.4911 | K8: =H8-I8-J8 -> 31185.162 | L8: =IF(F8=0,0,H8/F8-1) -> 0.21379974
A9: CARCAVAS|01.03 | B9: CARCAVAS | C9: 01.03 | D9: MEJORAMIENTO DE TROCHA CARROZABLE DE ACCESO | E9: km | F9: 4665.44 | G9: =SUMIFS(APU_BASE!$N$7:$N$782,APU_BASE!$A$7:$A$782,A9) -> 4665.44 | H9: =SUMIFS(APU_BASE!$Q$7:$Q$782,APU_BASE!$A$7:$A$782,A9) -> 5662.9213 | I9: =SUMIFS(APU_BASE!$Q$7:$Q$782,APU_BASE!$A$7:$A$782,A9,APU_BASE!$O$7:$O$782,"NC") -> 266.66625 | J9: =SUMIFS(APU_BASE!$Q$7:$Q$782,APU_BASE!$A$7:$A$782,A9,APU_BASE!$O$7:$O$782,"C") -> 198.74961 | K9: =H9-I9-J9 -> 5197.5055 | L9: =IF(F9=0,0,H9/F9-1) -> 0.2138022
A10: CARCAVAS|01.04 | B10: CARCAVAS | C10: 01.04 | D10: TRAZO, NIVELACION Y REPLANTEO POR KILOMETRO | E10: km | F10: 583.87 | G10: =SUMIFS(APU_BASE!$N$7:$N$782,APU_BASE!$A$7:$A$782,A10) -> 583.87 | H10: =SUMIFS(APU_BASE!$Q$7:$Q$782,APU_BASE!$A$7:$A$782,A10) -> 493.52749 | I10: =SUMIFS(APU_BASE!$Q$7:$Q$782,APU_BASE!$A$7:$A$782,A10,APU_BASE!$O$7:$O$782,"NC") -> 187.5 | J10: =SUMIFS(APU_BASE!$Q$7:$Q$782,APU_BASE!$A$7:$A$782,A10,APU_BASE!$O$7:$O$782,"C") -> 156.51073 | K10: =H10-I10-J10 -> 149.51676 | L10: =IF(F10=0,0,H10/F10-1) -> -0.15473052
A11: CARCAVAS|01.05 | B11: CARCAVAS | C11: 01.05 | D11: LIMPIEZA MANUAL DE TERRENO | E11: ha | F11: 285.04 | G11: =SUMIFS(APU_BASE!$N$7:$N$782,APU_BASE!$A$7:$A$782,A11) -> 285.04 | H11: =SUMIFS(APU_BASE!$Q$7:$Q$782,APU_BASE!$A$7:$A$782,A11) -> 212.33714 | I11: =SUMIFS(APU_BASE!$Q$7:$Q$782,APU_BASE!$A$7:$A$782,A11,APU_BASE!$O$7:$O$782,"NC") -> 200 | J11: =SUMIFS(APU_BASE!$Q$7:$Q$782,APU_BASE!$A$7:$A$782,A11,APU_BASE!$O$7:$O$782,"C") -> 6.1525626 | K11: =H11-I11-J11 -> 6.1845769 | L11: =IF(F11=0,0,H11/F11-1) -> -0.25506196
A12: CARCAVAS|01.06 | B12: CARCAVAS | C12: 01.06 | D12: SENSIBILIZACION A LA POBLACION EN CARCAVAS | E12: und | F12: 6000 | G12: =SUMIFS(APU_BASE!$N$7:$N$782,APU_BASE!$A$7:$A$782,A12) -> 6000 | H12: =SUMIFS(APU_BASE!$Q$7:$Q$782,APU_BASE!$A$7:$A$782,A12) -> 7717.775 | I12: =SUMIFS(APU_BASE!$Q$7:$Q$782,APU_BASE!$A$7:$A$782,A12,APU_BASE!$O$7:$O$782,"NC") -> 0 | J12: =SUMIFS(APU_BASE!$Q$7:$Q$782,APU_BASE!$A$7:$A$782,A12,APU_BASE!$O$7:$O$782,"C") -> 7717.775 | K12: =H12-I12-J12 -> 0 | L12: =IF(F12=0,0,H12/F12-1) -> 0.28629584
A13: CARCAVAS|02.01 | B13: CARCAVAS | C13: 02.01 | D13: CAMPAMENTO PROVISIONAL DE OBRA Y ALMACENES | E13: m2 | F13: 202.06 | G13: =SUMIFS(APU_BASE!$N$7:$N$782,APU_BASE!$A$7:$A$782,A13) -> 202.06 | H13: =SUMIFS(APU_BASE!$Q$7:$Q$782,APU_BASE!$A$7:$A$782,A13) -> 259.90894 | I13: =SUMIFS(APU_BASE!$Q$7:$Q$782,APU_BASE!$A$7:$A$782,A13,APU_BASE!$O$7:$O$782,"NC") -> 0 | J13: =SUMIFS(APU_BASE!$Q$7:$Q$782,APU_BASE!$A$7:$A$782,A13,APU_BASE!$O$7:$O$782,"C") -> 0 | K13: =H13-I13-J13 -> 259.90894 | L13: =IF(F13=0,0,H13/F13-1) -> 0.28629584
A14: CARCAVAS|02.02 | B14: CARCAVAS | C14: 02.02 | D14: CARTEL DE OBRA 4.80 X 3.60 M CON GIGANTOGRAFIA | E14: und | F14: 4445.55 | G14: =SUMIFS(APU_BASE!$N$7:$N$782,APU_BASE!$A$7:$A$782,A14) -> 4445.55 | H14: =SUMIFS(APU_BASE!$Q$7:$Q$782,APU_BASE!$A$7:$A$782,A14) -> 5255.3328 | I14: =SUMIFS(APU_BASE!$Q$7:$Q$782,APU_BASE!$A$7:$A$782,A14,APU_BASE!$O$7:$O$782,"NC") -> 400 | J14: =SUMIFS(APU_BASE!$Q$7:$Q$782,APU_BASE!$A$7:$A$782,A14,APU_BASE!$O$7:$O$782,"C") -> 216.71633 | K14: =H14-I14-J14 -> 4638.6165 | L14: =IF(F14=0,0,H14/F14-1) -> 0.18215583
A15: CARCAVAS|03.01.01 | B15: CARCAVAS | C15: 03.01.01 | D15: PEINADO DE CARCAVAS | E15: m2 | F15: 7.45 | G15: =SUMIFS(APU_BASE!$N$7:$N$782,APU_BASE!$A$7:$A$782,A15) -> 7.45 | H15: =SUMIFS(APU_BASE!$Q$7:$Q$782,APU_BASE!$A$7:$A$782,A15) -> 5.5460712 | I15: =SUMIFS(APU_BASE!$Q$7:$Q$782,APU_BASE!$A$7:$A$782,A15,APU_BASE!$O$7:$O$782,"NC") -> 5 | J15: =SUMIFS(APU_BASE!$Q$7:$Q$782,APU_BASE!$A$7:$A$782,A15,APU_BASE!$O$7:$O$782,"C") -> 0.38453516 | K15: =H15-I15-J15 -> 0.16153605 | L15: =IF(F15=0,0,H15/F15-1) -> -0.25556091
A16: CARCAVAS|03.01.02 | B16: CARCAVAS | C16: 03.01.02 | D16: EXCAVACION MANUAL EN MATERIAL SUELTO | E16: m3 | F16: 63.82 | G16: =SUMIFS(APU_BASE!$N$7:$N$782,APU_BASE!$A$7:$A$782,A16) -> 63.82 | H16: =SUMIFS(APU_BASE!$Q$7:$Q$782,APU_BASE!$A$7:$A$782,A16) -> 47.537139 | I16: =SUMIFS(APU_BASE!$Q$7:$Q$782,APU_BASE!$A$7:$A$782,A16,APU_BASE!$O$7:$O$782,"NC") -> 40 | J16: =SUMIFS(APU_BASE!$Q$7:$Q$782,APU_BASE!$A$7:$A$782,A16,APU_BASE!$O$7:$O$782,"C") -> 6.1525626 | K16: =H16-I16-J16 -> 1.3845769 | L16: =IF(F16=0,0,H16/F16-1) -> -0.25513727
A17: CARCAVAS|03.01.03 | B17: CARCAVAS | C17: 03.01.03 | D17: NIVELACION Y COMPACTACION MANUAL DE TERRENO | E17: m2 | F17: 3.19 | G17: =SUMIFS(APU_BASE!$N$7:$N$782,APU_BASE!$A$7:$A$782,A17) -> 3.19 | H17: =SUMIFS(APU_BASE!$Q$7:$Q$782,APU_BASE!$A$7:$A$782,A17) -> 3.0481022 | I17: =SUMIFS(APU_BASE!$Q$7:$Q$782,APU_BASE!$A$7:$A$782,A17,APU_BASE!$O$7:$O$782,"NC") -> 0.8 | J17: =SUMIFS(APU_BASE!$Q$7:$Q$782,APU_BASE!$A$7:$A$782,A17,APU_BASE!$O$7:$O$782,"C") -> 0.62076281 | K17: =H17-I17-J17 -> 1.6273394 | L17: =IF(F17=0,0,H17/F17-1) -> -0.044482077
A18: CARCAVAS|03.01.04 | B18: CARCAVAS | C18: 03.01.04 | D18: COLOCACION DE PIEDRA CANTEADA | E18: m3 | F18: 166 | G18: =SUMIFS(APU_BASE!$N$7:$N$782,APU_BASE!$A$7:$A$782,A18) -> 166 | H18: =SUMIFS(APU_BASE!$Q$7:$Q$782,APU_BASE!$A$7:$A$782,A18) -> 125.61451 | I18: =SUMIFS(APU_BASE!$Q$7:$Q$782,APU_BASE!$A$7:$A$782,A18,APU_BASE!$O$7:$O$782,"NC") -> 25 | J18: =SUMIFS(APU_BASE!$Q$7:$Q$782,APU_BASE!$A$7:$A$782,A18,APU_BASE!$O$7:$O$782,"C") -> 8.8356675 | K18: =H18-I18-J18 -> 91.778846 | L18: =IF(F18=0,0,H18/F18-1) -> -0.24328606
... A132: ZANJAS|03.03.07 | B132: ZANJAS | C132: 03.03.07 | D132: RIEGO MANUAL CON BALDE | E132: und | F132: 1.05 | G132: =SUMIFS(APU_BASE!$N$7:$N$782,APU_BASE!$A$7:$A$782,A132) -> 1.05 | H132: =SUMIFS(APU_BASE!$Q$7:$Q$782,APU_BASE!$A$7:$A$782,A132) -> 0.83367041 | I132: =SUMIFS(APU_BASE!$Q$7:$Q$782,APU_BASE!$A$7:$A$782,A132,APU_BASE!$O$7:$O$782,"NC") -> 0.625 | J132: =SUMIFS(APU_BASE!$Q$7:$Q$782,APU_BASE!$A$7:$A$782,A132,APU_BASE!$O$7:$O$782,"C") -> 0.019226758 | K132: =H132-I132-J132 -> 0.18944365 | L132: =IF(F132=0,0,H132/F132-1) -> -0.20602819

Sheet CU_COMP
A1: AUTORIDAD NACIONAL DE INFRAESTRUCTURA - ANIN
A2: DIRECCIÓN DE INTERVENCIONES MULTISECTORIALES Y DE EMERGENCIA - DIME
A3: SUBDIRECCIÓN DE ESTUDIOS DE INVERSIÓN
A4: PROYECTO IN PIURA – CUI 2669244 · Costos unitarios compuestos del paquete tecnológico
A5: Coeficientes = metrado ANIN ÷ meta base ANIN (trazables). Costo = coeficiente × CU actualizado de PARTIDAS.
A6: Grupo | B6: Clave partida | C6: Descripción | D6: Metrado ANIN | E6: Base ANIN | F6: Coeficiente por unidad | G6: CU actualizado | H6: Costo por unidad | I6: MO no calificada | J6: MO calificada | K6: Bienes y servicios
A7: PLANTON | B7: REFORESTACION|02.02.01 | C7: NIVELACION Y COMPACTACION MANUAL DE TERRENO | D7: 2500 | E7: 650000 | F7: =D7/E7 -> 0.0038461538 | G7: =INDEX(PARTIDAS!$H$7:$H$132,MATCH(B7,PARTIDAS!$A$7:$A$132,0)) -> 3.0481022 | H7: =F7*G7 -> 0.01172347 | I7: =F7*INDEX(PARTIDAS!$I$7:$I$132,MATCH(B7,PARTIDAS!$A$7:$A$132,0)) -> 0.0030769231 | J7: =F7*INDEX(PARTIDAS!$J$7:$J$132,MATCH(B7,PARTIDAS!$A$7:$A$132,0)) -> 0.0023875493 | K7: =H7-I7-J7 -> 0.0062589975
A8: PLANTON | B8: REFORESTACION|02.02.02 | C8: CERCO PERIMETRICO DE ALAMBRE DE PUAS | D8: 200 | E8: 650000 | F8: =D8/E8 -> 0.00030769231 | G8: =INDEX(PARTIDAS!$H$7:$H$132,MATCH(B8,PARTIDAS!$A$7:$A$132,0)) -> 21.969803 | H8: =F8*G8 -> 0.0067599393 | I8: =F8*INDEX(PARTIDAS!$I$7:$I$132,MATCH(B8,PARTIDAS!$A$7:$A$132,0)) -> 0 | J8: =F8*INDEX(PARTIDAS!$J$7:$J$132,MATCH(B8,PARTIDAS!$A$7:$A$132,0)) -> 0 | K8: =H8-I8-J8 -> 0.0067599393
A9: PLANTON | B9: REFORESTACION|02.02.03 | C9: POSTE ROLLIZO DE 3"x3.00 M. PARA COBERTURA INTERIOR | D9: 144 | E9: 650000 | F9: =D9/E9 -> 0.00022153846 | G9: =INDEX(PARTIDAS!$H$7:$H$132,MATCH(B9,PARTIDAS!$A$7:$A$132,0)) -> 19.616442 | H9: =F9*G9 -> 0.0043457964 | I9: =F9*INDEX(PARTIDAS!$I$7:$I$132,MATCH(B9,PARTIDAS!$A$7:$A$132,0)) -> 0.0022153846 | J9: =F9*INDEX(PARTIDAS!$J$7:$J$132,MATCH(B9,PARTIDAS!$A$7:$A$132,0)) -> 0.00012251948 | K9: =H9-I9-J9 -> 0.0020078923
A10: PLANTON | B10: REFORESTACION|02.02.04 | C10: MALLA RASHEL A 50% DE SOMBRA | D10: 2980 | E10: 650000 | F10: =D10/E10 -> 0.0045846154 | G10: =INDEX(PARTIDAS!$H$7:$H$132,MATCH(B10,PARTIDAS!$A$7:$A$132,0)) -> 1.1090006 | H10: =F10*G10 -> 0.0050843412 | I10: =F10*INDEX(PARTIDAS!$I$7:$I$132,MATCH(B10,PARTIDAS!$A$7:$A$132,0)) -> 0.0030545 | J10: =F10*INDEX(PARTIDAS!$J$7:$J$132,MATCH(B10,PARTIDAS!$A$7:$A$132,0)) -> 0.0001711444 | K10: =H10-I10-J10 -> 0.0018586968
A11: PLANTON | B11: REFORESTACION|02.02.05 | C11: ALAMBRE N°08 PARA SOSTENIMIENTO DE MALLA RASHEL | D11: 1540 | E11: 650000 | F11: =D11/E11 -> 0.0023692308 | G11: =INDEX(PARTIDAS!$H$7:$H$132,MATCH(B11,PARTIDAS!$A$7:$A$132,0)) -> 3.0768313 | H11: =F11*G11 -> 0.0072897233 | I11: =F11*INDEX(PARTIDAS!$I$7:$I$132,MATCH(B11,PARTIDAS!$A$7:$A$132,0)) -> 0.0011846154 | J11: =F11*INDEX(PARTIDAS!$J$7:$J$132,MATCH(B11,PARTIDAS!$A$7:$A$132,0)) -> 0.00013102778 | K11: =H11-I11-J11 -> 0.0059740801
A12: PLANTON | B12: REFORESTACION|02.02.06 | C12: ALAMBRE DE PUA GALVANIZADO | D12: 220 | E12: 650000 | F12: =D12/E12 -> 0.00033846154 | G12: =INDEX(PARTIDAS!$H$7:$H$132,MATCH(B12,PARTIDAS!$A$7:$A$132,0)) -> 1.5008287 | H12: =F12*G12 -> 0.0005079728 | I12: =F12*INDEX(PARTIDAS!$I$7:$I$132,MATCH(B12,PARTIDAS!$A$7:$A$132,0)) -> 0.00033846154 | J12: =F12*INDEX(PARTIDAS!$J$7:$J$132,MATCH(B12,PARTIDAS!$A$7:$A$132,0)) -> 1.8718254e-05 | K12: =H12-I12-J12 -> 0.00015079301
A13: PLANTON | B13: REFORESTACION|02.02.07 | C13: PUERTA DE INGRESO DE VIVERO | D13: 1 | E13: 650000 | F13: =D13/E13 -> 1.5384615e-06 | G13: =INDEX(PARTIDAS!$H$7:$H$132,MATCH(B13,PARTIDAS!$A$7:$A$132,0)) -> 155.44006 | H13: =F13*G13 -> 0.00023913856 | I13: =F13*INDEX(PARTIDAS!$I$7:$I$132,MATCH(B13,PARTIDAS!$A$7:$A$132,0)) -> 7.6923077e-05 | J13: =F13*INDEX(PARTIDAS!$J$7:$J$132,MATCH(B13,PARTIDAS!$A$7:$A$132,0)) -> 4.2541487e-05 | K13: =H13-I13-J13 -> 0.000119674
A14: PLANTON | B14: REFORESTACION|02.02.08 | C14: CONSTRUCCION DE CAMAS DE REPIQUE | D14: 1687.5 | E14: 650000 | F14: =D14/E14 -> 0.0025961538 | G14: =INDEX(PARTIDAS!$H$7:$H$132,MATCH(B14,PARTIDAS!$A$7:$A$132,0)) -> 21.008906 | H14: =F14*G14 -> 0.054542351 | I14: =F14*INDEX(PARTIDAS!$I$7:$I$132,MATCH(B14,PARTIDAS!$A$7:$A$132,0)) -> 0.010384615 | J14: =F14*INDEX(PARTIDAS!$J$7:$J$132,MATCH(B14,PARTIDAS!$A$7:$A$132,0)) -> 0.0011486202 | K14: =H14-I14-J14 -> 0.043009115
A15: PLANTON | B15: REFORESTACION|02.02.09 | C15: INSTALACIONES SANITARIAS PARA VIVEROS | D15: 2500 | E15: 650000 | F15: =D15/E15 -> 0.0038461538 | G15: =INDEX(PARTIDAS!$H$7:$H$132,MATCH(B15,PARTIDAS!$A$7:$A$132,0)) -> 14.149254 | H15: =F15*G15 -> 0.054420209 | I15: =F15*INDEX(PARTIDAS!$I$7:$I$132,MATCH(B15,PARTIDAS!$A$7:$A$132,0)) -> 0 | J15: =F15*INDEX(PARTIDAS!$J$7:$J$132,MATCH(B15,PARTIDAS!$A$7:$A$132,0)) -> 0 | K15: =H15-I15-J15 -> 0.054420209
A16: PLANTON | B16: REFORESTACION|02.02.10 | C16: AREA DE CARGA Y DESCARGA | D16: 50 | E16: 650000 | F16: =D16/E16 -> 7.6923077e-05 | G16: =INDEX(PARTIDAS!$H$7:$H$132,MATCH(B16,PARTIDAS!$A$7:$A$132,0)) -> 10.782309 | H16: =F16*G16 -> 0.00082940842 | I16: =F16*INDEX(PARTIDAS!$I$7:$I$132,MATCH(B16,PARTIDAS!$A$7:$A$132,0)) -> 0.00038461538 | J16: =F16*INDEX(PARTIDAS!$J$7:$J$132,MATCH(B16,PARTIDAS!$A$7:$A$132,0)) -> 0.00013593335 | K16: =H16-I16-J16 -> 0.00030885969
A17: PLANTON | B17: REFORESTACION|02.03.01 | C17: CONSTRUCCION DE CAMAS DE ALMACIGO | D17: 360 | E17: 650000 | F17: =D17/E17 -> 0.00055384615 | G17: =INDEX(PARTIDAS!$H$7:$H$132,MATCH(B17,PARTIDAS!$A$7:$A$132,0)) -> 70.904974 | H17: =F17*G17 -> 0.039270447 | I17: =F17*INDEX(PARTIDAS!$I$7:$I$132,MATCH(B17,PARTIDAS!$A$7:$A$132,0)) -> 0.0018463846 | J17: =F17*INDEX(PARTIDAS!$J$7:$J$132,MATCH(B17,PARTIDAS!$A$7:$A$132,0)) -> 0.0010207404 | K17: =H17-I17-J17 -> 0.036403322
A18: PLANTON | B18: REFORESTACION|02.03.02 | C18: TINGLADO DE CARRIZO | D18: 360 | E18: 650000 | F18: =D18/E18 -> 0.00055384615 | G18: =INDEX(PARTIDAS!$H$7:$H$132,MATCH(B18,PARTIDAS!$A$7:$A$132,0)) -> 19.463554 | H18: =F18*G18 -> 0.010779815 | I18: =F18*INDEX(PARTIDAS!$I$7:$I$132,MATCH(B18,PARTIDAS!$A$7:$A$132,0)) -> 0.0069230769 | J18: =F18*INDEX(PARTIDAS!$J$7:$J$132,MATCH(B18,PARTIDAS!$A$7:$A$132,0)) -> 0.00076574677 | K18: =H18-I18-J18 -> 0.0030909909
... A35: PLANTA | B35: REFORESTACION|04.02.05 | C35: TRANSPORTE DE PERSONAL EN CAMION BARANDA HASTA 16 KM | D35: 5300 | E35: 650000 | F35: =D35/E35 -> 0.0081538462 | G35: =INDEX(PARTIDAS!$H$7:$H$132,MATCH(B35,PARTIDAS!$A$7:$A$132,0)) -> 2.6180054 | H35: =F35*G35 -> 0.021346813 | I35: =F35*INDEX(PARTIDAS!$I$7:$I$132,MATCH(B35,PARTIDAS!$A$7:$A$132,0)) -> 0 | J35: =F35*INDEX(PARTIDAS!$J$7:$J$132,MATCH(B35,PARTIDAS!$A$7:$A$132,0)) -> 0.0030100229 | K35: =H35-I35-J35 -> 0.01833679
A36: PLANTA | B36: REFORESTACION|04.02.02 | C36: RIEGO MANUAL CON BALDE | D36: =P_RIEGOS -> 3 | E36: 1 | F36: =D36/E36 -> 3 | G36: =INDEX(PARTIDAS!$H$7:$H$132,MATCH(B36,PARTIDAS!$A$7:$A$132,0)) -> 0.83367041 | H36: =F36*G36 -> 2.5010112 | I36: =F36*INDEX(PARTIDAS!$I$7:$I$132,MATCH(B36,PARTIDAS!$A$7:$A$132,0)) -> 1.875 | J36: =F36*INDEX(PARTIDAS!$J$7:$J$132,MATCH(B36,PARTIDAS!$A$7:$A$132,0)) -> 0.057680274 | K36: =H36-I36-J36 -> 0.56833094
A37: PLANTA | B37: REFORESTACION|04.02.04 | C37: RECALCE DE PLANTONES DE ALGARROBO | D37: =P_RECALCE -> 0.1 | E37: 1 | F37: =D37/E37 -> 0.1 | G37: =INDEX(PARTIDAS!$H$7:$H$132,MATCH(B37,PARTIDAS!$A$7:$A$132,0)) -> 5.5860472 | H37: =F37*G37 -> 0.55860472 | I37: =F37*INDEX(PARTIDAS!$I$7:$I$132,MATCH(B37,PARTIDAS!$A$7:$A$132,0)) -> 0.333375 | J37: =F37*INDEX(PARTIDAS!$J$7:$J$132,MATCH(B37,PARTIDAS!$A$7:$A$132,0)) -> 0.025571588 | K37: =H37-I37-J37 -> 0.19965814
A38: HA | B38: REFORESTACION|01.04 | C38: TRAZO, NIVELACION Y REPLANTEO POR HECTAREA | D38: 1000.05 | E38: 1000.05 | F38: =D38/E38 -> 1 | G38: =INDEX(PARTIDAS!$H$7:$H$132,MATCH(B38,PARTIDAS!$A$7:$A$132,0)) -> 438.98644 | H38: =F38*G38 -> 438.98644 | I38: =F38*INDEX(PARTIDAS!$I$7:$I$132,MATCH(B38,PARTIDAS!$A$7:$A$132,0)) -> 166.66625 | J38: =F38*INDEX(PARTIDAS!$J$7:$J$132,MATCH(B38,PARTIDAS!$A$7:$A$132,0)) -> 139.11926 | K38: =H38-I38-J38 -> 133.20093
A39: HA | B39: REFORESTACION|01.05 | C39: LIMPIEZA MANUAL DE TERRENO | D39: 1000.05 | E39: 1000.05 | F39: =D39/E39 -> 1 | G39: =INDEX(PARTIDAS!$H$7:$H$132,MATCH(B39,PARTIDAS!$A$7:$A$132,0)) -> 212.33714 | H39: =F39*G39 -> 212.33714 | I39: =F39*INDEX(PARTIDAS!$I$7:$I$132,MATCH(B39,PARTIDAS!$A$7:$A$132,0)) -> 200 | J39: =F39*INDEX(PARTIDAS!$J$7:$J$132,MATCH(B39,PARTIDAS!$A$7:$A$132,0)) -> 6.1525626 | K39: =H39-I39-J39 -> 6.1845769
A40: HA | B40: REFORESTACION|04.01.03 | C40: CONTROL SANITARIO PREVIO A PLANTACION | D40: 1000 | E40: 1000 | F40: =D40/E40 -> 1 | G40: =INDEX(PARTIDAS!$H$7:$H$132,MATCH(B40,PARTIDAS!$A$7:$A$132,0)) -> 44.257816 | H40: =F40*G40 -> 44.257816 | I40: =F40*INDEX(PARTIDAS!$I$7:$I$132,MATCH(B40,PARTIDAS!$A$7:$A$132,0)) -> 25 | J40: =F40*INDEX(PARTIDAS!$J$7:$J$132,MATCH(B40,PARTIDAS!$A$7:$A$132,0)) -> 0.76907032 | K40: =H40-I40-J40 -> 18.488745
A41: HA | B41: REFORESTACION|04.02.03 | C41: DESHIERBE MANUAL EN AREAS REFORESTADAS | D41: =P_DESHIERBES -> 4 | E41: 1 | F41: =D41/E41 -> 4 | G41: =INDEX(PARTIDAS!$H$7:$H$132,MATCH(B41,PARTIDAS!$A$7:$A$132,0)) -> 106.16857 | H41: =F41*G41 -> 424.67428 | I41: =F41*INDEX(PARTIDAS!$I$7:$I$132,MATCH(B41,PARTIDAS!$A$7:$A$132,0)) -> 400 | J41: =F41*INDEX(PARTIDAS!$J$7:$J$132,MATCH(B41,PARTIDAS!$A$7:$A$132,0)) -> 12.305125 | K41: =H41-I41-J41 -> 12.369154
